Workbook

Sheet LEIA-ME
B1: AS 8 CONTAS ENTERPRISE PRIORITÁRIAS — perderam mais da metade do que pagavam numa redução
B2: Planilha apartada. Lê os CSVs originais sem alterá-los. Base: tabela de assinaturas (valores em MRR, US$ por mês).
B4: COMO AS 8 FORAM ESCOLHIDAS
B5: • Reduções de assinaturas Enterprise PAGAS (sem trial) em que a conta continuou com outra Enterprise: 68.
B6: • Para cada uma: % perdido = MRR da assinatura encerrada ÷ (ela + todas as outras assinaturas ativas da conta no dia). As 8 com mais de 50%.
B7: • Grupos: A = compra extra desfeita (até 30 dias, já havia Enterprise mais antiga); B = pacote antigo desligado havendo Enterprise mais nova; C = redução pura.
B9: O QUE MOSTRAM
B10: • Total perdido de uma vez pelas 8: US$ 68.854/mês.
B11: • Recuperaram (pagam hoje mais do que antes da redução): 3. Compra a mais desfeita (não é perda): 1. NÃO recuperaram: 4 — estas são a prioridade para conversa.
B12: • Três eram contratos ANUAIS encerrados antes de 12 meses (cancelamento antecipado).
B13: • Eventos de churn e tickets dessas contas não coincidem com o momento da redução (datas sem relação).
B14: • Perfil: FinTech e DevTools; Reino Unido e EUA; canais variados. Com 8 casos, nada disso é conclusivo.
... B20: • Base_Assinaturas_8 e Base_Contas_8: dados usados pelas fórmulas.

Sheet 1_As_8_Contas
A1: As 8 contas Enterprise que perderam mais da metade do que pagavam numa redução
A2: Entre as 68 reduções Enterprise pagas em que a conta seguiu com outra Enterprise, estas 8 cortaram mais de 50% do valor mensal da conta de uma vez. Valores em MRR (US$ por mês). "Antes" = assinatura encerrada + outras ativas no dia; "depois" = outras ativas no dia.
A4: # | B4: Conta | C4: Indústria | D4: País | E4: Canal | F4: Assinatura encerrada | G4: Seats | H4: Cobrança | I4: Início | J4: Fim | K4: Dias de vida | L4: MRR perdido | M4: MRR da conta antes | N4: MRR da conta depois | O4: % perdido | P4: Grupo | Q4: Tinha gêmea (mesmos seats)? | R4: MRR da conta em 31/12/2024 | S4: Recuperou? | T4: Eventos de churn | U4: Tickets | V4: O que aconteceu
A5: 1 | B5: A-42e5e1 | C5: =INDEX(Base_Contas_8!$C$2:$C$9,MATCH($B5,Base_Contas_8!$B$2:$B$9,0)) -> DevTools | D5: =INDEX(Base_Contas_8!$D$2:$D$9,MATCH($B5,Base_Contas_8!$B$2:$B$9,0)) -> US | E5: =INDEX(Base_Contas_8!$E$2:$E$9,MATCH($B5,Base_Contas_8!$B$2:$B$9,0)) -> ads | F5: =INDEX(Base_Contas_8!$G$2:$G$9,MATCH($B5,Base_Contas_8!$B$2:$B$9,0)) -> S-a3cbd4 | G5: =INDEX(Base_Contas_8!$H$2:$H$9,MATCH($B5,Base_Contas_8!$B$2:$B$9,0)) -> 20 | H5: =INDEX(Base_Contas_8!$I$2:$I$9,MATCH($B5,Base_Contas_8!$B$2:$B$9,0)) -> mensal | I5: =INDEX(Base_Contas_8!$J$2:$J$9,MATCH($B5,Base_Contas_8!$B$2:$B$9,0)) -> 45505 | J5: =INDEX(Base_Contas_8!$K$2:$K$9,MATCH($B5,Base_Contas_8!$B$2:$B$9,0)) -> 45518 | K5: =INDEX(Base_Contas_8!$L$2:$L$9,MATCH($B5,Base_Contas_8!$B$2:$B$9,0)) -> 13 | L5: =INDEX(Base_Contas_8!$M$2:$M$9,MATCH($B5,Base_Contas_8!$B$2:$B$9,0)) -> 3980 | M5: =L5+SUMIFS(Base_Assinaturas_8!$E$2:$E$73,Base_Assinaturas_8!$A$2:$A$73,$B5,Base_Assinaturas_8!$H$2:$H$73,"<="&J5,Base_Assinaturas_8!$J$2:$J$73,">"&J5) -> 4029 | N5: =SUMIFS(Base_Assinaturas_8!$E$2:$E$73,Base_Assinaturas_8!$A$2:$A$73,$B5,Base_Assinaturas_8!$H$2:$H$73,"<="&J5,Base_Assinaturas_8!$J$2:$J$73,">"&J5) -> 49 | O5: =L5/M5 -> 0.98783817 | P5: =INDEX(Base_Contas_8!$N$2:$N$9,MATCH($B5,Base_Contas_8!$B$2:$B$9,0)) -> B. Pacote antigo desligado (havia Enterprise mais nova) | Q5: =INDEX(Base_Contas_8!$O$2:$O$9,MATCH($B5,Base_Contas_8!$B$2:$B$9,0)) -> Não | R5: =SUMIFS(Base_Assinaturas_8!$E$2:$E$73,Base_Assinaturas_8!$A$2:$A$73,$B5,Base_Assinaturas_8!$J$2:$J$73,">"&DATE(2024,12,31)) -> 4936 | S5: =INDEX(Base_Contas_8!$P$2:$P$9,MATCH($B5,Base_Contas_8!$B$2:$B$9,0)) -> Sim — hoje paga mais do que antes | T5: =INDEX(Base_Contas_8!$Q$2:$Q$9,MATCH($B5,Base_Contas_8!$B$2:$B$9,0)) -> 1 | U5: =INDEX(Base_Contas_8!$S$2:$S$9,MATCH($B5,Base_Contas_8!$B$2:$B$9,0)) -> 3 | V5: Encerrou uma Enterprise de 20 seats (mensal) com 13 dias de vida, em 14/08/2024, e deixou de pagar US$ 3.980/mês — 99% do que a conta pagava (US$ 4.029). Seguiu cliente com 2 assinaturas (1 Enterprise), que somavam US$ 49/mês. 1 delas era trial (US$ 0), por isso a perda pesou tanto no total da conta. Perto do cancelamento abriu uma Enterprise TRIAL de 53 seats (US$ 0) em 02/08/2024: pode ter trocado o contrato pago por um teste. Em 31/12/2024 a conta paga US$ 4.936/mês: recuperou e hoje paga mais do que antes da redução. Eventos de churn registrados: 04/10/2024 (pricing, too expensive) — nenhum perto do cancelamento (não explicam a redução). Tickets: 3 (3 com data anterior ao cadastro da conta — datas não confiáveis).
A6: 2 | B6: A-13466a | C6: =INDEX(Base_Contas_8!$C$2:$C$9,MATCH($B6,Base_Contas_8!$B$2:$B$9,0)) -> DevTools | D6: =INDEX(Base_Contas_8!$D$2:$D$9,MATCH($B6,Base_Contas_8!$B$2:$B$9,0)) -> AU | E6: =INDEX(Base_Contas_8!$E$2:$E$9,MATCH($B6,Base_Contas_8!$B$2:$B$9,0)) -> event | F6: =INDEX(Base_Contas_8!$G$2:$G$9,MATCH($B6,Base_Contas_8!$B$2:$B$9,0)) -> S-af6536 | G6: =INDEX(Base_Contas_8!$H$2:$H$9,MATCH($B6,Base_Contas_8!$B$2:$B$9,0)) -> 40 | H6: =INDEX(Base_Contas_8!$I$2:$I$9,MATCH($B6,Base_Contas_8!$B$2:$B$9,0)) -> mensal | I6: =INDEX(Base_Contas_8!$J$2:$J$9,MATCH($B6,Base_Contas_8!$B$2:$B$9,0)) -> 45333 | J6: =INDEX(Base_Contas_8!$K$2:$K$9,MATCH($B6,Base_Contas_8!$B$2:$B$9,0)) -> 45593 | K6: =INDEX(Base_Contas_8!$L$2:$L$9,MATCH($B6,Base_Contas_8!$B$2:$B$9,0)) -> 260 | L6: =INDEX(Base_Contas_8!$M$2:$M$9,MATCH($B6,Base_Contas_8!$B$2:$B$9,0)) -> 7960 | M6: =L6+SUMIFS(Base_Assinaturas_8!$E$2:$E$73,Base_Assinaturas_8!$A$2:$A$73,$B6,Base_Assinaturas_8!$H$2:$H$73,"<="&J6,Base_Assinaturas_8!$J$2:$J$73,">"&J6) -> 8927 | N6: =SUMIFS(Base_Assinaturas_8!$E$2:$E$73,Base_Assinaturas_8!$A$2:$A$73,$B6,Base_Assinaturas_8!$H$2:$H$73,"<="&J6,Base_Assinaturas_8!$J$2:$J$73,">"&J6) -> 967 | O6: =L6/M6 -> 0.89167694 | P6: =INDEX(Base_Contas_8!$N$2:$N$9,MATCH($B6,Base_Contas_8!$B$2:$B$9,0)) -> B. Pacote antigo desligado (havia Enterprise mais nova) | Q6: =INDEX(Base_Contas_8!$O$2:$O$9,MATCH($B6,Base_Contas_8!$B$2:$B$9,0)) -> Não | R6: =SUMIFS(Base_Assinaturas_8!$E$2:$E$73,Base_Assinaturas_8!$A$2:$A$73,$B6,Base_Assinaturas_8!$J$2:$J$73,">"&DATE(2024,12,31)) -> 171 | S6: =INDEX(Base_Contas_8!$P$2:$P$9,MATCH($B6,Base_Contas_8!$B$2:$B$9,0)) -> Não — continuou caindo | T6: =INDEX(Base_Contas_8!$Q$2:$Q$9,MATCH($B6,Base_Contas_8!$B$2:$B$9,0)) -> 2 | U6: =INDEX(Base_Contas_8!$S$2:$S$9,MATCH($B6,Base_Contas_8!$B$2:$B$9,0)) -> 3 | V6: Encerrou uma Enterprise de 40 seats (mensal) com 260 dias de vida, em 28/10/2024, e deixou de pagar US$ 7.960/mês — 89% do que a conta pagava (US$ 8.927). Seguiu cliente com 3 assinaturas (1 Enterprise), que somavam US$ 967/mês. 1 delas era trial (US$ 0), por isso a perda pesou tanto no total da conta. Em 31/12/2024 a conta paga US$ 171/mês: continuou reduzindo depois. Eventos de churn registrados: 18/11/2023 (support, switched to competitor); 18/04/2024 (pricing, switched to competitor) — nenhum perto do cancelamento (não explicam a redução). Tickets: 3 (1 com data anterior ao cadastro da conta — datas não confiáveis).
A7: 3 | B7: A-425e76 | C7: =INDEX(Base_Contas_8!$C$2:$C$9,MATCH($B7,Base_Contas_8!$B$2:$B$9,0)) -> DevTools | D7: =INDEX(Base_Contas_8!$D$2:$D$9,MATCH($B7,Base_Contas_8!$B$2:$B$9,0)) -> UK | E7: =INDEX(Base_Contas_8!$E$2:$E$9,MATCH($B7,Base_Contas_8!$B$2:$B$9,0)) -> other | F7: =INDEX(Base_Contas_8!$G$2:$G$9,MATCH($B7,Base_Contas_8!$B$2:$B$9,0)) -> S-b45bc6 | G7: =INDEX(Base_Contas_8!$H$2:$H$9,MATCH($B7,Base_Contas_8!$B$2:$B$9,0)) -> 32 | H7: =INDEX(Base_Contas_8!$I$2:$I$9,MATCH($B7,Base_Contas_8!$B$2:$B$9,0)) -> mensal | I7: =INDEX(Base_Contas_8!$J$2:$J$9,MATCH($B7,Base_Contas_8!$B$2:$B$9,0)) -> 45156 | J7: =INDEX(Base_Contas_8!$K$2:$K$9,MATCH($B7,Base_Contas_8!$B$2:$B$9,0)) -> 45231 | K7: =INDEX(Base_Contas_8!$L$2:$L$9,MATCH($B7,Base_Contas_8!$B$2:$B$9,0)) -> 75 | L7: =INDEX(Base_Contas_8!$M$2:$M$9,MATCH($B7,Base_Contas_8!$B$2:$B$9,0)) -> 6368 | M7: =L7+SUMIFS(Base_Assinaturas_8!$E$2:$E$73,Base_Assinaturas_8!$A$2:$A$73,$B7,Base_Assinaturas_8!$H$2:$H$73,"<="&J7,Base_Assinaturas_8!$J$2:$J$73,">"&J7) -> 8884 | N7: =SUMIFS(Base_Assinaturas_8!$E$2:$E$73,Base_Assinaturas_8!$A$2:$A$73,$B7,Base_Assinaturas_8!$H$2:$H$73,"<="&J7,Base_Assinaturas_8!$J$2:$J$73,">"&J7) -> 2516 | O7: =L7/M7 -> 0.71679424 | P7: =INDEX(Base_Contas_8!$N$2:$N$9,MATCH($B7,Base_Contas_8!$B$2:$B$9,0)) -> C. Redução pura (sem Enterprise mais nova) | Q7: =INDEX(Base_Contas_8!$O$2:$O$9,MATCH($B7,Base_Contas_8!$B$2:$B$9,0)) -> Não | R7: =SUMIFS(Base_Assinaturas_8!$E$2:$E$73,Base_Assinaturas_8!$A$2:$A$73,$B7,Base_Assinaturas_8!$J$2:$J$73,">"&DATE(2024,12,31)) -> 10743 | S7: =INDEX(Base_Contas_8!$P$2:$P$9,MATCH($B7,Base_Contas_8!$B$2:$B$9,0)) -> Sim — hoje paga mais do que antes | T7: =INDEX(Base_Contas_8!$Q$2:$Q$9,MATCH($B7,Base_Contas_8!$B$2:$B$9,0)) -> 4 | U7: =INDEX(Base_Contas_8!$S$2:$S$9,MATCH($B7,Base_Contas_8!$B$2:$B$9,0)) -> 5 | V7: Encerrou uma Enterprise de 32 seats (mensal) com 75 dias de vida, em 01/11/2023, e deixou de pagar US$ 6.368/mês — 72% do que a conta pagava (US$ 8.884). Seguiu cliente com 3 assinaturas (1 Enterprise), que somavam US$ 2.516/mês. Em 31/12/2024 a conta paga US$ 10.743/mês: recuperou e hoje paga mais do que antes da redução. Eventos de churn registrados: 10/08/2023 (competitor, too expensive); 03/09/2023 (budget, missing features); 25/12/2023 (competitor, too expensive); 22/10/2024 (competitor, switched to competitor) — nenhum perto do cancelamento (não explicam a redução). Tickets: 5 (1 com data anterior ao cadastro da conta — datas não confiáveis).
A8: 4 | B8: A-f44180 | C8: =INDEX(Base_Contas_8!$C$2:$C$9,MATCH($B8,Base_Contas_8!$B$2:$B$9,0)) -> Cybersecurity | D8: =INDEX(Base_Contas_8!$D$2:$D$9,MATCH($B8,Base_Contas_8!$B$2:$B$9,0)) -> UK | E8: =INDEX(Base_Contas_8!$E$2:$E$9,MATCH($B8,Base_Contas_8!$B$2:$B$9,0)) -> event | F8: =INDEX(Base_Contas_8!$G$2:$G$9,MATCH($B8,Base_Contas_8!$B$2:$B$9,0)) -> S-7da02b | G8: =INDEX(Base_Contas_8!$H$2:$H$9,MATCH($B8,Base_Contas_8!$B$2:$B$9,0)) -> 89 | H8: =INDEX(Base_Contas_8!$I$2:$I$9,MATCH($B8,Base_Contas_8!$B$2:$B$9,0)) -> anual | I8: =INDEX(Base_Contas_8!$J$2:$J$9,MATCH($B8,Base_Contas_8!$B$2:$B$9,0)) -> 45066 | J8: =INDEX(Base_Contas_8!$K$2:$K$9,MATCH($B8,Base_Contas_8!$B$2:$B$9,0)) -> 45279 | K8: =INDEX(Base_Contas_8!$L$2:$L$9,MATCH($B8,Base_Contas_8!$B$2:$B$9,0)) -> 213 | L8: =INDEX(Base_Contas_8!$M$2:$M$9,MATCH($B8,Base_Contas_8!$B$2:$B$9,0)) -> 17711 | M8: =L8+SUMIFS(Base_Assinaturas_8!$E$2:$E$73,Base_Assinaturas_8!$A$2:$A$73,$B8,Base_Assinaturas_8!$H$2:$H$73,"<="&J8,Base_Assinaturas_8!$J$2:$J$73,">"&J8) -> 25870 | N8: =SUMIFS(Base_Assinaturas_8!$E$2:$E$73,Base_Assinaturas_8!$A$2:$A$73,$B8,Base_Assinaturas_8!$H$2:$H$73,"<="&J8,Base_Assinaturas_8!$J$2:$J$73,">"&J8) -> 8159 | O8: =L8/M8 -> 0.68461538 | P8: =INDEX(Base_Contas_8!$N$2:$N$9,MATCH($B8,Base_Contas_8!$B$2:$B$9,0)) -> B. Pacote antigo desligado (havia Enterprise mais nova) | Q8: =INDEX(Base_Contas_8!$O$2:$O$9,MATCH($B8,Base_Contas_8!$B$2:$B$9,0)) -> Não | R8: =SUMIFS(Base_Assinaturas_8!$E$2:$E$73,Base_Assinaturas_8!$A$2:$A$73,$B8,Base_Assinaturas_8!$J$2:$J$73,">"&DATE(2024,12,31)) -> 9286 | S8: =INDEX(Base_Contas_8!$P$2:$P$9,MATCH($B8,Base_Contas_8!$B$2:$B$9,0)) -> Não — perda mantida | T8: =INDEX(Base_Contas_8!$Q$2:$Q$9,MATCH($B8,Base_Contas_8!$B$2:$B$9,0)) -> 1 | U8: =INDEX(Base_Contas_8!$S$2:$S$9,MATCH($B8,Base_Contas_8!$B$2:$B$9,0)) -> 2 | V8: Encerrou uma Enterprise de 89 seats (anual) com 213 dias de vida, em 19/12/2023, e deixou de pagar US$ 17.711/mês — 68% do que a conta pagava (US$ 25.870). Seguiu cliente com 4 assinaturas (4 Enterprise), que somavam US$ 8.159/mês. Era contrato ANUAL encerrado com 213 dias: cancelamento antecipado (verificar multa/reembolso). Em 31/12/2024 a conta paga US$ 9.286/mês: perda mantida. Eventos de churn registrados: 29/04/2023 (competitor, too expensive) — nenhum perto do cancelamento (não explicam a redução). Tickets: 2.
A9: 5 | B9: A-8ae05d | C9: =INDEX(Base_Contas_8!$C$2:$C$9,MATCH($B9,Base_Contas_8!$B$2:$B$9,0)) -> FinTech | D9: =INDEX(Base_Contas_8!$D$2:$D$9,MATCH($B9,Base_Contas_8!$B$2:$B$9,0)) -> IN | E9: =INDEX(Base_Contas_8!$E$2:$E$9,MATCH($B9,Base_Contas_8!$B$2:$B$9,0)) -> other | F9: =INDEX(Base_Contas_8!$G$2:$G$9,MATCH($B9,Base_Contas_8!$B$2:$B$9,0)) -> S-f4b648 | G9: =INDEX(Base_Contas_8!$H$2:$H$9,MATCH($B9,Base_Contas_8!$B$2:$B$9,0)) -> 86 | H9: =INDEX(Base_Contas_8!$I$2:$I$9,MATCH($B9,Base_Contas_8!$B$2:$B$9,0)) -> anual | I9: =INDEX(Base_Contas_8!$J$2:$J$9,MATCH($B9,Base_Contas_8!$B$2:$B$9,0)) -> 45623 | J9: =INDEX(Base_Contas_8!$K$2:$K$9,MATCH($B9,Base_Contas_8!$B$2:$B$9,0)) -> 45654 | K9: =INDEX(Base_Contas_8!$L$2:$L$9,MATCH($B9,Base_Contas_8!$B$2:$B$9,0)) -> 31 | L9: =INDEX(Base_Contas_8!$M$2:$M$9,MATCH($B9,Base_Contas_8!$B$2:$B$9,0)) -> 17114 | M9: =L9+SUMIFS(Base_Assinaturas_8!$E$2:$E$73,Base_Assinaturas_8!$A$2:$A$73,$B9,Base_Assinaturas_8!$H$2:$H$73,"<="&J9,Base_Assinaturas_8!$J$2:$J$73,">"&J9) -> 26230 | N9: =SUMIFS(Base_Assinaturas_8!$E$2:$E$73,Base_Assinaturas_8!$A$2:$A$73,$B9,Base_Assinaturas_8!$H$2:$H$73,"<="&J9,Base_Assinaturas_8!$J$2:$J$73,">"&J9) -> 9116 | O9: =L9/M9 -> 0.65245902 | P9: =INDEX(Base_Contas_8!$N$2:$N$9,MATCH($B9,Base_Contas_8!$B$2:$B$9,0)) -> B. Pacote antigo desligado (havia Enterprise mais nova) | Q9: =INDEX(Base_Contas_8!$O$2:$O$9,MATCH($B9,Base_Contas_8!$B$2:$B$9,0)) -> Sim | R9: =SUMIFS(Base_Assinaturas_8!$E$2:$E$73,Base_Assinaturas_8!$A$2:$A$73,$B9,Base_Assinaturas_8!$J$2:$J$73,">"&DATE(2024,12,31)) -> 9116 | S9: =INDEX(Base_Contas_8!$P$2:$P$9,MATCH($B9,Base_Contas_8!$B$2:$B$9,0)) -> Não — perda mantida | T9: =INDEX(Base_Contas_8!$Q$2:$Q$9,MATCH($B9,Base_Contas_8!$B$2:$B$9,0)) -> 1 | U9: =INDEX(Base_Contas_8!$S$2:$S$9,MATCH($B9,Base_Contas_8!$B$2:$B$9,0)) -> 1 | V9: Encerrou uma Enterprise de 86 seats (anual) com 31 dias de vida, em 28/12/2024, e deixou de pagar US$ 17.114/mês — 65% do que a conta pagava (US$ 26.230). Seguiu cliente com 6 assinaturas (1 Enterprise, uma delas com os mesmos seats), que somavam US$ 9.116/mês. 2 delas eram trial (US$ 0), por isso a perda pesou tanto no total da conta. Perto do cancelamento abriu uma Enterprise TRIAL de 86 seats (US$ 0) em 13/12/2024: pode ter trocado o contrato pago por um teste. Era contrato ANUAL encerrado com 31 dias: cancelamento antecipado (verificar multa/reembolso). Em 31/12/2024 a conta paga US$ 9.116/mês: perda mantida. Eventos de churn registrados: 30/08/2024 (unknown, missing features) — nenhum perto do cancelamento (não explicam a redução). Tickets: 1 (1 com data anterior ao cadastro da conta — datas não confiáveis).
A10: 6 | B10: A-bcf87c | C10: =INDEX(Base_Contas_8!$C$2:$C$9,MATCH($B10,Base_Contas_8!$B$2:$B$9,0)) -> FinTech | D10: =INDEX(Base_Contas_8!$D$2:$D$9,MATCH($B10,Base_Contas_8!$B$2:$B$9,0)) -> US | E10: =INDEX(Base_Contas_8!$E$2:$E$9,MATCH($B10,Base_Contas_8!$B$2:$B$9,0)) -> event | F10: =INDEX(Base_Contas_8!$G$2:$G$9,MATCH($B10,Base_Contas_8!$B$2:$B$9,0)) -> S-c75159 | G10: =INDEX(Base_Contas_8!$H$2:$H$9,MATCH($B10,Base_Contas_8!$B$2:$B$9,0)) -> 31 | H10: =INDEX(Base_Contas_8!$I$2:$I$9,MATCH($B10,Base_Contas_8!$B$2:$B$9,0)) -> mensal | I10: =INDEX(Base_Contas_8!$J$2:$J$9,MATCH($B10,Base_Contas_8!$B$2:$B$9,0)) -> 45526 | J10: =INDEX(Base_Contas_8!$K$2:$K$9,MATCH($B10,Base_Contas_8!$B$2:$B$9,0)) -> 45563 | K10: =INDEX(Base_Contas_8!$L$2:$L$9,MATCH($B10,Base_Contas_8!$B$2:$B$9,0)) -> 37 | L10: =INDEX(Base_Contas_8!$M$2:$M$9,MATCH($B10,Base_Contas_8!$B$2:$B$9,0)) -> 6169 | M10: =L10+SUMIFS(Base_Assinaturas_8!$E$2:$E$73,Base_Assinaturas_8!$A$2:$A$73,$B10,Base_Assinaturas_8!$H$2:$H$73,"<="&J10,Base_Assinaturas_8!$J$2:$J$73,">"&J10) -> 9482 | N10: =SUMIFS(Base_Assinaturas_8!$E$2:$E$73,Base_Assinaturas_8!$A$2:$A$73,$B10,Base_Assinaturas_8!$H$2:$H$73,"<="&J10,Base_Assinaturas_8!$J$2:$J$73,">"&J10) -> 3313 | O10: =L10/M10 -> 0.65060114 | P10: =INDEX(Base_Contas_8!$N$2:$N$9,MATCH($B10,Base_Contas_8!$B$2:$B$9,0)) -> B. Pacote antigo desligado (havia Enterprise mais nova) | Q10: =INDEX(Base_Contas_8!$O$2:$O$9,MATCH($B10,Base_Contas_8!$B$2:$B$9,0)) -> Não | R10: =SUMIFS(Base_Assinaturas_8!$E$2:$E$73,Base_Assinaturas_8!$A$2:$A$73,$B10,Base_Assinaturas_8!$J$2:$J$73,">"&DATE(2024,12,31)) -> 13611 | S10: =INDEX(Base_Contas_8!$P$2:$P$9,MATCH($B10,Base_Contas_8!$B$2:$B$9,0)) -> Sim — hoje paga mais do que antes | T10: =INDEX(Base_Contas_8!$Q$2:$Q$9,MATCH($B10,Base_Contas_8!$B$2:$B$9,0)) -> 0 | U10: =INDEX(Base_Contas_8!$S$2:$S$9,MATCH($B10,Base_Contas_8!$B$2:$B$9,0)) -> 2 | V10: Encerrou uma Enterprise de 31 seats (mensal) com 37 dias de vida, em 28/09/2024, e deixou de pagar US$ 6.169/mês — 65% do que a conta pagava (US$ 9.482). Seguiu cliente com 3 assinaturas (1 Enterprise), que somavam US$ 3.313/mês. Em 31/12/2024 a conta paga US$ 13.611/mês: recuperou e hoje paga mais do que antes da redução. Nenhum evento de churn registrado para a conta. Tickets: 2 (2 com data anterior ao cadastro da conta — datas não confiáveis).
A11: 7 | B11: A-c45b23 | C11: =INDEX(Base_Contas_8!$C$2:$C$9,MATCH($B11,Base_Contas_8!$B$2:$B$9,0)) -> FinTech | D11: =INDEX(Base_Contas_8!$D$2:$D$9,MATCH($B11,Base_Contas_8!$B$2:$B$9,0)) -> UK | E11: =INDEX(Base_Contas_8!$E$2:$E$9,MATCH($B11,Base_Contas_8!$B$2:$B$9,0)) -> partner | F11: =INDEX(Base_Contas_8!$G$2:$G$9,MATCH($B11,Base_Contas_8!$B$2:$B$9,0)) -> S-2361ec | G11: =INDEX(Base_Contas_8!$H$2:$H$9,MATCH($B11,Base_Contas_8!$B$2:$B$9,0)) -> 26 | H11: =INDEX(Base_Contas_8!$I$2:$I$9,MATCH($B11,Base_Contas_8!$B$2:$B$9,0)) -> anual | I11: =INDEX(Base_Contas_8!$J$2:$J$9,MATCH($B11,Base_Contas_8!$B$2:$B$9,0)) -> 45638 | J11: =INDEX(Base_Contas_8!$K$2:$K$9,MATCH($B11,Base_Contas_8!$B$2:$B$9,0)) -> 45641 | K11: =INDEX(Base_Contas_8!$L$2:$L$9,MATCH($B11,Base_Contas_8!$B$2:$B$9,0)) -> 3 | L11: =INDEX(Base_Contas_8!$M$2:$M$9,MATCH($B11,Base_Contas_8!$B$2:$B$9,0)) -> 5174 | M11: =L11+SUMIFS(Base_Assinaturas_8!$E$2:$E$73,Base_Assinaturas_8!$A$2:$A$73,$B11,Base_Assinaturas_8!$H$2:$H$73,"<="&J11,Base_Assinaturas_8!$J$2:$J$73,">"&J11) -> 8504 | N11: =SUMIFS(Base_Assinaturas_8!$E$2:$E$73,Base_Assinaturas_8!$A$2:$A$73,$B11,Base_Assinaturas_8!$H$2:$H$73,"<="&J11,Base_Assinaturas_8!$J$2:$J$73,">"&J11) -> 3330 | O11: =L11/M11 -> 0.60841957 | P11: =INDEX(Base_Contas_8!$N$2:$N$9,MATCH($B11,Base_Contas_8!$B$2:$B$9,0)) -> A. Compra extra desfeita | Q11: =INDEX(Base_Contas_8!$O$2:$O$9,MATCH($B11,Base_Contas_8!$B$2:$B$9,0)) -> Não | R11: =SUMIFS(Base_Assinaturas_8!$E$2:$E$73,Base_Assinaturas_8!$A$2:$A$73,$B11,Base_Assinaturas_8!$J$2:$J$73,">"&DATE(2024,12,31)) -> 3330 | S11: =INDEX(Base_Contas_8!$P$2:$P$9,MATCH($B11,Base_Contas_8!$B$2:$B$9,0)) -> Compra a mais desfeita — voltou ao valor de antes da compra | T11: =INDEX(Base_Contas_8!$Q$2:$Q$9,MATCH($B11,Base_Contas_8!$B$2:$B$9,0)) -> 1 | U11: =INDEX(Base_Contas_8!$S$2:$S$9,MATCH($B11,Base_Contas_8!$B$2:$B$9,0)) -> 3 | V11: Encerrou uma Enterprise de 26 seats (anual) com 3 dias de vida, em 15/12/2024, e deixou de pagar US$ 5.174/mês — 61% do que a conta pagava (US$ 8.504). Seguiu cliente com 11 assinaturas (1 Enterprise), que somavam US$ 3.330/mês. 3 delas eram trial (US$ 0), por isso a perda pesou tanto no total da conta. Era contrato ANUAL encerrado com 3 dias: cancelamento antecipado (verificar multa/reembolso). Já tinha outra Enterprise mais antiga: parece compra a mais desfeita, não perda de cliente. Em 31/12/2024 a conta paga US$ 3.330/mês: o mesmo que pagava antes da compra a mais. Eventos de churn registrados: 24/03/2024 (support, missing features) — nenhum perto do cancelamento (não explicam a redução). Tickets: 3.
A12: 8 | B12: A-69fad4 | C12: =INDEX(Base_Contas_8!$C$2:$C$9,MATCH($B12,Base_Contas_8!$B$2:$B$9,0)) -> FinTech | D12: =INDEX(Base_Contas_8!$D$2:$D$9,MATCH($B12,Base_Contas_8!$B$2:$B$9,0)) -> UK | E12: =INDEX(Base_Contas_8!$E$2:$E$9,MATCH($B12,Base_Contas_8!$B$2:$B$9,0)) -> ads | F12: =INDEX(Base_Contas_8!$G$2:$G$9,MATCH($B12,Base_Contas_8!$B$2:$B$9,0)) -> S-1d63bf | G12: =INDEX(Base_Contas_8!$H$2:$H$9,MATCH($B12,Base_Contas_8!$B$2:$B$9,0)) -> 22 | H12: =INDEX(Base_Contas_8!$I$2:$I$9,MATCH($B12,Base_Contas_8!$B$2:$B$9,0)) -> mensal | I12: =INDEX(Base_Contas_8!$J$2:$J$9,MATCH($B12,Base_Contas_8!$B$2:$B$9,0)) -> 45323 | J12: =INDEX(Base_Contas_8!$K$2:$K$9,MATCH($B12,Base_Contas_8!$B$2:$B$9,0)) -> 45523 | K12: =INDEX(Base_Contas_8!$L$2:$L$9,MATCH($B12,Base_Contas_8!$B$2:$B$9,0)) -> 200 | L12: =INDEX(Base_Contas_8!$M$2:$M$9,MATCH($B12,Base_Contas_8!$B$2:$B$9,0)) -> 4378 | M12: =L12+SUMIFS(Base_Assinaturas_8!$E$2:$E$73,Base_Assinaturas_8!$A$2:$A$73,$B12,Base_Assinaturas_8!$H$2:$H$73,"<="&J12,Base_Assinaturas_8!$J$2:$J$73,">"&J12) -> 8056 | N12: =SUMIFS(Base_Assinaturas_8!$E$2:$E$73,Base_Assinaturas_8!$A$2:$A$73,$B12,Base_Assinaturas_8!$H$2:$H$73,"<="&J12,Base_Assinaturas_8!$J$2:$J$73,">"&J12) -> 3678 | O12: =L12/M12 -> 0.54344588 | P12: =INDEX(Base_Contas_8!$N$2:$N$9,MATCH($B12,Base_Contas_8!$B$2:$B$9,0)) -> C. Redução pura (sem Enterprise mais nova) | Q12: =INDEX(Base_Contas_8!$O$2:$O$9,MATCH($B12,Base_Contas_8!$B$2:$B$9,0)) -> Não | R12: =SUMIFS(Base_Assinaturas_8!$E$2:$E$73,Base_Assinaturas_8!$A$2:$A$73,$B12,Base_Assinaturas_8!$J$2:$J$73,">"&DATE(2024,12,31)) -> 3678 | S12: =INDEX(Base_Contas_8!$P$2:$P$9,MATCH($B12,Base_Contas_8!$B$2:$B$9,0)) -> Não — perda mantida | T12: =INDEX(Base_Contas_8!$Q$2:$Q$9,MATCH($B12,Base_Contas_8!$B$2:$B$9,0)) -> 1 | U12: =INDEX(Base_Contas_8!$S$2:$S$9,MATCH($B12,Base_Contas_8!$B$2:$B$9,0)) -> 4 | V12: Encerrou uma Enterprise de 22 seats (mensal) com 200 dias de vida, em 19/08/2024, e deixou de pagar US$ 4.378/mês — 54% do que a conta pagava (US$ 8.056). Seguiu cliente com 5 assinaturas (2 Enterprise), que somavam US$ 3.678/mês. 1 delas era trial (US$ 0), por isso a perda pesou tanto no total da conta. Em 31/12/2024 a conta paga US$ 3.678/mês: perda mantida. Eventos de churn registrados: 17/06/2024 (support) — nenhum perto do cancelamento (não explicam a redução). Tickets: 4.
B13: Total | L13: =SUM(L5:L12) -> 68854 | M13: =SUM(M5:M12) -> 99982 | N13: =SUM(N5:N12) -> 31128 | O13: =L13/M13 -> 0.68866396 | R13: =SUM(R5:R12) -> 54871
A15: Leitura: das 8, só parte representa perda que ficou. Algumas contas recuperaram o valor (abriram outras assinaturas depois) e uma foi compra a mais desfeita em 3 dias. As que NÃO recuperaram são as prioritárias para conversa: a coluna "Recuperou?" separa os casos. Eventos de churn e tickets não explicam as reduções (datas fora do momento do cancelamento).

Sheet 2_Linha_do_tempo
A1: Linha do tempo das 8 contas: todas as assinaturas
A2: Em destaque, a assinatura Enterprise cuja redução é analisada. "Situação" segue as regras da planilha 02 (Migração, Compra extra desfeita, Redução real, Saída do cliente, Ativa).
A4: Conta | B4: Assinatura | C4: Plano | D4: Seats | E4: MRR | F4: Cobrança | G4: Trial | H4: Início | I4: Fim | J4: Situação
A5: A-42e5e1 — DevTools · US · canal ads · cadastro 09/07/2024
A6: A-42e5e1 | B6: S-2881e0 | C6: Pro | D6: 1 | E6: 49 | F6: anual | G6: Não | H6: 45494 | J6: Ativa em 31/12/2024
A7: A-42e5e1 | B7: S-a3cbd4 | C7: Enterprise | D7: 20 | E7: 3980 | F7: mensal | G7: Não | H7: 45505 | I7: 45518 | J7: Redução real
A8: A-42e5e1 | B8: S-ce9977 | C8: Enterprise | D8: 53 | E8: 0 | F8: mensal | G8: Sim | H8: 45506 | J8: Ativa em 31/12/2024
A9: A-42e5e1 | B9: S-860bc8 | C9: Basic | D9: 1 | E9: 19 | F9: anual | G9: Não | H9: 45533 | J9: Ativa em 31/12/2024
A10: A-42e5e1 | B10: S-8426e7 | C10: Enterprise | D10: 22 | E10: 4378 | F10: anual | G10: Não | H10: 45583 | J10: Ativa em 31/12/2024
A11: A-42e5e1 | B11: S-06e3cd | C11: Basic | D11: 22 | E11: 0 | F11: mensal | G11: Sim | H11: 45587 | J11: Ativa em 31/12/2024
A12: A-42e5e1 | B12: S-9f7b07 | C12: Pro | D12: 10 | E12: 490 | F12: anual | G12: Não | H12: 45624 | J12: Ativa em 31/12/2024
D13: MRR em 31/12/2024: | E13: =SUMIFS(Base_Assinaturas_8!$E$2:$E$73,Base_Assinaturas_8!$A$2:$A$73,"A-42e5e1",Base_Assinaturas_8!$J$2:$J$73,">"&DATE(2024,12,31)) -> 4936
A15: A-13466a — DevTools · AU · canal event · cadastro 22/10/2023
A16: A-13466a | B16: S-2f8dbb | C16: Basic | D16: 2 | E16: 38 | F16: anual | G16: Não | H16: 45248 | I16: 45466 | J16: Redução real
A17: A-13466a | B17: S-af6536 | C17: Enterprise | D17: 40 | E17: 7960 | F17: mensal | G17: Não | H17: 45333 | I17: 45593 | J17: Redução real
A18: A-13466a | B18: S-1c45b4 | C18: Basic | D18: 65 | E18: 0 | F18: mensal | G18: Sim | H18: 45402 | J18: Ativa em 31/12/2024
A19: A-13466a | B19: S-063586 | C19: Enterprise | D19: 22 | E19: 4378 | F19: anual | G19: Não | H19: 45435 | I19: 45562 | J19: Migração
A20: A-13466a | B20: S-b89456 | C20: Enterprise | D20: 4 | E20: 796 | F20: mensal | G20: Não | H20: 45536 | I20: 45657 | J20: Redução real
A21: A-13466a | B21: S-3223a2 | C21: Basic | D21: 9 | E21: 171 | F21: anual | G21: Não | H21: 45555 | J21: Ativa em 31/12/2024
D22: MRR em 31/12/2024: | E22: =SUMIFS(Base_Assinaturas_8!$E$2:$E$73,Base_Assinaturas_8!$A$2:$A$73,"A-13466a",Base_Assinaturas_8!$J$2:$J$73,">"&DATE(2024,12,31)) -> 171
A24: A-425e76 — DevTools · UK · canal other · cadastro 17/05/2023
A25: A-425e76 | B25: S-12ca50 | C25: Enterprise | D25: 8 | E25: 1592 | F25: mensal | G25: Não | H25: 45098 | J25: Ativa em 31/12/2024
A26: A-425e76 | B26: S-6d356a | C26: Basic | D26: 28 | E26: 532 | F26: anual | G26: Não | H26: 45103 | J26: Ativa em 31/12/2024
A27: A-425e76 | B27: S-2d3434 | C27: Pro | D27: 8 | E27: 392 | F27: anual | G27: Não | H27: 45129 | J27: Ativa em 31/12/2024
A28: A-425e76 | B28: S-b45bc6 | C28: Enterprise | D28: 32 | E28: 6368 | F28: mensal | G28: Não | H28: 45156 | I28: 45231 | J28: Redução real
A29: A-425e76 | B29: S-0d8293 | C29: Pro | D29: 71 | E29: 3479 | F29: mensal | G29: Não | H29: 45248 | J29: Ativa em 31/12/2024
A30: A-425e76 | B30: S-2196c4 | C30: Basic | D30: 8 | E30: 152 | F30: mensal | G30: Não | H30: 45398 | J30: Ativa em 31/12/2024
A31: A-425e76 | B31: S-f7f6d7 | C31: Basic | D31: 14 | E31: 266 | F31: mensal | G31: Não | H31: 45419 | J31: Ativa em 31/12/2024
A32: A-425e76 | B32: S-3e0382 | C32: Basic | D32: 27 | E32: 513 | F32: mensal | G32: Não | H32: 45436 | J32: Ativa em 31/12/2024
A33: A-425e76 | B33: S-25f647 | C33: Basic | D33: 37 | E33: 703 | F33: mensal | G33: Não | H33: 45483 | J33: Ativa em 31/12/2024
A34: A-425e76 | B34: S-77f7fd | C34: Pro | D34: 27 | E34: 1323 | F34: mensal | G34: Não | H34: 45510 | J34: Ativa em 31/12/2024
A35: A-425e76 | B35: S-18b808 | C35: Enterprise | D35: 9 | E35: 1791 | F35: anual | G35: Não | H35: 45517 | J35: Ativa em 31/12/2024
D36: MRR em 31/12/2024: | E36: =SUMIFS(Base_Assinaturas_8!$E$2:$E$73,Base_Assinaturas_8!$A$2:$A$73,"A-425e76",Base_Assinaturas_8!$J$2:$J$73,">"&DATE(2024,12,31)) -> 10743
A38: A-f44180 — Cybersecurity · UK · canal event · cadastro 13/02/2023
A39: A-f44180 | B39: S-f5c7b2 | C39: Enterprise | D39: 9 | E39: 1791 | F39: anual | G39: Não | H39: 45010 | J39: Ativa em 31/12/2024
A40: A-f44180 | B40: S-f42cc4 | C40: Enterprise | D40: 14 | E40: 2786 | F40: anual | G40: Não | H40: 45026 | J40: Ativa em 31/12/2024
A41: A-f44180 | B41: S-7da02b | C41: Enterprise | D41: 89 | E41: 17711 | F41: anual | G41: Não | H41: 45066 | I41: 45279 | J41: Redução real
A42: A-f44180 | B42: S-83dc0a | C42: Enterprise | D42: 9 | E42: 1791 | F42: anual | G42: Não | H42: 45169 | J42: Ativa em 31/12/2024
A43: A-f44180 | B43: S-beff12 | C43: Enterprise | D43: 9 | E43: 1791 | F43: mensal | G43: Não | H43: 45216 | J43: Ativa em 31/12/2024
A44: A-f44180 | B44: S-0d6ea4 | C44: Enterprise | D44: 9 | E44: 1791 | F44: mensal | G44: Não | H44: 45287 | I44: 45595 | J44: Redução real
...

Sheet 3_Perfil
A1: Indústria, canal e país das 8 contas
A2: Comparado com as 68 reduções Enterprise pagas em que a conta seguiu com outra Enterprise e com todas as contas que tiveram Enterprise. Com 8 casos, nenhuma diferença pode ser considerada confiável.
A4: Indústria | B4: As 8 contas | C4: MRR perdido pelas 8 | D4: % das 8 | E4: % nas 68 reduções | F4: % das contas com Enterprise | G4: Diferente? (8 x demais reduções)
A5: Cybersecurity | B5: =COUNTIFS(Base_Contas_8!$C$2:$C$9,$A5) -> 1 | C5: =SUMIFS(Base_Contas_8!$M$2:$M$9,Base_Contas_8!$C$2:$C$9,$A5) -> 17711 | D5: =B5/COUNTA(Base_Contas_8!$B$2:$B$9) -> 0.125 | E5: 0.25 | F5: 0.19624217 | G5: Não (pode ser coincidência)
A6: DevTools | B6: =COUNTIFS(Base_Contas_8!$C$2:$C$9,$A6) -> 3 | C6: =SUMIFS(Base_Contas_8!$M$2:$M$9,Base_Contas_8!$C$2:$C$9,$A6) -> 18308 | D6: =B6/COUNTA(Base_Contas_8!$B$2:$B$9) -> 0.375 | E6: 0.22058824 | F6: 0.22546973 | G6: Não (pode ser coincidência)
A7: EdTech | B7: =COUNTIFS(Base_Contas_8!$C$2:$C$9,$A7) -> 0 | C7: =SUMIFS(Base_Contas_8!$M$2:$M$9,Base_Contas_8!$C$2:$C$9,$A7) -> 0 | D7: =B7/COUNTA(Base_Contas_8!$B$2:$B$9) -> 0 | E7: 0.14705882 | F7: 0.16075157 | G7: Não (pode ser coincidência)
A8: FinTech | B8: =COUNTIFS(Base_Contas_8!$C$2:$C$9,$A8) -> 4 | C8: =SUMIFS(Base_Contas_8!$M$2:$M$9,Base_Contas_8!$C$2:$C$9,$A8) -> 32835 | D8: =B8/COUNTA(Base_Contas_8!$B$2:$B$9) -> 0.5 | E8: 0.20588235 | F8: 0.22338205 | G8: Não (pode ser coincidência)
A9: HealthTech | B9: =COUNTIFS(Base_Contas_8!$C$2:$C$9,$A9) -> 0 | C9: =SUMIFS(Base_Contas_8!$M$2:$M$9,Base_Contas_8!$C$2:$C$9,$A9) -> 0 | D9: =B9/COUNTA(Base_Contas_8!$B$2:$B$9) -> 0 | E9: 0.17647059 | F9: 0.19415449 | G9: Não (pode ser coincidência)
A11: Canal | B11: As 8 contas | C11: MRR perdido pelas 8 | D11: % das 8 | E11: % nas 68 reduções | F11: % das contas com Enterprise | G11: Diferente? (8 x demais reduções)
A12: ads | B12: =COUNTIFS(Base_Contas_8!$E$2:$E$9,$A12) -> 2 | C12: =SUMIFS(Base_Contas_8!$M$2:$M$9,Base_Contas_8!$E$2:$E$9,$A12) -> 8358 | D12: =B12/COUNTA(Base_Contas_8!$B$2:$B$9) -> 0.25 | E12: 0.22058824 | F12: 0.19832985 | G12: Não (pode ser coincidência)
A13: event | B13: =COUNTIFS(Base_Contas_8!$E$2:$E$9,$A13) -> 3 | C13: =SUMIFS(Base_Contas_8!$M$2:$M$9,Base_Contas_8!$E$2:$E$9,$A13) -> 31840 | D13: =B13/COUNTA(Base_Contas_8!$B$2:$B$9) -> 0.375 | E13: 0.23529412 | F13: 0.18997912 | G13: Não (pode ser coincidência)
A14: organic | B14: =COUNTIFS(Base_Contas_8!$E$2:$E$9,$A14) -> 0 | C14: =SUMIFS(Base_Contas_8!$M$2:$M$9,Base_Contas_8!$E$2:$E$9,$A14) -> 0 | D14: =B14/COUNTA(Base_Contas_8!$B$2:$B$9) -> 0 | E14: 0.22058824 | F14: 0.22964509 | G14: Não (pode ser coincidência)
A15: other | B15: =COUNTIFS(Base_Contas_8!$E$2:$E$9,$A15) -> 2 | C15: =SUMIFS(Base_Contas_8!$M$2:$M$9,Base_Contas_8!$E$2:$E$9,$A15) -> 23482 | D15: =B15/COUNTA(Base_Contas_8!$B$2:$B$9) -> 0.25 | E15: 0.14705882 | F15: 0.20250522 | G15: Não (pode ser coincidência)
A16: partner | B16: =COUNTIFS(Base_Contas_8!$E$2:$E$9,$A16) -> 1 | C16: =SUMIFS(Base_Contas_8!$M$2:$M$9,Base_Contas_8!$E$2:$E$9,$A16) -> 5174 | D16: =B16/COUNTA(Base_Contas_8!$B$2:$B$9) -> 0.125 | E16: 0.17647059 | F16: 0.17954071 | G16: Não (pode ser coincidência)
A18: País | B18: As 8 contas | C18: MRR perdido pelas 8 | D18: % das 8 | E18: % nas 68 reduções | F18: % das contas com Enterprise | G18: Diferente? (8 x demais reduções)
A19: AU | B19: =COUNTIFS(Base_Contas_8!$D$2:$D$9,$A19) -> 1 | C19: =SUMIFS(Base_Contas_8!$M$2:$M$9,Base_Contas_8!$D$2:$D$9,$A19) -> 7960 | D19: =B19/COUNTA(Base_Contas_8!$B$2:$B$9) -> 0.125 | E19: 0.088235294 | F19: 0.066805846 | G19: Poucos casos para concluir
A20: CA | B20: =COUNTIFS(Base_Contas_8!$D$2:$D$9,$A20) -> 0 | C20: =SUMIFS(Base_Contas_8!$M$2:$M$9,Base_Contas_8!$D$2:$D$9,$A20) -> 0 | D20: =B20/COUNTA(Base_Contas_8!$B$2:$B$9) -> 0 | E20: 0.014705882 | F20: 0.043841336 | G20: Poucos casos para concluir
A21: DE | B21: =COUNTIFS(Base_Contas_8!$D$2:$D$9,$A21) -> 0 | C21: =SUMIFS(Base_Contas_8!$M$2:$M$9,Base_Contas_8!$D$2:$D$9,$A21) -> 0 | D21: =B21/COUNTA(Base_Contas_8!$B$2:$B$9) -> 0 | E21: 0.073529412 | F21: 0.052192067 | G21: Poucos casos para concluir
A22: FR | B22: =COUNTIFS(Base_Contas_8!$D$2:$D$9,$A22) -> 0 | C22: =SUMIFS(Base_Contas_8!$M$2:$M$9,Base_Contas_8!$D$2:$D$9,$A22) -> 0 | D22: =B22/COUNTA(Base_Contas_8!$B$2:$B$9) -> 0 | E22: 0.073529412 | F22: 0.041753653 | G22: Poucos casos para concluir
A23: IN | B23: =COUNTIFS(Base_Contas_8!$D$2:$D$9,$A23) -> 1 | C23: =SUMIFS(Base_Contas_8!$M$2:$M$9,Base_Contas_8!$D$2:$D$9,$A23) -> 17114 | D23: =B23/COUNTA(Base_Contas_8!$B$2:$B$9) -> 0.125 | E23: 0.029411765 | F23: 0.098121086 | G23: Poucos casos para concluir
A24: UK | B24: =COUNTIFS(Base_Contas_8!$D$2:$D$9,$A24) -> 4 | C24: =SUMIFS(Base_Contas_8!$M$2:$M$9,Base_Contas_8!$D$2:$D$9,$A24) -> 33631 | D24: =B24/COUNTA(Base_Contas_8!$B$2:$B$9) -> 0.5 | E24: 0.20588235 | F24: 0.11691023 | G24: Não (pode ser coincidência)
A25: US | B25: =COUNTIFS(Base_Contas_8!$D$2:$D$9,$A25) -> 2 | C25: =SUMIFS(Base_Contas_8!$M$2:$M$9,Base_Contas_8!$D$2:$D$9,$A25) -> 10149 | D25: =B25/COUNTA(Base_Contas_8!$B$2:$B$9) -> 0.25 | E25: 0.51470588 | F25: 0.58037578 | G25: Não (pode ser coincidência)
A27: Leitura: as 8 se concentram em FinTech (4) e DevTools (3), e no Reino Unido (4). É um sinal para olhar, não uma conclusão: com 8 casos qualquer concentração pode ser coincidência. As colunas E e F (valores calculados pelo programa) servem de comparação.

Sheet Base_Assinaturas_8
A1: account_id | B1: subscription_id | C1: plan_tier | D1: seats | E1: mrr_amount | F1: cobranca | G1: trial | H1: start_date | I1: end_date | J1: fim_para_conta | K1: situacao_txt | L1: eh_a_reducao_analisada
A2: A-13466a | B2: S-2f8dbb | C2: Basic | D2: 2 | E2: 38 | F2: anual | G2: Não | H2: 45248 | I2: 45466 | J2: 45466 | K2: Redução real | L2: Não
A3: A-13466a | B3: S-af6536 | C3: Enterprise | D3: 40 | E3: 7960 | F3: mensal | G3: Não | H3: 45333 | I3: 45593 | J3: 45593 | K3: Redução real | L3: Sim
A4: A-13466a | B4: S-1c45b4 | C4: Basic | D4: 65 | E4: 0 | F4: mensal | G4: Sim | H4: 45402 | J4: 73050 | K4: Ativa em 31/12/2024 | L4: Não
A5: A-13466a | B5: S-063586 | C5: Enterprise | D5: 22 | E5: 4378 | F5: anual | G5: Não | H5: 45435 | I5: 45562 | J5: 45562 | K5: Migração | L5: Não
A6: A-13466a | B6: S-b89456 | C6: Enterprise | D6: 4 | E6: 796 | F6: mensal | G6: Não | H6: 45536 | I6: 45657 | J6: 45657 | K6: Redução real | L6: Não
A7: A-13466a | B7: S-3223a2 | C7: Basic | D7: 9 | E7: 171 | F7: anual | G7: Não | H7: 45555 | J7: 73050 | K7: Ativa em 31/12/2024 | L7: Não
A8: A-425e76 | B8: S-12ca50 | C8: Enterprise | D8: 8 | E8: 1592 | F8: mensal | G8: Não | H8: 45098 | J8: 73050 | K8: Ativa em 31/12/2024 | L8: Não
A9: A-425e76 | B9: S-6d356a | C9: Basic | D9: 28 | E9: 532 | F9: anual | G9: Não | H9: 45103 | J9: 73050 | K9: Ativa em 31/12/2024 | L9: Não
A10: A-425e76 | B10: S-2d3434 | C10: Pro | D10: 8 | E10: 392 | F10: anual | G10: Não | H10: 45129 | J10: 73050 | K10: Ativa em 31/12/2024 | L10: Não
A11: A-425e76 | B11: S-b45bc6 | C11: Enterprise | D11: 32 | E11: 6368 | F11: mensal | G11: Não | H11: 45156 | I11: 45231 | J11: 45231 | K11: Redução real | L11: Sim
A12: A-425e76 | B12: S-0d8293 | C12: Pro | D12: 71 | E12: 3479 | F12: mensal | G12: Não | H12: 45248 | J12: 73050 | K12: Ativa em 31/12/2024 | L12: Não
A13: A-425e76 | B13: S-2196c4 | C13: Basic | D13: 8 | E13: 152 | F13: mensal | G13: Não | H13: 45398 | J13: 73050 | K13: Ativa em 31/12/2024 | L13: Não
A14: A-425e76 | B14: S-f7f6d7 | C14: Basic | D14: 14 | E14: 266 | F14: mensal | G14: Não | H14: 45419 | J14: 73050 | K14: Ativa em 31/12/2024 | L14: Não
A15: A-425e76 | B15: S-3e0382 | C15: Basic | D15: 27 | E15: 513 | F15: mensal | G15: Não | H15: 45436 | J15: 73050 | K15: Ativa em 31/12/2024 | L15: Não
A16: A-425e76 | B16: S-25f647 | C16: Basic | D16: 37 | E16: 703 | F16: mensal | G16: Não | H16: 45483 | J16: 73050 | K16: Ativa em 31/12/2024 | L16: Não
A17: A-425e76 | B17: S-77f7fd | C17: Pro | D17: 27 | E17: 1323 | F17: mensal | G17: Não | H17: 45510 | J17: 73050 | K17: Ativa em 31/12/2024 | L17: Não
A18: A-425e76 | B18: S-18b808 | C18: Enterprise | D18: 9 | E18: 1791 | F18: anual | G18: Não | H18: 45517 | J18: 73050 | K18: Ativa em 31/12/2024 | L18: Não
A19: A-42e5e1 | B19: S-2881e0 | C19: Pro | D19: 1 | E19: 49 | F19: anual | G19: Não | H19: 45494 | J19: 73050 | K19: Ativa em 31/12/2024 | L19: Não
A20: A-42e5e1 | B20: S-a3cbd4 | C20: Enterprise | D20: 20 | E20: 3980 | F20: mensal | G20: Não | H20: 45505 | I20: 45518 | J20: 45518 | K20: Redução real | L20: Sim
A21: A-42e5e1 | B21: S-ce9977 | C21: Enterprise | D21: 53 | E21: 0 | F21: mensal | G21: Sim | H21: 45506 | J21: 73050 | K21: Ativa em 31/12/2024 | L21: Não
A22: A-42e5e1 | B22: S-860bc8 | C22: Basic | D22: 1 | E22: 19 | F22: anual | G22: Não | H22: 45533 | J22: 73050 | K22: Ativa em 31/12/2024 | L22: Não
A23: A-42e5e1 | B23: S-8426e7 | C23: Enterprise | D23: 22 | E23: 4378 | F23: anual | G23: Não | H23: 45583 | J23: 73050 | K23: Ativa em 31/12/2024 | L23: Não
A24: A-42e5e1 | B24: S-06e3cd | C24: Basic | D24: 22 | E24: 0 | F24: mensal | G24: Sim | H24: 45587 | J24: 73050 | K24: Ativa em 31/12/2024 | L24: Não
A25: A-42e5e1 | B25: S-9f7b07 | C25: Pro | D25: 10 | E25: 490 | F25: anual | G25: Não | H25: 45624 | J25: 73050 | K25: Ativa em 31/12/2024 | L25: Não
A26: A-69fad4 | B26: S-23281c | C26: Basic | D26: 15 | E26: 285 | F26: mensal | G26: Não | H26: 45131 | J26: 73050 | K26: Ativa em 31/12/2024 | L26: Não
A27: A-69fad4 | B27: S-2d4edf | C27: Enterprise | D27: 6 | E27: 1194 | F27: anual | G27: Não | H27: 45173 | J27: 73050 | K27: Ativa em 31/12/2024 | L27: Não
A28: A-69fad4 | B28: S-3eb9c8 | C28: Basic | D28: 35 | E28: 665 | F28: mensal | G28: Não | H28: 45176 | I28: 45333 | J28: 45333 | K28: Migração | L28: Não
A29: A-69fad4 | B29: S-fffeb8 | C29: Enterprise | D29: 10 | E29: 1990 | F29: anual | G29: Não | H29: 45277 | J29: 73050 | K29: Ativa em 31/12/2024 | L29: Não
A30: A-69fad4 | B30: S-1d63bf | C30: Enterprise | D30: 22 | E30: 4378 | F30: mensal | G30: Não | H30: 45323 | I30: 45523 | J30: 45523 | K30: Redução real | L30: Sim
A31: A-69fad4 | B31: S-b90a53 | C31: Basic | D31: 11 | E31: 209 | F31: anual | G31: Não | H31: 45332 | J31: 73050 | K31: Ativa em 31/12/2024 | L31: Não
A32: A-69fad4 | B32: S-e0179e | C32: Pro | D32: 13 | E32: 0 | F32: mensal | G32: Sim | H32: 45375 | J32: 73050 | K32: Ativa em 31/12/2024 | L32: Não
A33: A-8ae05d | B33: S-a54fb2 | C33: Basic | D33: 86 | E33: 1634 | F33: anual | G33: Não | H33: 45444 | J33: 73050 | K33: Ativa em 31/12/2024 | L33: Não
A34: A-8ae05d | B34: S-a1d3ad | C34: Basic | D34: 86 | E34: 0 | F34: mensal | G34: Sim | H34: 45452 | J34: 73050 | K34: Ativa em 31/12/2024 | L34: Não
A35: A-8ae05d | B35: S-be601b | C35: Basic | D35: 86 | E35: 1634 | F35: mensal | G35: Não | H35: 45480 | J35: 73050 | K35: Ativa em 31/12/2024 | L35: Não
A36: A-8ae05d | B36: S-55db9e | C36: Basic | D36: 86 | E36: 1634 | F36: anual | G36: Não | H36: 45523 | J36: 73050 | K36: Ativa em 31/12/2024 | L36: Não
A37: A-8ae05d | B37: S-f4b648 | C37: Enterprise | D37: 86 | E37: 17114 | F37: anual | G37: Não | H37: 45623 | I37: 45654 | J37: 45654 | K37: Redução real | L37: Sim
A38: A-8ae05d | B38: S-f74e00 | C38: Pro | D38: 86 | E38: 4214 | F38: mensal | G38: Não | H38: 45628 | J38: 73050 | K38: Ativa em 31/12/2024 | L38: Não
A39: A-8ae05d | B39: S-b8c3e6 | C39: Enterprise | D39: 86 | E39: 0 | F39: mensal | G39: Sim | H39: 45639 | J39: 73050 | K39: Ativa em 31/12/2024 | L39: Não
A40: A-bcf87c | B40: S-dc90ef | C40: Pro | D40: 17 | E40: 833 | F40: anual | G40: Não | H40: 45495 | J40: 73050 | K40: Ativa em 31/12/2024 | L40: Não
...

Sheet Base_Contas_8
A1: ordem | B1: account_id | C1: industry | D1: country | E1: referral_source | F1: signup_date | G1: subscription_id | H1: seats | I1: cobranca | J1: start_date | K1: end_date | L1: dias_de_vida | M1: mrr_perdido | N1: grupo | O1: gemea | P1: recuperou | Q1: eventos | R1: motivos | S1: tickets | T1: tickets_antes_cadastro
A2: 1 | B2: A-42e5e1 | C2: DevTools | D2: US | E2: ads | F2: 45482 | G2: S-a3cbd4 | H2: 20 | I2: mensal | J2: 45505 | K2: 45518 | L2: 13 | M2: 3980 | N2: B. Pacote antigo desligado (havia Enterprise mais nova) | O2: Não | P2: Sim — hoje paga mais do que antes | Q2: 1 | R2: pricing | S2: 3 | T2: 3
A3: 2 | B3: A-13466a | C3: DevTools | D3: AU | E3: event | F3: 45221 | G3: S-af6536 | H3: 40 | I3: mensal | J3: 45333 | K3: 45593 | L3: 260 | M3: 7960 | N3: B. Pacote antigo desligado (havia Enterprise mais nova) | O3: Não | P3: Não — continuou caindo | Q3: 2 | R3: support, pricing | S3: 3 | T3: 1
A4: 3 | B4: A-425e76 | C4: DevTools | D4: UK | E4: other | F4: 45063 | G4: S-b45bc6 | H4: 32 | I4: mensal | J4: 45156 | K4: 45231 | L4: 75 | M4: 6368 | N4: C. Redução pura (sem Enterprise mais nova) | O4: Não | P4: Sim — hoje paga mais do que antes | Q4: 4 | R4: competitor, budget, competitor, competitor | S4: 5 | T4: 1
A5: 4 | B5: A-f44180 | C5: Cybersecurity | D5: UK | E5: event | F5: 44970 | G5: S-7da02b | H5: 89 | I5: anual | J5: 45066 | K5: 45279 | L5: 213 | M5: 17711 | N5: B. Pacote antigo desligado (havia Enterprise mais nova) | O5: Não | P5: Não — perda mantida | Q5: 1 | R5: competitor | S5: 2 | T5: 0
A6: 5 | B6: A-8ae05d | C6: FinTech | D6: IN | E6: other | F6: 45388 | G6: S-f4b648 | H6: 86 | I6: anual | J6: 45623 | K6: 45654 | L6: 31 | M6: 17114 | N6: B. Pacote antigo desligado (havia Enterprise mais nova) | O6: Sim | P6: Não — perda mantida | Q6: 1 | R6: unknown | S6: 1 | T6: 1
A7: 6 | B7: A-bcf87c | C7: FinTech | D7: US | E7: event | F7: 45470 | G7: S-c75159 | H7: 31 | I7: mensal | J7: 45526 | K7: 45563 | L7: 37 | M7: 6169 | N7: B. Pacote antigo desligado (havia Enterprise mais nova) | O7: Não | P7: Sim — hoje paga mais do que antes | Q7: 0 | R7: — | S7: 2 | T7: 2
A8: 7 | B8: A-c45b23 | C8: FinTech | D8: UK | E8: partner | F8: 45268 | G8: S-2361ec | H8: 26 | I8: anual | J8: 45638 | K8: 45641 | L8: 3 | M8: 5174 | N8: A. Compra extra desfeita | O8: Não | P8: Compra a mais desfeita — voltou ao valor de antes da compra | Q8: 1 | R8: support | S8: 3 | T8: 0
A9: 8 | B9: A-69fad4 | C9: FinTech | D9: UK | E9: ads | F9: 45022 | G9: S-1d63bf | H9: 22 | I9: mensal | J9: 45323 | K9: 45523 | L9: 200 | M9: 4378 | N9: C. Redução pura (sem Enterprise mais nova) | O9: Não | P9: Não — perda mantida | Q9: 1 | R9: support | S9: 4 | T9: 0
