Workbook

Sheet LEIA-ME
B1: PERDA REAL x "CHURN" CONTADO HOJE — por trimestre, em quantidade e em US$
B2: Planilha apartada. Lê os CSVs originais sem alterá-los. Base: tabela de assinaturas (a única coerente). Valores em MRR (receita mensal).
B4: COMO CADA ASSINATURA ENCERRADA FOI CLASSIFICADA
B5: • Migração (troca): a mesma conta abriu outra assinatura até 7 dias antes ou depois. NÃO é perda; em US$, só a diferença entre a encerrada e a nova conta.
B6: • Compra extra desfeita: a assinatura durou até 30 dias e a conta já tinha outra assinatura MAIS ANTIGA do mesmo plano ativa. A conta desfez uma compra a mais e voltou ao que pagava antes. NÃO é perda.
B7: • Redução real: a conta desligou uma assinatura (sem troca e sem ser compra extra recente) e continuou cliente. É perda de receita.
B8: • Saída do cliente: a conta ficou sem nenhuma assinatura ativa. É perda (só 4 casos em 24 meses, e todos voltaram depois).
B9: • Por que assinaturas "gêmeas" (mesmo plano e mesmos seats) com mais de 30 dias continuam como perda: na base, quase metade das assinaturas ativas tem uma gêmea; ter uma igual não prova troca.
B11: RESULTADO EM 24 MESES (jan/23–dez/24)
B12: • "Churn" como contado hoje: 486 assinaturas encerradas. US$ 1.179.139 de MRR.
B13: • Não era perda: 233 migrações (reposto US$ 460.780) e 64 compras extras desfeitas (US$ 180.445).
B14: • PERDA REAL: 189 assinaturas e US$ 537.914 de MRR = 46% do "churn" de hoje: redução real US$ 400.148, saída US$ 23.406 e diferença nas trocas US$ 114.360.
... B23: • Base fictícia. As janelas de 7 dias (troca) e 30 dias (compra extra) são escolhas da análise. Diferença em relação à planilha 07 (US$ 718 mil de perda real): aqui a compra extra desfeita deixou de contar como perda.

Sheet 1_Resumo_CEO
A1: Churn: o que é contado hoje x o que foi perda de verdade
A2: Por trimestre, jan/23–dez/24. Barras cinzas = como o churn é contado hoje (toda assinatura encerrada). Barras vermelhas = perda real (redução real + saída do cliente; em US$, também a diferença nas trocas). Detalhes nas abas 2, 3 e 4.
A4: Trimestre | B4: Quantidade: "churn" de hoje | C4: Quantidade: perda real | D4: US$: "churn" de hoje | E4: US$: perda real | F4: % perda real (US$)
A5: 2023-T1 | B5: =2_Quantidade!B5 -> 0 | C5: =2_Quantidade!G5 -> 0 | D5: ='3_Valor_US$'!B5 -> 0 | E5: ='3_Valor_US$'!I5 -> 0 | F5: =IF(D5>0,E5/D5,"")
A6: 2023-T2 | B6: =2_Quantidade!B6 -> 2 | C6: =2_Quantidade!G6 -> 1 | D6: ='3_Valor_US$'!B6 -> 1421 | E6: ='3_Valor_US$'!I6 -> 1421 | F6: =IF(D6>0,E6/D6,"") -> 1
A7: 2023-T3 | B7: =2_Quantidade!B7 -> 2 | C7: =2_Quantidade!G7 -> 1 | D7: ='3_Valor_US$'!B7 -> 914 | E7: ='3_Valor_US$'!I7 -> 496 | F7: =IF(D7>0,E7/D7,"") -> 0.54266958
A8: 2023-T4 | B8: =2_Quantidade!B8 -> 14 | C8: =2_Quantidade!G8 -> 11 | D8: ='3_Valor_US$'!B8 -> 49160 | E8: ='3_Valor_US$'!I8 -> 46218 | F8: =IF(D8>0,E8/D8,"") -> 0.9401546
A9: 2024-T1 | B9: =2_Quantidade!B9 -> 27 | C9: =2_Quantidade!G9 -> 20 | D9: ='3_Valor_US$'!B9 -> 50138 | E9: ='3_Valor_US$'!I9 -> 44828 | F9: =IF(D9>0,E9/D9,"") -> 0.89409231
A10: 2024-T2 | B10: =2_Quantidade!B10 -> 37 | C10: =2_Quantidade!G10 -> 29 | D10: ='3_Valor_US$'!B10 -> 59026 | E10: ='3_Valor_US$'!I10 -> 36192 | F10: =IF(D10>0,E10/D10,"") -> 0.61315353
A11: 2024-T3 | B11: =2_Quantidade!B11 -> 80 | C11: =2_Quantidade!G11 -> 43 | D11: ='3_Valor_US$'!B11 -> 146668 | E11: ='3_Valor_US$'!I11 -> 77445 | F11: =IF(D11>0,E11/D11,"") -> 0.52802929
A12: 2024-T4 | B12: =2_Quantidade!B12 -> 324 | C12: =2_Quantidade!G12 -> 84 | D12: ='3_Valor_US$'!B12 -> 871812 | E12: ='3_Valor_US$'!I12 -> 331314 | F12: =IF(D12>0,E12/D12,"") -> 0.38002918
A13: Total 24 meses | B13: =SUM(B5:B12) -> 486 | C13: =SUM(C5:C12) -> 189 | D13: =SUM(D5:D12) -> 1179139 | E13: =SUM(E5:E12) -> 537914 | F13: =E13/D13 -> 0.45619219
A15: Leitura: até o 1º trimestre de 2024, quase todo o "churn" contado era perda real (≈90% em US$), mas pequena. No 2º e 3º trimestres de 2024, só cerca de 55–60% era perda. No 4º trimestre de 2024 o "churn" de hoje dispara (US$ 872 mil), mas só 38% (US$ 331 mil) foi perda real: o resto foram trocas e compras extras desfeitas. A perda real também cresce no 4º trimestre, puxada por reduções de assinaturas Enterprise.

Sheet 2_Quantidade
A1: Assinaturas encerradas por trimestre: o que foi perda e o que não foi (quantidade)
A2: Cada assinatura encerrada é contada hoje como "churn". Aqui ela é separada em: Migração (a conta abriu outra assinatura até 7 dias antes/depois — troca, não é perda), Compra extra desfeita (assinatura com até 30 dias, a conta já tinha outra mais antiga do mesmo plano ativa — desfez uma compra a mais, não é perda), Redução real (a conta desligou uma assinatura e seguiu cliente — perda) e Saída do cliente (ficou sem assinatura — perda).
A4: Trimestre do fim | B4: "Churn" como contado hoje (assinaturas encerradas) | C4: Migração (troca) | D4: Compra extra desfeita | E4: Redução real | F4: Saída do cliente | G4: PERDA REAL (redução real + saída) | H4: NÃO era perda (migração + compra extra) | I4: % do "churn" de hoje que é perda real
A5: 2023-T1 | B5: =COUNTIFS(Base_Encerradas!$J$2:$J$487,$A5) -> 0 | C5: =COUNTIFS(Base_Encerradas!$J$2:$J$487,$A5,Base_Encerradas!$K$2:$K$487,"Migração") -> 0 | D5: =COUNTIFS(Base_Encerradas!$J$2:$J$487,$A5,Base_Encerradas!$K$2:$K$487,"Compra extra desfeita") -> 0 | E5: =COUNTIFS(Base_Encerradas!$J$2:$J$487,$A5,Base_Encerradas!$K$2:$K$487,"Redução real") -> 0 | F5: =COUNTIFS(Base_Encerradas!$J$2:$J$487,$A5,Base_Encerradas!$K$2:$K$487,"Saída do cliente") -> 0 | G5: =E5+F5 -> 0 | H5: =C5+D5 -> 0 | I5: =IF(B5>0,G5/B5,"")
A6: 2023-T2 | B6: =COUNTIFS(Base_Encerradas!$J$2:$J$487,$A6) -> 2 | C6: =COUNTIFS(Base_Encerradas!$J$2:$J$487,$A6,Base_Encerradas!$K$2:$K$487,"Migração") -> 1 | D6: =COUNTIFS(Base_Encerradas!$J$2:$J$487,$A6,Base_Encerradas!$K$2:$K$487,"Compra extra desfeita") -> 0 | E6: =COUNTIFS(Base_Encerradas!$J$2:$J$487,$A6,Base_Encerradas!$K$2:$K$487,"Redução real") -> 1 | F6: =COUNTIFS(Base_Encerradas!$J$2:$J$487,$A6,Base_Encerradas!$K$2:$K$487,"Saída do cliente") -> 0 | G6: =E6+F6 -> 1 | H6: =C6+D6 -> 1 | I6: =IF(B6>0,G6/B6,"") -> 0.5
A7: 2023-T3 | B7: =COUNTIFS(Base_Encerradas!$J$2:$J$487,$A7) -> 2 | C7: =COUNTIFS(Base_Encerradas!$J$2:$J$487,$A7,Base_Encerradas!$K$2:$K$487,"Migração") -> 1 | D7: =COUNTIFS(Base_Encerradas!$J$2:$J$487,$A7,Base_Encerradas!$K$2:$K$487,"Compra extra desfeita") -> 0 | E7: =COUNTIFS(Base_Encerradas!$J$2:$J$487,$A7,Base_Encerradas!$K$2:$K$487,"Redução real") -> 1 | F7: =COUNTIFS(Base_Encerradas!$J$2:$J$487,$A7,Base_Encerradas!$K$2:$K$487,"Saída do cliente") -> 0 | G7: =E7+F7 -> 1 | H7: =C7+D7 -> 1 | I7: =IF(B7>0,G7/B7,"") -> 0.5
A8: 2023-T4 | B8: =COUNTIFS(Base_Encerradas!$J$2:$J$487,$A8) -> 14 | C8: =COUNTIFS(Base_Encerradas!$J$2:$J$487,$A8,Base_Encerradas!$K$2:$K$487,"Migração") -> 3 | D8: =COUNTIFS(Base_Encerradas!$J$2:$J$487,$A8,Base_Encerradas!$K$2:$K$487,"Compra extra desfeita") -> 0 | E8: =COUNTIFS(Base_Encerradas!$J$2:$J$487,$A8,Base_Encerradas!$K$2:$K$487,"Redução real") -> 10 | F8: =COUNTIFS(Base_Encerradas!$J$2:$J$487,$A8,Base_Encerradas!$K$2:$K$487,"Saída do cliente") -> 1 | G8: =E8+F8 -> 11 | H8: =C8+D8 -> 3 | I8: =IF(B8>0,G8/B8,"") -> 0.78571429
A9: 2024-T1 | B9: =COUNTIFS(Base_Encerradas!$J$2:$J$487,$A9) -> 27 | C9: =COUNTIFS(Base_Encerradas!$J$2:$J$487,$A9,Base_Encerradas!$K$2:$K$487,"Migração") -> 5 | D9: =COUNTIFS(Base_Encerradas!$J$2:$J$487,$A9,Base_Encerradas!$K$2:$K$487,"Compra extra desfeita") -> 2 | E9: =COUNTIFS(Base_Encerradas!$J$2:$J$487,$A9,Base_Encerradas!$K$2:$K$487,"Redução real") -> 19 | F9: =COUNTIFS(Base_Encerradas!$J$2:$J$487,$A9,Base_Encerradas!$K$2:$K$487,"Saída do cliente") -> 1 | G9: =E9+F9 -> 20 | H9: =C9+D9 -> 7 | I9: =IF(B9>0,G9/B9,"") -> 0.74074074
A10: 2024-T2 | B10: =COUNTIFS(Base_Encerradas!$J$2:$J$487,$A10) -> 37 | C10: =COUNTIFS(Base_Encerradas!$J$2:$J$487,$A10,Base_Encerradas!$K$2:$K$487,"Migração") -> 7 | D10: =COUNTIFS(Base_Encerradas!$J$2:$J$487,$A10,Base_Encerradas!$K$2:$K$487,"Compra extra desfeita") -> 1 | E10: =COUNTIFS(Base_Encerradas!$J$2:$J$487,$A10,Base_Encerradas!$K$2:$K$487,"Redução real") -> 28 | F10: =COUNTIFS(Base_Encerradas!$J$2:$J$487,$A10,Base_Encerradas!$K$2:$K$487,"Saída do cliente") -> 1 | G10: =E10+F10 -> 29 | H10: =C10+D10 -> 8 | I10: =IF(B10>0,G10/B10,"") -> 0.78378378
A11: 2024-T3 | B11: =COUNTIFS(Base_Encerradas!$J$2:$J$487,$A11) -> 80 | C11: =COUNTIFS(Base_Encerradas!$J$2:$J$487,$A11,Base_Encerradas!$K$2:$K$487,"Migração") -> 31 | D11: =COUNTIFS(Base_Encerradas!$J$2:$J$487,$A11,Base_Encerradas!$K$2:$K$487,"Compra extra desfeita") -> 6 | E11: =COUNTIFS(Base_Encerradas!$J$2:$J$487,$A11,Base_Encerradas!$K$2:$K$487,"Redução real") -> 42 | F11: =COUNTIFS(Base_Encerradas!$J$2:$J$487,$A11,Base_Encerradas!$K$2:$K$487,"Saída do cliente") -> 1 | G11: =E11+F11 -> 43 | H11: =C11+D11 -> 37 | I11: =IF(B11>0,G11/B11,"") -> 0.5375
A12: 2024-T4 | B12: =COUNTIFS(Base_Encerradas!$J$2:$J$487,$A12) -> 324 | C12: =COUNTIFS(Base_Encerradas!$J$2:$J$487,$A12,Base_Encerradas!$K$2:$K$487,"Migração") -> 185 | D12: =COUNTIFS(Base_Encerradas!$J$2:$J$487,$A12,Base_Encerradas!$K$2:$K$487,"Compra extra desfeita") -> 55 | E12: =COUNTIFS(Base_Encerradas!$J$2:$J$487,$A12,Base_Encerradas!$K$2:$K$487,"Redução real") -> 84 | F12: =COUNTIFS(Base_Encerradas!$J$2:$J$487,$A12,Base_Encerradas!$K$2:$K$487,"Saída do cliente") -> 0 | G12: =E12+F12 -> 84 | H12: =C12+D12 -> 240 | I12: =IF(B12>0,G12/B12,"") -> 0.25925926
A13: Total 24 meses | B13: =SUM(B5:B12) -> 486 | C13: =SUM(C5:C12) -> 233 | D13: =SUM(D5:D12) -> 64 | E13: =SUM(E5:E12) -> 185 | F13: =SUM(F5:F12) -> 4 | G13: =SUM(G5:G12) -> 189 | H13: =SUM(H5:H12) -> 297 | I13: =G13/B13 -> 0.38888889

Sheet 3_Valor_US$
A1: MRR encerrado por trimestre: o que foi perda de receita e o que não foi (US$ por mês)
A2: Valores em MRR (receita mensal). Na migração, a assinatura encerrada foi trocada por outra: o "reposto" é o MRR da assinatura nova (cada nova contada uma única vez) e só a DIFERENÇA é perda (ou ganho, se a nova for mais cara). Compra extra desfeita não é perda. PERDA REAL = diferença nas trocas + redução real + saída.
A4: Trimestre do fim | B4: "Churn" de receita como contado hoje | C4: Migração: MRR encerrado | D4: Migração: MRR reposto na assinatura nova | E4: Migração: diferença (encerrado − reposto) | F4: Compra extra desfeita | G4: Redução real | H4: Saída do cliente | I4: PERDA REAL | J4: NÃO era perda | K4: % do "churn" de hoje que é perda real | L4: Gráfico: reposto (até o encerrado) | M4: Gráfico: diferença perdida na troca | N4: Gráfico: ganho na troca
A5: 2023-T1 | B5: =SUMIFS(Base_Encerradas!$F$2:$F$487,Base_Encerradas!$J$2:$J$487,$A5) -> 0 | C5: =SUMIFS(Base_Encerradas!$F$2:$F$487,Base_Encerradas!$J$2:$J$487,$A5,Base_Encerradas!$K$2:$K$487,"Migração") -> 0 | D5: =SUMIFS(Base_Encerradas!$M$2:$M$487,Base_Encerradas!$J$2:$J$487,$A5,Base_Encerradas!$K$2:$K$487,"Migração") -> 0 | E5: =C5-D5 -> 0 | F5: =SUMIFS(Base_Encerradas!$F$2:$F$487,Base_Encerradas!$J$2:$J$487,$A5,Base_Encerradas!$K$2:$K$487,"Compra extra desfeita") -> 0 | G5: =SUMIFS(Base_Encerradas!$F$2:$F$487,Base_Encerradas!$J$2:$J$487,$A5,Base_Encerradas!$K$2:$K$487,"Redução real") -> 0 | H5: =SUMIFS(Base_Encerradas!$F$2:$F$487,Base_Encerradas!$J$2:$J$487,$A5,Base_Encerradas!$K$2:$K$487,"Saída do cliente") -> 0 | I5: =E5+G5+H5 -> 0 | J5: =B5-I5 -> 0 | K5: =IF(B5>0,I5/B5,"") | L5: =MIN(C5,D5) -> 0 | M5: =MAX(0,E5) -> 0 | N5: =MAX(0,-E5) -> 0
A6: 2023-T2 | B6: =SUMIFS(Base_Encerradas!$F$2:$F$487,Base_Encerradas!$J$2:$J$487,$A6) -> 1421 | C6: =SUMIFS(Base_Encerradas!$F$2:$F$487,Base_Encerradas!$J$2:$J$487,$A6,Base_Encerradas!$K$2:$K$487,"Migração") -> 245 | D6: =SUMIFS(Base_Encerradas!$M$2:$M$487,Base_Encerradas!$J$2:$J$487,$A6,Base_Encerradas!$K$2:$K$487,"Migração") -> 0 | E6: =C6-D6 -> 245 | F6: =SUMIFS(Base_Encerradas!$F$2:$F$487,Base_Encerradas!$J$2:$J$487,$A6,Base_Encerradas!$K$2:$K$487,"Compra extra desfeita") -> 0 | G6: =SUMIFS(Base_Encerradas!$F$2:$F$487,Base_Encerradas!$J$2:$J$487,$A6,Base_Encerradas!$K$2:$K$487,"Redução real") -> 1176 | H6: =SUMIFS(Base_Encerradas!$F$2:$F$487,Base_Encerradas!$J$2:$J$487,$A6,Base_Encerradas!$K$2:$K$487,"Saída do cliente") -> 0 | I6: =E6+G6+H6 -> 1421 | J6: =B6-I6 -> 0 | K6: =IF(B6>0,I6/B6,"") -> 1 | L6: =MIN(C6,D6) -> 0 | M6: =MAX(0,E6) -> 245 | N6: =MAX(0,-E6) -> 0
A7: 2023-T3 | B7: =SUMIFS(Base_Encerradas!$F$2:$F$487,Base_Encerradas!$J$2:$J$487,$A7) -> 914 | C7: =SUMIFS(Base_Encerradas!$F$2:$F$487,Base_Encerradas!$J$2:$J$487,$A7,Base_Encerradas!$K$2:$K$487,"Migração") -> 228 | D7: =SUMIFS(Base_Encerradas!$M$2:$M$487,Base_Encerradas!$J$2:$J$487,$A7,Base_Encerradas!$K$2:$K$487,"Migração") -> 418 | E7: =C7-D7 -> -190 | F7: =SUMIFS(Base_Encerradas!$F$2:$F$487,Base_Encerradas!$J$2:$J$487,$A7,Base_Encerradas!$K$2:$K$487,"Compra extra desfeita") -> 0 | G7: =SUMIFS(Base_Encerradas!$F$2:$F$487,Base_Encerradas!$J$2:$J$487,$A7,Base_Encerradas!$K$2:$K$487,"Redução real") -> 686 | H7: =SUMIFS(Base_Encerradas!$F$2:$F$487,Base_Encerradas!$J$2:$J$487,$A7,Base_Encerradas!$K$2:$K$487,"Saída do cliente") -> 0 | I7: =E7+G7+H7 -> 496 | J7: =B7-I7 -> 418 | K7: =IF(B7>0,I7/B7,"") -> 0.54266958 | L7: =MIN(C7,D7) -> 228 | M7: =MAX(0,E7) -> 0 | N7: =MAX(0,-E7) -> 190
A8: 2023-T4 | B8: =SUMIFS(Base_Encerradas!$F$2:$F$487,Base_Encerradas!$J$2:$J$487,$A8) -> 49160 | C8: =SUMIFS(Base_Encerradas!$F$2:$F$487,Base_Encerradas!$J$2:$J$487,$A8,Base_Encerradas!$K$2:$K$487,"Migração") -> 5083 | D8: =SUMIFS(Base_Encerradas!$M$2:$M$487,Base_Encerradas!$J$2:$J$487,$A8,Base_Encerradas!$K$2:$K$487,"Migração") -> 2942 | E8: =C8-D8 -> 2141 | F8: =SUMIFS(Base_Encerradas!$F$2:$F$487,Base_Encerradas!$J$2:$J$487,$A8,Base_Encerradas!$K$2:$K$487,"Compra extra desfeita") -> 0 | G8: =SUMIFS(Base_Encerradas!$F$2:$F$487,Base_Encerradas!$J$2:$J$487,$A8,Base_Encerradas!$K$2:$K$487,"Redução real") -> 31341 | H8: =SUMIFS(Base_Encerradas!$F$2:$F$487,Base_Encerradas!$J$2:$J$487,$A8,Base_Encerradas!$K$2:$K$487,"Saída do cliente") -> 12736 | I8: =E8+G8+H8 -> 46218 | J8: =B8-I8 -> 2942 | K8: =IF(B8>0,I8/B8,"") -> 0.9401546 | L8: =MIN(C8,D8) -> 2942 | M8: =MAX(0,E8) -> 2141 | N8: =MAX(0,-E8) -> 0
A9: 2024-T1 | B9: =SUMIFS(Base_Encerradas!$F$2:$F$487,Base_Encerradas!$J$2:$J$487,$A9) -> 50138 | C9: =SUMIFS(Base_Encerradas!$F$2:$F$487,Base_Encerradas!$J$2:$J$487,$A9,Base_Encerradas!$K$2:$K$487,"Migração") -> 17055 | D9: =SUMIFS(Base_Encerradas!$M$2:$M$487,Base_Encerradas!$J$2:$J$487,$A9,Base_Encerradas!$K$2:$K$487,"Migração") -> 2860 | E9: =C9-D9 -> 14195 | F9: =SUMIFS(Base_Encerradas!$F$2:$F$487,Base_Encerradas!$J$2:$J$487,$A9,Base_Encerradas!$K$2:$K$487,"Compra extra desfeita") -> 2450 | G9: =SUMIFS(Base_Encerradas!$F$2:$F$487,Base_Encerradas!$J$2:$J$487,$A9,Base_Encerradas!$K$2:$K$487,"Redução real") -> 27449 | H9: =SUMIFS(Base_Encerradas!$F$2:$F$487,Base_Encerradas!$J$2:$J$487,$A9,Base_Encerradas!$K$2:$K$487,"Saída do cliente") -> 3184 | I9: =E9+G9+H9 -> 44828 | J9: =B9-I9 -> 5310 | K9: =IF(B9>0,I9/B9,"") -> 0.89409231 | L9: =MIN(C9,D9) -> 2860 | M9: =MAX(0,E9) -> 14195 | N9: =MAX(0,-E9) -> 0
A10: 2024-T2 | B10: =SUMIFS(Base_Encerradas!$F$2:$F$487,Base_Encerradas!$J$2:$J$487,$A10) -> 59026 | C10: =SUMIFS(Base_Encerradas!$F$2:$F$487,Base_Encerradas!$J$2:$J$487,$A10,Base_Encerradas!$K$2:$K$487,"Migração") -> 4102 | D10: =SUMIFS(Base_Encerradas!$M$2:$M$487,Base_Encerradas!$J$2:$J$487,$A10,Base_Encerradas!$K$2:$K$487,"Migração") -> 20645 | E10: =C10-D10 -> -16543 | F10: =SUMIFS(Base_Encerradas!$F$2:$F$487,Base_Encerradas!$J$2:$J$487,$A10,Base_Encerradas!$K$2:$K$487,"Compra extra desfeita") -> 2189 | G10: =SUMIFS(Base_Encerradas!$F$2:$F$487,Base_Encerradas!$J$2:$J$487,$A10,Base_Encerradas!$K$2:$K$487,"Redução real") -> 51020 | H10: =SUMIFS(Base_Encerradas!$F$2:$F$487,Base_Encerradas!$J$2:$J$487,$A10,Base_Encerradas!$K$2:$K$487,"Saída do cliente") -> 1715 | I10: =E10+G10+H10 -> 36192 | J10: =B10-I10 -> 22834 | K10: =IF(B10>0,I10/B10,"") -> 0.61315353 | L10: =MIN(C10,D10) -> 4102 | M10: =MAX(0,E10) -> 0 | N10: =MAX(0,-E10) -> 16543
A11: 2024-T3 | B11: =SUMIFS(Base_Encerradas!$F$2:$F$487,Base_Encerradas!$J$2:$J$487,$A11) -> 146668 | C11: =SUMIFS(Base_Encerradas!$F$2:$F$487,Base_Encerradas!$J$2:$J$487,$A11,Base_Encerradas!$K$2:$K$487,"Migração") -> 73811 | D11: =SUMIFS(Base_Encerradas!$M$2:$M$487,Base_Encerradas!$J$2:$J$487,$A11,Base_Encerradas!$K$2:$K$487,"Migração") -> 61892 | E11: =C11-D11 -> 11919 | F11: =SUMIFS(Base_Encerradas!$F$2:$F$487,Base_Encerradas!$J$2:$J$487,$A11,Base_Encerradas!$K$2:$K$487,"Compra extra desfeita") -> 7331 | G11: =SUMIFS(Base_Encerradas!$F$2:$F$487,Base_Encerradas!$J$2:$J$487,$A11,Base_Encerradas!$K$2:$K$487,"Redução real") -> 59755 | H11: =SUMIFS(Base_Encerradas!$F$2:$F$487,Base_Encerradas!$J$2:$J$487,$A11,Base_Encerradas!$K$2:$K$487,"Saída do cliente") -> 5771 | I11: =E11+G11+H11 -> 77445 | J11: =B11-I11 -> 69223 | K11: =IF(B11>0,I11/B11,"") -> 0.52802929 | L11: =MIN(C11,D11) -> 61892 | M11: =MAX(0,E11) -> 11919 | N11: =MAX(0,-E11) -> 0
A12: 2024-T4 | B12: =SUMIFS(Base_Encerradas!$F$2:$F$487,Base_Encerradas!$J$2:$J$487,$A12) -> 871812 | C12: =SUMIFS(Base_Encerradas!$F$2:$F$487,Base_Encerradas!$J$2:$J$487,$A12,Base_Encerradas!$K$2:$K$487,"Migração") -> 474616 | D12: =SUMIFS(Base_Encerradas!$M$2:$M$487,Base_Encerradas!$J$2:$J$487,$A12,Base_Encerradas!$K$2:$K$487,"Migração") -> 372023 | E12: =C12-D12 -> 102593 | F12: =SUMIFS(Base_Encerradas!$F$2:$F$487,Base_Encerradas!$J$2:$J$487,$A12,Base_Encerradas!$K$2:$K$487,"Compra extra desfeita") -> 168475 | G12: =SUMIFS(Base_Encerradas!$F$2:$F$487,Base_Encerradas!$J$2:$J$487,$A12,Base_Encerradas!$K$2:$K$487,"Redução real") -> 228721 | H12: =SUMIFS(Base_Encerradas!$F$2:$F$487,Base_Encerradas!$J$2:$J$487,$A12,Base_Encerradas!$K$2:$K$487,"Saída do cliente") -> 0 | I12: =E12+G12+H12 -> 331314 | J12: =B12-I12 -> 540498 | K12: =IF(B12>0,I12/B12,"") -> 0.38002918 | L12: =MIN(C12,D12) -> 372023 | M12: =MAX(0,E12) -> 102593 | N12: =MAX(0,-E12) -> 0
A13: Total 24 meses | B13: =SUM(B5:B12) -> 1179139 | C13: =SUM(C5:C12) -> 575140 | D13: =SUM(D5:D12) -> 460780 | E13: =SUM(E5:E12) -> 114360 | F13: =SUM(F5:F12) -> 180445 | G13: =SUM(G5:G12) -> 400148 | H13: =SUM(H5:H12) -> 23406 | I13: =SUM(I5:I12) -> 537914 | J13: =SUM(J5:J12) -> 641225 | K13: =I13/B13 -> 0.45619219 | L13: =SUM(L5:L12) -> 444047 | M13: =SUM(M5:M12) -> 131093 | N13: =SUM(N5:N12) -> 16733
A14: Colunas L a N só alimentam o gráfico. Quando a assinatura nova é mais cara que a encerrada (ganho na troca, coluna N), o ganho já está descontado da PERDA REAL (coluna I).

Sheet 4_Por_plano
A1: Por plano, 24 meses: "churn" de hoje x perda por redução e saída
A2: Mesmas regras das abas 2 e 3, somando jan/23–dez/24. As trocas (migrações) ficam fora da perda por plano porque muitas mudam de plano (ex.: encerra Basic e abre Enterprise): o saldo das trocas só faz sentido no total.
A4: Plano | B4: Encerradas | C4: Migração | D4: Compra extra desfeita | E4: Redução real | F4: Saída | G4: "Churn" de hoje (US$) | H4: Migração: MRR encerrado (US$) | I4: Compra extra desfeita (US$) | J4: PERDA do plano: redução real + saída (US$) | K4: % do "churn" de hoje
A5: Basic | B5: =COUNTIFS(Base_Encerradas!$C$2:$C$487,$A5) -> 152 | C5: =COUNTIFS(Base_Encerradas!$C$2:$C$487,$A5,Base_Encerradas!$K$2:$K$487,"Migração") -> 73 | D5: =COUNTIFS(Base_Encerradas!$C$2:$C$487,$A5,Base_Encerradas!$K$2:$K$487,"Compra extra desfeita") -> 18 | E5: =COUNTIFS(Base_Encerradas!$C$2:$C$487,$A5,Base_Encerradas!$K$2:$K$487,"Redução real") -> 61 | F5: =COUNTIFS(Base_Encerradas!$C$2:$C$487,$A5,Base_Encerradas!$K$2:$K$487,"Saída do cliente") -> 0 | G5: =SUMIFS(Base_Encerradas!$F$2:$F$487,Base_Encerradas!$C$2:$C$487,$A5) -> 72523 | H5: =SUMIFS(Base_Encerradas!$F$2:$F$487,Base_Encerradas!$C$2:$C$487,$A5,Base_Encerradas!$K$2:$K$487,"Migração") -> 39159 | I5: =SUMIFS(Base_Encerradas!$F$2:$F$487,Base_Encerradas!$C$2:$C$487,$A5,Base_Encerradas!$K$2:$K$487,"Compra extra desfeita") -> 7163 | J5: =SUMIFS(Base_Encerradas!$F$2:$F$487,Base_Encerradas!$C$2:$C$487,$A5,Base_Encerradas!$K$2:$K$487,"Redução real")+SUMIFS(Base_Encerradas!$F$2:$F$487,Base_Encerradas!$C$2:$C$487,$A5,Base_Encerradas!$K$2:$K$487,"Saída do cliente") -> 26201 | K5: =J5/G5 -> 0.36127849
A6: Pro | B6: =COUNTIFS(Base_Encerradas!$C$2:$C$487,$A6) -> 162 | C6: =COUNTIFS(Base_Encerradas!$C$2:$C$487,$A6,Base_Encerradas!$K$2:$K$487,"Migração") -> 80 | D6: =COUNTIFS(Base_Encerradas!$C$2:$C$487,$A6,Base_Encerradas!$K$2:$K$487,"Compra extra desfeita") -> 25 | E6: =COUNTIFS(Base_Encerradas!$C$2:$C$487,$A6,Base_Encerradas!$K$2:$K$487,"Redução real") -> 56 | F6: =COUNTIFS(Base_Encerradas!$C$2:$C$487,$A6,Base_Encerradas!$K$2:$K$487,"Saída do cliente") -> 1 | G6: =SUMIFS(Base_Encerradas!$F$2:$F$487,Base_Encerradas!$C$2:$C$487,$A6) -> 180271 | H6: =SUMIFS(Base_Encerradas!$F$2:$F$487,Base_Encerradas!$C$2:$C$487,$A6,Base_Encerradas!$K$2:$K$487,"Migração") -> 89425 | I6: =SUMIFS(Base_Encerradas!$F$2:$F$487,Base_Encerradas!$C$2:$C$487,$A6,Base_Encerradas!$K$2:$K$487,"Compra extra desfeita") -> 25823 | J6: =SUMIFS(Base_Encerradas!$F$2:$F$487,Base_Encerradas!$C$2:$C$487,$A6,Base_Encerradas!$K$2:$K$487,"Redução real")+SUMIFS(Base_Encerradas!$F$2:$F$487,Base_Encerradas!$C$2:$C$487,$A6,Base_Encerradas!$K$2:$K$487,"Saída do cliente") -> 65023 | K6: =J6/G6 -> 0.36069584
A7: Enterprise | B7: =COUNTIFS(Base_Encerradas!$C$2:$C$487,$A7) -> 172 | C7: =COUNTIFS(Base_Encerradas!$C$2:$C$487,$A7,Base_Encerradas!$K$2:$K$487,"Migração") -> 80 | D7: =COUNTIFS(Base_Encerradas!$C$2:$C$487,$A7,Base_Encerradas!$K$2:$K$487,"Compra extra desfeita") -> 21 | E7: =COUNTIFS(Base_Encerradas!$C$2:$C$487,$A7,Base_Encerradas!$K$2:$K$487,"Redução real") -> 68 | F7: =COUNTIFS(Base_Encerradas!$C$2:$C$487,$A7,Base_Encerradas!$K$2:$K$487,"Saída do cliente") -> 3 | G7: =SUMIFS(Base_Encerradas!$F$2:$F$487,Base_Encerradas!$C$2:$C$487,$A7) -> 926345 | H7: =SUMIFS(Base_Encerradas!$F$2:$F$487,Base_Encerradas!$C$2:$C$487,$A7,Base_Encerradas!$K$2:$K$487,"Migração") -> 446556 | I7: =SUMIFS(Base_Encerradas!$F$2:$F$487,Base_Encerradas!$C$2:$C$487,$A7,Base_Encerradas!$K$2:$K$487,"Compra extra desfeita") -> 147459 | J7: =SUMIFS(Base_Encerradas!$F$2:$F$487,Base_Encerradas!$C$2:$C$487,$A7,Base_Encerradas!$K$2:$K$487,"Redução real")+SUMIFS(Base_Encerradas!$F$2:$F$487,Base_Encerradas!$C$2:$C$487,$A7,Base_Encerradas!$K$2:$K$487,"Saída do cliente") -> 332330 | K7: =J7/G7 -> 0.35875403
A8: Total | B8: =SUM(B5:B7) -> 486 | C8: =SUM(C5:C7) -> 233 | D8: =SUM(D5:D7) -> 64 | E8: =SUM(E5:E7) -> 185 | F8: =SUM(F5:F7) -> 4 | G8: =SUM(G5:G7) -> 1179139 | H8: =SUM(H5:H7) -> 575140 | I8: =SUM(I5:I7) -> 180445 | J8: =SUM(J5:J7) -> 423554 | K8: =J8/G8 -> 0.35920617
A9: + saldo das trocas (todas) | J9: ='3_Valor_US$'!E13 -> 114360
A10: PERDA REAL total | J10: =J8+J9 -> 537914
A12: Leitura: o Enterprise concentra a perda por redução: cada assinatura vale muito mais (US$ 199 por seat, contra 49 e 19).

Sheet Base_Encerradas
A1: subscription_id | B1: account_id | C1: plan_tier | D1: trial | E1: seats | F1: mrr_amount | G1: start_date | H1: end_date | I1: dias_de_vida | J1: trimestre_fim | K1: situacao | L1: assinatura_nova | M1: mrr_reposto
A2: S-8cec59 | B2: A-3c1a3f | C2: Enterprise | D2: Não | E2: 14 | F2: 2786 | G2: 45283 | H2: 45394 | I2: 111 | J2: 2024-T2 | K2: Redução real | M2: 0
A3: S-f81687 | B3: A-e7a1e2 | C3: Enterprise | D3: Não | E3: 5 | F3: 995 | G3: 45619 | H3: 45639 | I3: 20 | J3: 2024-T4 | K3: Compra extra desfeita | M3: 0
A4: S-13939b | B4: A-86902e | C4: Pro | D4: Sim | E4: 34 | F4: 0 | G4: 45128 | H4: 45507 | I4: 379 | J4: 2024-T3 | K4: Redução real | M4: 0
A5: S-9333c5 | B5: A-ef84cf | C5: Basic | D5: Não | E5: 8 | F5: 152 | G5: 45449 | H5: 45517 | I5: 68 | J5: 2024-T3 | K5: Migração | L5: S-1ffdd8 | M5: 152
A6: S-3bd427 | B6: A-2e3bad | C6: Basic | D6: Não | E6: 61 | F6: 1159 | G6: 45630 | H6: 45653 | I6: 23 | J6: 2024-T4 | K6: Compra extra desfeita | M6: 0
A7: S-c75159 | B7: A-bcf87c | C7: Enterprise | D7: Não | E7: 31 | F7: 6169 | G7: 45526 | H7: 45563 | I7: 37 | J7: 2024-T3 | K7: Redução real | M7: 0
A8: S-aff55c | B8: A-bb2f49 | C8: Pro | D8: Sim | E8: 8 | F8: 0 | G8: 45305 | H8: 45655 | I8: 350 | J8: 2024-T4 | K8: Migração | L8: S-e44831 | M8: 1372
A9: S-7f8cd8 | B9: A-53f4e3 | C9: Enterprise | D9: Não | E9: 20 | F9: 3980 | G9: 45553 | H9: 45613 | I9: 60 | J9: 2024-T4 | K9: Redução real | M9: 0
A10: S-b2d472 | B10: A-bcf87c | C10: Enterprise | D10: Não | E10: 10 | F10: 1990 | G10: 45531 | H10: 45637 | I10: 106 | J10: 2024-T4 | K10: Migração | L10: S-0e12c9 | M10: 0
A11: S-0267b7 | B11: A-65a46c | C11: Enterprise | D11: Sim | E11: 13 | F11: 0 | G11: 45582 | H11: 45630 | I11: 48 | J11: 2024-T4 | K11: Redução real | M11: 0
A12: S-ce5450 | B12: A-0a282f | C12: Pro | D12: Sim | E12: 8 | F12: 0 | G12: 45651 | H12: 45654 | I12: 3 | J12: 2024-T4 | K12: Migração | L12: S-9c414f | M12: 98
A13: S-09cdac | B13: A-82861f | C13: Basic | D13: Não | E13: 41 | F13: 779 | G13: 45504 | H13: 45539 | I13: 35 | J13: 2024-T3 | K13: Redução real | M13: 0
A14: S-0cb6ed | B14: A-ac85cd | C14: Pro | D14: Não | E14: 53 | F14: 2597 | G14: 45605 | H14: 45644 | I14: 39 | J14: 2024-T4 | K14: Migração | L14: S-b35203 | M14: 10547
A15: S-0e4b0c | B15: A-39b19f | C15: Pro | D15: Não | E15: 24 | F15: 1176 | G15: 44985 | H15: 45092 | I15: 107 | J15: 2023-T2 | K15: Redução real | M15: 0
A16: S-1bd2ec | B16: A-e60f9d | C16: Basic | D16: Não | E16: 38 | F16: 722 | G16: 45651 | H16: 45654 | I16: 3 | J16: 2024-T4 | K16: Migração | L16: S-3867d6 | M16: 0
A17: S-401496 | B17: A-68f37c | C17: Enterprise | D17: Não | E17: 4 | F17: 796 | G17: 45151 | H17: 45465 | I17: 314 | J17: 2024-T2 | K17: Redução real | M17: 0
A18: S-017e33 | B18: A-f9cc74 | C18: Basic | D18: Não | E18: 53 | F18: 1007 | G18: 45604 | H18: 45621 | I18: 17 | J18: 2024-T4 | K18: Migração | L18: S-c76699 | M18: 570
A19: S-9b2c95 | B19: A-e60f9d | C19: Pro | D19: Sim | E19: 29 | F19: 0 | G19: 45620 | H19: 45631 | I19: 11 | J19: 2024-T4 | K19: Migração | L19: S-a8299c | M19: 5771
A20: S-0b0ffa | B20: A-180abf | C20: Basic | D20: Sim | E20: 64 | F20: 0 | G20: 45308 | H20: 45401 | I20: 93 | J20: 2024-T2 | K20: Migração | L20: S-612bfb | M20: 12736
A21: S-431c03 | B21: A-e4bf56 | C21: Enterprise | D21: Não | E21: 37 | F21: 7363 | G21: 45628 | H21: 45645 | I21: 17 | J21: 2024-T4 | K21: Migração | L21: S-bba658 | M21: 323
A22: S-4f0027 | B22: A-ff79f2 | C22: Enterprise | D22: Não | E22: 19 | F22: 3781 | G22: 45657 | H22: 45657 | I22: 0 | J22: 2024-T4 | K22: Migração | L22: S-2ded06 | M22: 589
A23: S-396a84 | B23: A-5b4ebb | C23: Basic | D23: Não | E23: 21 | F23: 399 | G23: 45588 | H23: 45623 | I23: 35 | J23: 2024-T4 | K23: Migração | L23: S-02cde8 | M23: 12537
A24: S-33e40e | B24: A-86cdb4 | C24: Enterprise | D24: Não | E24: 2 | F24: 398 | G24: 45575 | H24: 45655 | I24: 80 | J24: 2024-T4 | K24: Migração | L24: S-684751 | M24: 323
A25: S-bbafad | B25: A-854864 | C25: Basic | D25: Não | E25: 20 | F25: 380 | G25: 45653 | H25: 45656 | I25: 3 | J25: 2024-T4 | K25: Migração | L25: S-676254 | M25: 980
A26: S-7904d3 | B26: A-d4e0d4 | C26: Enterprise | D26: Não | E26: 117 | F26: 23283 | G26: 45626 | H26: 45629 | I26: 3 | J26: 2024-T4 | K26: Compra extra desfeita | M26: 0
A27: S-936732 | B27: A-2f6a32 | C27: Pro | D27: Não | E27: 19 | F27: 931 | G27: 45624 | H27: 45632 | I27: 8 | J27: 2024-T4 | K27: Migração | L27: S-55d53c | M27: 361
A28: S-c2f293 | B28: A-69b156 | C28: Basic | D28: Não | E28: 8 | F28: 152 | G28: 45636 | H28: 45656 | I28: 20 | J28: 2024-T4 | K28: Compra extra desfeita | M28: 0
A29: S-f5f5b3 | B29: A-89ee83 | C29: Basic | D29: Não | E29: 10 | F29: 190 | G29: 45652 | H29: 45655 | I29: 3 | J29: 2024-T4 | K29: Migração | L29: S-bf304b | M29: 3582
A30: S-4afb53 | B30: A-40de06 | C30: Enterprise | D30: Não | E30: 28 | F30: 5572 | G30: 45272 | H30: 45655 | I30: 383 | J30: 2024-T4 | K30: Redução real | M30: 0
A31: S-85796b | B31: A-f19409 | C31: Enterprise | D31: Não | E31: 23 | F31: 4577 | G31: 45531 | H31: 45596 | I31: 65 | J31: 2024-T4 | K31: Migração | L31: S-f9e5e9 | M31: 1127
A32: S-4bef15 | B32: A-600734 | C32: Enterprise | D32: Sim | E32: 29 | F32: 0 | G32: 45518 | H32: 45557 | I32: 39 | J32: 2024-T3 | K32: Redução real | M32: 0
A33: S-61e53d | B33: A-d42431 | C33: Basic | D33: Não | E33: 22 | F33: 418 | G33: 45611 | H33: 45640 | I33: 29 | J33: 2024-T4 | K33: Migração | L33: S-48ce17 | M33: 4378
A34: S-8324d4 | B34: A-5a215a | C34: Pro | D34: Sim | E34: 87 | F34: 0 | G34: 45486 | H34: 45507 | I34: 21 | J34: 2024-T3 | K34: Migração | L34: S-5da6e7 | M34: 4263
A35: S-93fab3 | B35: A-9f9299 | C35: Pro | D35: Não | E35: 28 | F35: 1372 | G35: 45606 | H35: 45657 | I35: 51 | J35: 2024-T4 | K35: Redução real | M35: 0
A36: S-24ae40 | B36: A-328bd0 | C36: Basic | D36: Não | E36: 18 | F36: 342 | G36: 45333 | H36: 45379 | I36: 46 | J36: 2024-T1 | K36: Redução real | M36: 0
A37: S-fee60b | B37: A-4a267b | C37: Pro | D37: Não | E37: 46 | F37: 2254 | G37: 45557 | H37: 45564 | I37: 7 | J37: 2024-T3 | K37: Migração | L37: S-5a6941 | M37: 1225
A38: S-d01053 | B38: A-779e4e | C38: Enterprise | D38: Não | E38: 36 | F38: 7164 | G38: 45242 | H38: 45594 | I38: 352 | J38: 2024-T4 | K38: Redução real | M38: 0
A39: S-321498 | B39: A-3a7284 | C39: Pro | D39: Sim | E39: 31 | F39: 0 | G39: 45651 | H39: 45657 | I39: 6 | J39: 2024-T4 | K39: Migração | L39: S-7be036 | M39: 1519
A40: S-627cfa | B40: A-9bfc9f | C40: Pro | D40: Não | E40: 53 | F40: 2597 | G40: 45188 | H40: 45295 | I40: 107 | J40: 2024-T1 | K40: Migração | L40: S-84c44b | M40: 1007
...
