Workbook

Sheet LEIA-ME
B1: Passo 3 da reconciliação: o que mudou no 2º semestre de 2024 e em dezembro?
B2: Planilha apartada. Lê os CSVs originais sem alterá-los. Base principal = assinaturas (01_Evidencias); ponto de partida = aba Tempo de 02_Triangulacao.
B4: PERGUNTAS
B5: 1. As assinaturas que entraram em 2024-S2 são de outro tipo (plano, cliente, canal…) ou o mesmo tipo de assinatura passou a cancelar mais? → aba Coorte_x_Fator
B6: 2. O que há de diferente em dezembro/2024? → aba Dezembro
B7: 3. Suporte e uso pioraram junto com o churn? → aba Sinais_no_tempo
B8: 4. O que diferencia as contas em que as 3 marcações concordam? → aba Subconjunto_limpo
B10: RESPOSTAS
B11: 1. Mesmo tipo de assinatura, cancelando mais. A taxa de encerramento em 30 dias sobe de ~0,7% para ~4,2% (cerca de 6x) em praticamente todas as categorias de plano, cobrança, trial, seats, indústria, país, canal e idade da conta. O mix muda um pouco em alguns fatores, mas, mantidas as taxas antigas, essa mudança explicaria quase nada do aumento (coluna O). É um efeito do período, não do mix.
B12: 2. Dezembro soma o efeito do período (muitas assinaturas novas encerrando em poucos dias) com uma concentração anormal de encerramentos em 29–31/12. Essa concentração precisa ser confirmada com a área (fechamento de ano, renovação, corte da extração) antes de ser lida como perda de cliente.
B13: 3. Não. Satisfação, tempo de resolução, primeira resposta, escalação, uso e erros ficam estáveis enquanto o churn sobe. Por isso "CS diz que a satisfação está ok" e "produto diz que o uso cresceu" não contradizem o churn: esses indicadores simplesmente não captam o que está mudando.
B14: 4. Contas limpas são parecidas em quase tudo. Mais assinaturas e mais uso no grupo churn é efeito mecânico; a concentração em DevTools vem do próprio churn_flag e não é confirmada por receita nem eventos.
... B21: • p-valores (Fisher exato, permutação) são calculados no script; contagens, % e médias são fórmulas sobre as abas Base_*.

Sheet Coorte_x_Fator
A1: O que mudou nas assinaturas iniciadas no 2º semestre de 2024?
A2: Só assinaturas com 30 dias observáveis (início até 01/12/2024). "% encerra em 30 dias" = assinaturas encerradas com até 30 dias de vida. Composição = peso de cada categoria dentro da coorte. Contagens e % são fórmulas; p-valores vêm do script (Fisher exato e permutação).
A4: Fator | B4: Categoria | C4: Até 2024-S1: assinaturas | D4: Até 2024-S1: encerram em 30 dias | E4: Até 2024-S1: % | F4: 2024-S2: assinaturas | G4: 2024-S2: encerram em 30 dias | H4: 2024-S2: % | I4: Aumento (S2 ÷ antes) | J4: p (Fisher) | K4: Composição até S1 | L4: Composição S2 | M4: Mudança de composição (p.p.) | N4: p da composição (fator) | O4: % S2 esperado só pela mudança de mix
A5: TODAS | C5: =COUNTIFS(Base_Assinaturas!$H$2:$H$5001,"Sim",Base_Assinaturas!$G$2:$G$5001,"Até 2024-S1") | D5: =SUMIFS(Base_Assinaturas!$I$2:$I$5001,Base_Assinaturas!$H$2:$H$5001,"Sim",Base_Assinaturas!$G$2:$G$5001,"Até 2024-S1") | E5: =D5/C5 | F5: =COUNTIFS(Base_Assinaturas!$H$2:$H$5001,"Sim",Base_Assinaturas!$G$2:$G$5001,"2024-S2") | G5: =SUMIFS(Base_Assinaturas!$I$2:$I$5001,Base_Assinaturas!$H$2:$H$5001,"Sim",Base_Assinaturas!$G$2:$G$5001,"2024-S2") | H5: =G5/F5 | I5: =IF(E5>0,H5/E5,"") | J5: 0 | O5: =E5
A6: Plano da assinatura | B6: Basic | C6: =COUNTIFS(Base_Assinaturas!$H$2:$H$5001,"Sim",Base_Assinaturas!$G$2:$G$5001,"Até 2024-S1",Base_Assinaturas!$M$2:$M$5001,"Basic") | D6: =SUMIFS(Base_Assinaturas!$I$2:$I$5001,Base_Assinaturas!$H$2:$H$5001,"Sim",Base_Assinaturas!$G$2:$G$5001,"Até 2024-S1",Base_Assinaturas!$M$2:$M$5001,"Basic") | E6: =IF(C6>0,D6/C6,"") | F6: =COUNTIFS(Base_Assinaturas!$H$2:$H$5001,"Sim",Base_Assinaturas!$G$2:$G$5001,"2024-S2",Base_Assinaturas!$M$2:$M$5001,"Basic") | G6: =SUMIFS(Base_Assinaturas!$I$2:$I$5001,Base_Assinaturas!$H$2:$H$5001,"Sim",Base_Assinaturas!$G$2:$G$5001,"2024-S2",Base_Assinaturas!$M$2:$M$5001,"Basic") | H6: =IF(F6>0,G6/F6,"") | I6: =IF(AND(ISNUMBER(E6),E6>0),H6/E6,"sem casos antes") | J6: 0 | K6: =C6/C$5 | L6: =F6/F$5 | M6: =(L6-K6)*100 | N6: 0.4346 | O6: =SUMPRODUCT(L6:L8,E6:E8)
B7: Enterprise | C7: =COUNTIFS(Base_Assinaturas!$H$2:$H$5001,"Sim",Base_Assinaturas!$G$2:$G$5001,"Até 2024-S1",Base_Assinaturas!$M$2:$M$5001,"Enterprise") | D7: =SUMIFS(Base_Assinaturas!$I$2:$I$5001,Base_Assinaturas!$H$2:$H$5001,"Sim",Base_Assinaturas!$G$2:$G$5001,"Até 2024-S1",Base_Assinaturas!$M$2:$M$5001,"Enterprise") | E7: =IF(C7>0,D7/C7,"") | F7: =COUNTIFS(Base_Assinaturas!$H$2:$H$5001,"Sim",Base_Assinaturas!$G$2:$G$5001,"2024-S2",Base_Assinaturas!$M$2:$M$5001,"Enterprise") | G7: =SUMIFS(Base_Assinaturas!$I$2:$I$5001,Base_Assinaturas!$H$2:$H$5001,"Sim",Base_Assinaturas!$G$2:$G$5001,"2024-S2",Base_Assinaturas!$M$2:$M$5001,"Enterprise") | H7: =IF(F7>0,G7/F7,"") | I7: =IF(AND(ISNUMBER(E7),E7>0),H7/E7,"sem casos antes") | J7: 0.000384 | K7: =C7/C$5 | L7: =F7/F$5 | M7: =(L7-K7)*100
B8: Pro | C8: =COUNTIFS(Base_Assinaturas!$H$2:$H$5001,"Sim",Base_Assinaturas!$G$2:$G$5001,"Até 2024-S1",Base_Assinaturas!$M$2:$M$5001,"Pro") | D8: =SUMIFS(Base_Assinaturas!$I$2:$I$5001,Base_Assinaturas!$H$2:$H$5001,"Sim",Base_Assinaturas!$G$2:$G$5001,"Até 2024-S1",Base_Assinaturas!$M$2:$M$5001,"Pro") | E8: =IF(C8>0,D8/C8,"") | F8: =COUNTIFS(Base_Assinaturas!$H$2:$H$5001,"Sim",Base_Assinaturas!$G$2:$G$5001,"2024-S2",Base_Assinaturas!$M$2:$M$5001,"Pro") | G8: =SUMIFS(Base_Assinaturas!$I$2:$I$5001,Base_Assinaturas!$H$2:$H$5001,"Sim",Base_Assinaturas!$G$2:$G$5001,"2024-S2",Base_Assinaturas!$M$2:$M$5001,"Pro") | H8: =IF(F8>0,G8/F8,"") | I8: =IF(AND(ISNUMBER(E8),E8>0),H8/E8,"sem casos antes") | J8: 0.0001 | K8: =C8/C$5 | L8: =F8/F$5 | M8: =(L8-K8)*100
A9: Cobrança | B9: annual | C9: =COUNTIFS(Base_Assinaturas!$H$2:$H$5001,"Sim",Base_Assinaturas!$G$2:$G$5001,"Até 2024-S1",Base_Assinaturas!$N$2:$N$5001,"annual") | D9: =SUMIFS(Base_Assinaturas!$I$2:$I$5001,Base_Assinaturas!$H$2:$H$5001,"Sim",Base_Assinaturas!$G$2:$G$5001,"Até 2024-S1",Base_Assinaturas!$N$2:$N$5001,"annual") | E9: =IF(C9>0,D9/C9,"") | F9: =COUNTIFS(Base_Assinaturas!$H$2:$H$5001,"Sim",Base_Assinaturas!$G$2:$G$5001,"2024-S2",Base_Assinaturas!$N$2:$N$5001,"annual") | G9: =SUMIFS(Base_Assinaturas!$I$2:$I$5001,Base_Assinaturas!$H$2:$H$5001,"Sim",Base_Assinaturas!$G$2:$G$5001,"2024-S2",Base_Assinaturas!$N$2:$N$5001,"annual") | H9: =IF(F9>0,G9/F9,"") | I9: =IF(AND(ISNUMBER(E9),E9>0),H9/E9,"sem casos antes") | J9: 0 | K9: =C9/C$5 | L9: =F9/F$5 | M9: =(L9-K9)*100 | N9: 0.7552 | O9: =SUMPRODUCT(L9:L10,E9:E10)
B10: monthly | C10: =COUNTIFS(Base_Assinaturas!$H$2:$H$5001,"Sim",Base_Assinaturas!$G$2:$G$5001,"Até 2024-S1",Base_Assinaturas!$N$2:$N$5001,"monthly") | D10: =SUMIFS(Base_Assinaturas!$I$2:$I$5001,Base_Assinaturas!$H$2:$H$5001,"Sim",Base_Assinaturas!$G$2:$G$5001,"Até 2024-S1",Base_Assinaturas!$N$2:$N$5001,"monthly") | E10: =IF(C10>0,D10/C10,"") | F10: =COUNTIFS(Base_Assinaturas!$H$2:$H$5001,"Sim",Base_Assinaturas!$G$2:$G$5001,"2024-S2",Base_Assinaturas!$N$2:$N$5001,"monthly") | G10: =SUMIFS(Base_Assinaturas!$I$2:$I$5001,Base_Assinaturas!$H$2:$H$5001,"Sim",Base_Assinaturas!$G$2:$G$5001,"2024-S2",Base_Assinaturas!$N$2:$N$5001,"monthly") | H10: =IF(F10>0,G10/F10,"") | I10: =IF(AND(ISNUMBER(E10),E10>0),H10/E10,"sem casos antes") | J10: 0 | K10: =C10/C$5 | L10: =F10/F$5 | M10: =(L10-K10)*100
A11: Trial | B11: Pago | C11: =COUNTIFS(Base_Assinaturas!$H$2:$H$5001,"Sim",Base_Assinaturas!$G$2:$G$5001,"Até 2024-S1",Base_Assinaturas!$O$2:$O$5001,"Pago") | D11: =SUMIFS(Base_Assinaturas!$I$2:$I$5001,Base_Assinaturas!$H$2:$H$5001,"Sim",Base_Assinaturas!$G$2:$G$5001,"Até 2024-S1",Base_Assinaturas!$O$2:$O$5001,"Pago") | E11: =IF(C11>0,D11/C11,"") | F11: =COUNTIFS(Base_Assinaturas!$H$2:$H$5001,"Sim",Base_Assinaturas!$G$2:$G$5001,"2024-S2",Base_Assinaturas!$O$2:$O$5001,"Pago") | G11: =SUMIFS(Base_Assinaturas!$I$2:$I$5001,Base_Assinaturas!$H$2:$H$5001,"Sim",Base_Assinaturas!$G$2:$G$5001,"2024-S2",Base_Assinaturas!$O$2:$O$5001,"Pago") | H11: =IF(F11>0,G11/F11,"") | I11: =IF(AND(ISNUMBER(E11),E11>0),H11/E11,"sem casos antes") | J11: 0 | K11: =C11/C$5 | L11: =F11/F$5 | M11: =(L11-K11)*100 | N11: 0.3736 | O11: =SUMPRODUCT(L11:L12,E11:E12)
B12: Trial | C12: =COUNTIFS(Base_Assinaturas!$H$2:$H$5001,"Sim",Base_Assinaturas!$G$2:$G$5001,"Até 2024-S1",Base_Assinaturas!$O$2:$O$5001,"Trial") | D12: =SUMIFS(Base_Assinaturas!$I$2:$I$5001,Base_Assinaturas!$H$2:$H$5001,"Sim",Base_Assinaturas!$G$2:$G$5001,"Até 2024-S1",Base_Assinaturas!$O$2:$O$5001,"Trial") | E12: =IF(C12>0,D12/C12,"") | F12: =COUNTIFS(Base_Assinaturas!$H$2:$H$5001,"Sim",Base_Assinaturas!$G$2:$G$5001,"2024-S2",Base_Assinaturas!$O$2:$O$5001,"Trial") | G12: =SUMIFS(Base_Assinaturas!$I$2:$I$5001,Base_Assinaturas!$H$2:$H$5001,"Sim",Base_Assinaturas!$G$2:$G$5001,"2024-S2",Base_Assinaturas!$O$2:$O$5001,"Trial") | H12: =IF(F12>0,G12/F12,"") | I12: =IF(AND(ISNUMBER(E12),E12>0),H12/E12,"sem casos antes") | J12: 0.001212 | K12: =C12/C$5 | L12: =F12/F$5 | M12: =(L12-K12)*100
A13: Renovação automática | B13: Não | C13: =COUNTIFS(Base_Assinaturas!$H$2:$H$5001,"Sim",Base_Assinaturas!$G$2:$G$5001,"Até 2024-S1",Base_Assinaturas!$P$2:$P$5001,"Não") | D13: =SUMIFS(Base_Assinaturas!$I$2:$I$5001,Base_Assinaturas!$H$2:$H$5001,"Sim",Base_Assinaturas!$G$2:$G$5001,"Até 2024-S1",Base_Assinaturas!$P$2:$P$5001,"Não") | E13: =IF(C13>0,D13/C13,"") | F13: =COUNTIFS(Base_Assinaturas!$H$2:$H$5001,"Sim",Base_Assinaturas!$G$2:$G$5001,"2024-S2",Base_Assinaturas!$P$2:$P$5001,"Não") | G13: =SUMIFS(Base_Assinaturas!$I$2:$I$5001,Base_Assinaturas!$H$2:$H$5001,"Sim",Base_Assinaturas!$G$2:$G$5001,"2024-S2",Base_Assinaturas!$P$2:$P$5001,"Não") | H13: =IF(F13>0,G13/F13,"") | I13: =IF(AND(ISNUMBER(E13),E13>0),H13/E13,"sem casos antes") | J13: 0.00016 | K13: =C13/C$5 | L13: =F13/F$5 | M13: =(L13-K13)*100 | N13: 0.3926 | O13: =SUMPRODUCT(L13:L14,E13:E14)
B14: Sim | C14: =COUNTIFS(Base_Assinaturas!$H$2:$H$5001,"Sim",Base_Assinaturas!$G$2:$G$5001,"Até 2024-S1",Base_Assinaturas!$P$2:$P$5001,"Sim") | D14: =SUMIFS(Base_Assinaturas!$I$2:$I$5001,Base_Assinaturas!$H$2:$H$5001,"Sim",Base_Assinaturas!$G$2:$G$5001,"Até 2024-S1",Base_Assinaturas!$P$2:$P$5001,"Sim") | E14: =IF(C14>0,D14/C14,"") | F14: =COUNTIFS(Base_Assinaturas!$H$2:$H$5001,"Sim",Base_Assinaturas!$G$2:$G$5001,"2024-S2",Base_Assinaturas!$P$2:$P$5001,"Sim") | G14: =SUMIFS(Base_Assinaturas!$I$2:$I$5001,Base_Assinaturas!$H$2:$H$5001,"Sim",Base_Assinaturas!$G$2:$G$5001,"2024-S2",Base_Assinaturas!$P$2:$P$5001,"Sim") | H14: =IF(F14>0,G14/F14,"") | I14: =IF(AND(ISNUMBER(E14),E14>0),H14/E14,"sem casos antes") | J14: 0 | K14: =C14/C$5 | L14: =F14/F$5 | M14: =(L14-K14)*100
A15: Upgrade na assinatura | B15: Não | C15: =COUNTIFS(Base_Assinaturas!$H$2:$H$5001,"Sim",Base_Assinaturas!$G$2:$G$5001,"Até 2024-S1",Base_Assinaturas!$Q$2:$Q$5001,"Não") | D15: =SUMIFS(Base_Assinaturas!$I$2:$I$5001,Base_Assinaturas!$H$2:$H$5001,"Sim",Base_Assinaturas!$G$2:$G$5001,"Até 2024-S1",Base_Assinaturas!$Q$2:$Q$5001,"Não") | E15: =IF(C15>0,D15/C15,"") | F15: =COUNTIFS(Base_Assinaturas!$H$2:$H$5001,"Sim",Base_Assinaturas!$G$2:$G$5001,"2024-S2",Base_Assinaturas!$Q$2:$Q$5001,"Não") | G15: =SUMIFS(Base_Assinaturas!$I$2:$I$5001,Base_Assinaturas!$H$2:$H$5001,"Sim",Base_Assinaturas!$G$2:$G$5001,"2024-S2",Base_Assinaturas!$Q$2:$Q$5001,"Não") | H15: =IF(F15>0,G15/F15,"") | I15: =IF(AND(ISNUMBER(E15),E15>0),H15/E15,"sem casos antes") | J15: 0 | K15: =C15/C$5 | L15: =F15/F$5 | M15: =(L15-K15)*100 | N15: 0.1089 | O15: =SUMPRODUCT(L15:L16,E15:E16)
B16: Sim | C16: =COUNTIFS(Base_Assinaturas!$H$2:$H$5001,"Sim",Base_Assinaturas!$G$2:$G$5001,"Até 2024-S1",Base_Assinaturas!$Q$2:$Q$5001,"Sim") | D16: =SUMIFS(Base_Assinaturas!$I$2:$I$5001,Base_Assinaturas!$H$2:$H$5001,"Sim",Base_Assinaturas!$G$2:$G$5001,"Até 2024-S1",Base_Assinaturas!$Q$2:$Q$5001,"Sim") | E16: =IF(C16>0,D16/C16,"") | F16: =COUNTIFS(Base_Assinaturas!$H$2:$H$5001,"Sim",Base_Assinaturas!$G$2:$G$5001,"2024-S2",Base_Assinaturas!$Q$2:$Q$5001,"Sim") | G16: =SUMIFS(Base_Assinaturas!$I$2:$I$5001,Base_Assinaturas!$H$2:$H$5001,"Sim",Base_Assinaturas!$G$2:$G$5001,"2024-S2",Base_Assinaturas!$Q$2:$Q$5001,"Sim") | H16: =IF(F16>0,G16/F16,"") | I16: =IF(AND(ISNUMBER(E16),E16>0),H16/E16,"sem casos antes") | J16: 0.089953 | K16: =C16/C$5 | L16: =F16/F$5 | M16: =(L16-K16)*100
A17: Downgrade na assinatura | B17: Não | C17: =COUNTIFS(Base_Assinaturas!$H$2:$H$5001,"Sim",Base_Assinaturas!$G$2:$G$5001,"Até 2024-S1",Base_Assinaturas!$R$2:$R$5001,"Não") | D17: =SUMIFS(Base_Assinaturas!$I$2:$I$5001,Base_Assinaturas!$H$2:$H$5001,"Sim",Base_Assinaturas!$G$2:$G$5001,"Até 2024-S1",Base_Assinaturas!$R$2:$R$5001,"Não") | E17: =IF(C17>0,D17/C17,"") | F17: =COUNTIFS(Base_Assinaturas!$H$2:$H$5001,"Sim",Base_Assinaturas!$G$2:$G$5001,"2024-S2",Base_Assinaturas!$R$2:$R$5001,"Não") | G17: =SUMIFS(Base_Assinaturas!$I$2:$I$5001,Base_Assinaturas!$H$2:$H$5001,"Sim",Base_Assinaturas!$G$2:$G$5001,"2024-S2",Base_Assinaturas!$R$2:$R$5001,"Não") | H17: =IF(F17>0,G17/F17,"") | I17: =IF(AND(ISNUMBER(E17),E17>0),H17/E17,"sem casos antes") | J17: 0 | K17: =C17/C$5 | L17: =F17/F$5 | M17: =(L17-K17)*100 | N17: 0.8342 | O17: =SUMPRODUCT(L17:L18,E17:E18)
B18: Sim | C18: =COUNTIFS(Base_Assinaturas!$H$2:$H$5001,"Sim",Base_Assinaturas!$G$2:$G$5001,"Até 2024-S1",Base_Assinaturas!$R$2:$R$5001,"Sim") | D18: =SUMIFS(Base_Assinaturas!$I$2:$I$5001,Base_Assinaturas!$H$2:$H$5001,"Sim",Base_Assinaturas!$G$2:$G$5001,"Até 2024-S1",Base_Assinaturas!$R$2:$R$5001,"Sim") | E18: =IF(C18>0,D18/C18,"") | F18: =COUNTIFS(Base_Assinaturas!$H$2:$H$5001,"Sim",Base_Assinaturas!$G$2:$G$5001,"2024-S2",Base_Assinaturas!$R$2:$R$5001,"Sim") | G18: =SUMIFS(Base_Assinaturas!$I$2:$I$5001,Base_Assinaturas!$H$2:$H$5001,"Sim",Base_Assinaturas!$G$2:$G$5001,"2024-S2",Base_Assinaturas!$R$2:$R$5001,"Sim") | H18: =IF(F18>0,G18/F18,"") | I18: =IF(AND(ISNUMBER(E18),E18>0),H18/E18,"sem casos antes") | J18: 0.231124 | K18: =C18/C$5 | L18: =F18/F$5 | M18: =(L18-K18)*100
A19: Seats da assinatura | B19: 16–40 | C19: =COUNTIFS(Base_Assinaturas!$H$2:$H$5001,"Sim",Base_Assinaturas!$G$2:$G$5001,"Até 2024-S1",Base_Assinaturas!$S$2:$S$5001,"16–40") | D19: =SUMIFS(Base_Assinaturas!$I$2:$I$5001,Base_Assinaturas!$H$2:$H$5001,"Sim",Base_Assinaturas!$G$2:$G$5001,"Até 2024-S1",Base_Assinaturas!$S$2:$S$5001,"16–40") | E19: =IF(C19>0,D19/C19,"") | F19: =COUNTIFS(Base_Assinaturas!$H$2:$H$5001,"Sim",Base_Assinaturas!$G$2:$G$5001,"2024-S2",Base_Assinaturas!$S$2:$S$5001,"16–40") | G19: =SUMIFS(Base_Assinaturas!$I$2:$I$5001,Base_Assinaturas!$H$2:$H$5001,"Sim",Base_Assinaturas!$G$2:$G$5001,"2024-S2",Base_Assinaturas!$S$2:$S$5001,"16–40") | H19: =IF(F19>0,G19/F19,"") | I19: =IF(AND(ISNUMBER(E19),E19>0),H19/E19,"sem casos antes") | J19: 2e-06 | K19: =C19/C$5 | L19: =F19/F$5 | M19: =(L19-K19)*100 | N19: 0.7552 | O19: =SUMPRODUCT(L19:L22,E19:E22)
B20: 1–5 | C20: =COUNTIFS(Base_Assinaturas!$H$2:$H$5001,"Sim",Base_Assinaturas!$G$2:$G$5001,"Até 2024-S1",Base_Assinaturas!$S$2:$S$5001,"1–5") | D20: =SUMIFS(Base_Assinaturas!$I$2:$I$5001,Base_Assinaturas!$H$2:$H$5001,"Sim",Base_Assinaturas!$G$2:$G$5001,"Até 2024-S1",Base_Assinaturas!$S$2:$S$5001,"1–5") | E20: =IF(C20>0,D20/C20,"") | F20: =COUNTIFS(Base_Assinaturas!$H$2:$H$5001,"Sim",Base_Assinaturas!$G$2:$G$5001,"2024-S2",Base_Assinaturas!$S$2:$S$5001,"1–5") | G20: =SUMIFS(Base_Assinaturas!$I$2:$I$5001,Base_Assinaturas!$H$2:$H$5001,"Sim",Base_Assinaturas!$G$2:$G$5001,"2024-S2",Base_Assinaturas!$S$2:$S$5001,"1–5") | H20: =IF(F20>0,G20/F20,"") | I20: =IF(AND(ISNUMBER(E20),E20>0),H20/E20,"sem casos antes") | J20: 0.013717 | K20: =C20/C$5 | L20: =F20/F$5 | M20: =(L20-K20)*100
B21: 41+ | C21: =COUNTIFS(Base_Assinaturas!$H$2:$H$5001,"Sim",Base_Assinaturas!$G$2:$G$5001,"Até 2024-S1",Base_Assinaturas!$S$2:$S$5001,"41+") | D21: =SUMIFS(Base_Assinaturas!$I$2:$I$5001,Base_Assinaturas!$H$2:$H$5001,"Sim",Base_Assinaturas!$G$2:$G$5001,"Até 2024-S1",Base_Assinaturas!$S$2:$S$5001,"41+") | E21: =IF(C21>0,D21/C21,"") | F21: =COUNTIFS(Base_Assinaturas!$H$2:$H$5001,"Sim",Base_Assinaturas!$G$2:$G$5001,"2024-S2",Base_Assinaturas!$S$2:$S$5001,"41+") | G21: =SUMIFS(Base_Assinaturas!$I$2:$I$5001,Base_Assinaturas!$H$2:$H$5001,"Sim",Base_Assinaturas!$G$2:$G$5001,"2024-S2",Base_Assinaturas!$S$2:$S$5001,"41+") | H21: =IF(F21>0,G21/F21,"") | I21: =IF(AND(ISNUMBER(E21),E21>0),H21/E21,"sem casos antes") | J21: 6.8e-05 | K21: =C21/C$5 | L21: =F21/F$5 | M21: =(L21-K21)*100
B22: 6–15 | C22: =COUNTIFS(Base_Assinaturas!$H$2:$H$5001,"Sim",Base_Assinaturas!$G$2:$G$5001,"Até 2024-S1",Base_Assinaturas!$S$2:$S$5001,"6–15") | D22: =SUMIFS(Base_Assinaturas!$I$2:$I$5001,Base_Assinaturas!$H$2:$H$5001,"Sim",Base_Assinaturas!$G$2:$G$5001,"Até 2024-S1",Base_Assinaturas!$S$2:$S$5001,"6–15") | E22: =IF(C22>0,D22/C22,"") | F22: =COUNTIFS(Base_Assinaturas!$H$2:$H$5001,"Sim",Base_Assinaturas!$G$2:$G$5001,"2024-S2",Base_Assinaturas!$S$2:$S$5001,"6–15") | G22: =SUMIFS(Base_Assinaturas!$I$2:$I$5001,Base_Assinaturas!$H$2:$H$5001,"Sim",Base_Assinaturas!$G$2:$G$5001,"2024-S2",Base_Assinaturas!$S$2:$S$5001,"6–15") | H22: =IF(F22>0,G22/F22,"") | I22: =IF(AND(ISNUMBER(E22),E22>0),H22/E22,"sem casos antes") | J22: 0.009253 | K22: =C22/C$5 | L22: =F22/F$5 | M22: =(L22-K22)*100
A23: Idade da conta ao assinar | B23: 181–365 dias | C23: =COUNTIFS(Base_Assinaturas!$H$2:$H$5001,"Sim",Base_Assinaturas!$G$2:$G$5001,"Até 2024-S1",Base_Assinaturas!$T$2:$T$5001,"181–365 dias") | D23: =SUMIFS(Base_Assinaturas!$I$2:$I$5001,Base_Assinaturas!$H$2:$H$5001,"Sim",Base_Assinaturas!$G$2:$G$5001,"Até 2024-S1",Base_Assinaturas!$T$2:$T$5001,"181–365 dias") | E23: =IF(C23>0,D23/C23,"") | F23: =COUNTIFS(Base_Assinaturas!$H$2:$H$5001,"Sim",Base_Assinaturas!$G$2:$G$5001,"2024-S2",Base_Assinaturas!$T$2:$T$5001,"181–365 dias") | G23: =SUMIFS(Base_Assinaturas!$I$2:$I$5001,Base_Assinaturas!$H$2:$H$5001,"Sim",Base_Assinaturas!$G$2:$G$5001,"2024-S2",Base_Assinaturas!$T$2:$T$5001,"181–365 dias") | H23: =IF(F23>0,G23/F23,"") | I23: =IF(AND(ISNUMBER(E23),E23>0),H23/E23,"sem casos antes") | J23: 0.025388 | K23: =C23/C$5 | L23: =F23/F$5 | M23: =(L23-K23)*100 | N23: 0.001 | O23: =SUMPRODUCT(L23:L27,E23:E27)
B24: 31–90 dias | C24: =COUNTIFS(Base_Assinaturas!$H$2:$H$5001,"Sim",Base_Assinaturas!$G$2:$G$5001,"Até 2024-S1",Base_Assinaturas!$T$2:$T$5001,"31–90 dias") | D24: =SUMIFS(Base_Assinaturas!$I$2:$I$5001,Base_Assinaturas!$H$2:$H$5001,"Sim",Base_Assinaturas!$G$2:$G$5001,"Até 2024-S1",Base_Assinaturas!$T$2:$T$5001,"31–90 dias") | E24: =IF(C24>0,D24/C24,"") | F24: =COUNTIFS(Base_Assinaturas!$H$2:$H$5001,"Sim",Base_Assinaturas!$G$2:$G$5001,"2024-S2",Base_Assinaturas!$T$2:$T$5001,"31–90 dias") | G24: =SUMIFS(Base_Assinaturas!$I$2:$I$5001,Base_Assinaturas!$H$2:$H$5001,"Sim",Base_Assinaturas!$G$2:$G$5001,"2024-S2",Base_Assinaturas!$T$2:$T$5001,"31–90 dias") | H24: =IF(F24>0,G24/F24,"") | I24: =IF(AND(ISNUMBER(E24),E24>0),H24/E24,"sem casos antes") | J24: 0.000833 | K24: =C24/C$5 | L24: =F24/F$5 | M24: =(L24-K24)*100
B25: 91–180 dias | C25: =COUNTIFS(Base_Assinaturas!$H$2:$H$5001,"Sim",Base_Assinaturas!$G$2:$G$5001,"Até 2024-S1",Base_Assinaturas!$T$2:$T$5001,"91–180 dias") | D25: =SUMIFS(Base_Assinaturas!$I$2:$I$5001,Base_Assinaturas!$H$2:$H$5001,"Sim",Base_Assinaturas!$G$2:$G$5001,"Até 2024-S1",Base_Assinaturas!$T$2:$T$5001,"91–180 dias") | E25: =IF(C25>0,D25/C25,"") | F25: =COUNTIFS(Base_Assinaturas!$H$2:$H$5001,"Sim",Base_Assinaturas!$G$2:$G$5001,"2024-S2",Base_Assinaturas!$T$2:$T$5001,"91–180 dias") | G25: =SUMIFS(Base_Assinaturas!$I$2:$I$5001,Base_Assinaturas!$H$2:$H$5001,"Sim",Base_Assinaturas!$G$2:$G$5001,"2024-S2",Base_Assinaturas!$T$2:$T$5001,"91–180 dias") | H25: =IF(F25>0,G25/F25,"") | I25: =IF(AND(ISNUMBER(E25),E25>0),H25/E25,"sem casos antes") | J25: 1.1e-05 | K25: =C25/C$5 | L25: =F25/F$5 | M25: =(L25-K25)*100
B26: Conta nova (≤ 30 dias) | C26: =COUNTIFS(Base_Assinaturas!$H$2:$H$5001,"Sim",Base_Assinaturas!$G$2:$G$5001,"Até 2024-S1",Base_Assinaturas!$T$2:$T$5001,"Conta nova (≤ 30 dias)") | D26: =SUMIFS(Base_Assinaturas!$I$2:$I$5001,Base_Assinaturas!$H$2:$H$5001,"Sim",Base_Assinaturas!$G$2:$G$5001,"Até 2024-S1",Base_Assinaturas!$T$2:$T$5001,"Conta nova (≤ 30 dias)") | E26: =IF(C26>0,D26/C26,"") | F26: =COUNTIFS(Base_Assinaturas!$H$2:$H$5001,"Sim",Base_Assinaturas!$G$2:$G$5001,"2024-S2",Base_Assinaturas!$T$2:$T$5001,"Conta nova (≤ 30 dias)") | G26: =SUMIFS(Base_Assinaturas!$I$2:$I$5001,Base_Assinaturas!$H$2:$H$5001,"Sim",Base_Assinaturas!$G$2:$G$5001,"2024-S2",Base_Assinaturas!$T$2:$T$5001,"Conta nova (≤ 30 dias)") | H26: =IF(F26>0,G26/F26,"") | I26: =IF(AND(ISNUMBER(E26),E26>0),H26/E26,"sem casos antes") | J26: 0.000529 | K26: =C26/C$5 | L26: =F26/F$5 | M26: =(L26-K26)*100
B27: Mais de 365 dias | C27: =COUNTIFS(Base_Assinaturas!$H$2:$H$5001,"Sim",Base_Assinaturas!$G$2:$G$5001,"Até 2024-S1",Base_Assinaturas!$T$2:$T$5001,"Mais de 365 dias") | D27: =SUMIFS(Base_Assinaturas!$I$2:$I$5001,Base_Assinaturas!$H$2:$H$5001,"Sim",Base_Assinaturas!$G$2:$G$5001,"Até 2024-S1",Base_Assinaturas!$T$2:$T$5001,"Mais de 365 dias") | E27: =IF(C27>0,D27/C27,"") | F27: =COUNTIFS(Base_Assinaturas!$H$2:$H$5001,"Sim",Base_Assinaturas!$G$2:$G$5001,"2024-S2",Base_Assinaturas!$T$2:$T$5001,"Mais de 365 dias") | G27: =SUMIFS(Base_Assinaturas!$I$2:$I$5001,Base_Assinaturas!$H$2:$H$5001,"Sim",Base_Assinaturas!$G$2:$G$5001,"2024-S2",Base_Assinaturas!$T$2:$T$5001,"Mais de 365 dias") | H27: =IF(F27>0,G27/F27,"") | I27: =IF(AND(ISNUMBER(E27),E27>0),H27/E27,"sem casos antes") | J27: 0.054163 | K27: =C27/C$5 | L27: =F27/F$5 | M27: =(L27-K27)*100
A28: Indústria | B28: Cybersecurity | C28: =COUNTIFS(Base_Assinaturas!$H$2:$H$5001,"Sim",Base_Assinaturas!$G$2:$G$5001,"Até 2024-S1",Base_Assinaturas!$U$2:$U$5001,"Cybersecurity") | D28: =SUMIFS(Base_Assinaturas!$I$2:$I$5001,Base_Assinaturas!$H$2:$H$5001,"Sim",Base_Assinaturas!$G$2:$G$5001,"Até 2024-S1",Base_Assinaturas!$U$2:$U$5001,"Cybersecurity") | E28: =IF(C28>0,D28/C28,"") | F28: =COUNTIFS(Base_Assinaturas!$H$2:$H$5001,"Sim",Base_Assinaturas!$G$2:$G$5001,"2024-S2",Base_Assinaturas!$U$2:$U$5001,"Cybersecurity") | G28: =SUMIFS(Base_Assinaturas!$I$2:$I$5001,Base_Assinaturas!$H$2:$H$5001,"Sim",Base_Assinaturas!$G$2:$G$5001,"2024-S2",Base_Assinaturas!$U$2:$U$5001,"Cybersecurity") | H28: =IF(F28>0,G28/F28,"") | I28: =IF(AND(ISNUMBER(E28),E28>0),H28/E28,"sem casos antes") | J28: 0.000915 | K28: =C28/C$5 | L28: =F28/F$5 | M28: =(L28-K28)*100 | N28: 0.001 | O28: =SUMPRODUCT(L28:L32,E28:E32)
B29: DevTools | C29: =COUNTIFS(Base_Assinaturas!$H$2:$H$5001,"Sim",Base_Assinaturas!$G$2:$G$5001,"Até 2024-S1",Base_Assinaturas!$U$2:$U$5001,"DevTools") | D29: =SUMIFS(Base_Assinaturas!$I$2:$I$5001,Base_Assinaturas!$H$2:$H$5001,"Sim",Base_Assinaturas!$G$2:$G$5001,"Até 2024-S1",Base_Assinaturas!$U$2:$U$5001,"DevTools") | E29: =IF(C29>0,D29/C29,"") | F29: =COUNTIFS(Base_Assinaturas!$H$2:$H$5001,"Sim",Base_Assinaturas!$G$2:$G$5001,"2024-S2",Base_Assinaturas!$U$2:$U$5001,"DevTools") | G29: =SUMIFS(Base_Assinaturas!$I$2:$I$5001,Base_Assinaturas!$H$2:$H$5001,"Sim",Base_Assinaturas!$G$2:$G$5001,"2024-S2",Base_Assinaturas!$U$2:$U$5001,"DevTools") | H29: =IF(F29>0,G29/F29,"") | I29: =IF(AND(ISNUMBER(E29),E29>0),H29/E29,"sem casos antes") | J29: 0.001714 | K29: =C29/C$5 | L29: =F29/F$5 | M29: =(L29-K29)*100
B30: EdTech | C30: =COUNTIFS(Base_Assinaturas!$H$2:$H$5001,"Sim",Base_Assinaturas!$G$2:$G$5001,"Até 2024-S1",Base_Assinaturas!$U$2:$U$5001,"EdTech") | D30: =SUMIFS(Base_Assinaturas!$I$2:$I$5001,Base_Assinaturas!$H$2:$H$5001,"Sim",Base_Assinaturas!$G$2:$G$5001,"Até 2024-S1",Base_Assinaturas!$U$2:$U$5001,"EdTech") | E30: =IF(C30>0,D30/C30,"") | F30: =COUNTIFS(Base_Assinaturas!$H$2:$H$5001,"Sim",Base_Assinaturas!$G$2:$G$5001,"2024-S2",Base_Assinaturas!$U$2:$U$5001,"EdTech") | G30: =SUMIFS(Base_Assinaturas!$I$2:$I$5001,Base_Assinaturas!$H$2:$H$5001,"Sim",Base_Assinaturas!$G$2:$G$5001,"2024-S2",Base_Assinaturas!$U$2:$U$5001,"EdTech") | H30: =IF(F30>0,G30/F30,"") | I30: =IF(AND(ISNUMBER(E30),E30>0),H30/E30,"sem casos antes") | J30: 0.120218 | K30: =C30/C$5 | L30: =F30/F$5 | M30: =(L30-K30)*100
B31: FinTech | C31: =COUNTIFS(Base_Assinaturas!$H$2:$H$5001,"Sim",Base_Assinaturas!$G$2:$G$5001,"Até 2024-S1",Base_Assinaturas!$U$2:$U$5001,"FinTech") | D31: =SUMIFS(Base_Assinaturas!$I$2:$I$5001,Base_Assinaturas!$H$2:$H$5001,"Sim",Base_Assinaturas!$G$2:$G$5001,"Até 2024-S1",Base_Assinaturas!$U$2:$U$5001,"FinTech") | E31: =IF(C31>0,D31/C31,"") | F31: =COUNTIFS(Base_Assinaturas!$H$2:$H$5001,"Sim",Base_Assinaturas!$G$2:$G$5001,"2024-S2",Base_Assinaturas!$U$2:$U$5001,"FinTech") | G31: =SUMIFS(Base_Assinaturas!$I$2:$I$5001,Base_Assinaturas!$H$2:$H$5001,"Sim",Base_Assinaturas!$G$2:$G$5001,"2024-S2",Base_Assinaturas!$U$2:$U$5001,"FinTech") | H31: =IF(F31>0,G31/F31,"") | I31: =IF(AND(ISNUMBER(E31),E31>0),H31/E31,"sem casos antes") | J31: 6.4e-05 | K31: =C31/C$5 | L31: =F31/F$5 | M31: =(L31-K31)*100
B32: HealthTech | C32: =COUNTIFS(Base_Assinaturas!$H$2:$H$5001,"Sim",Base_Assinaturas!$G$2:$G$5001,"Até 2024-S1",Base_Assinaturas!$U$2:$U$5001,"HealthTech") | D32: =SUMIFS(Base_Assinaturas!$I$2:$I$5001,Base_Assinaturas!$H$2:$H$5001,"Sim",Base_Assinaturas!$G$2:$G$5001,"Até 2024-S1",Base_Assinaturas!$U$2:$U$5001,"HealthTech") | E32: =IF(C32>0,D32/C32,"") | F32: =COUNTIFS(Base_Assinaturas!$H$2:$H$5001,"Sim",Base_Assinaturas!$G$2:$G$5001,"2024-S2",Base_Assinaturas!$U$2:$U$5001,"HealthTech") | G32: =SUMIFS(Base_Assinaturas!$I$2:$I$5001,Base_Assinaturas!$H$2:$H$5001,"Sim",Base_Assinaturas!$G$2:$G$5001,"2024-S2",Base_Assinaturas!$U$2:$U$5001,"HealthTech") | H32: =IF(F32>0,G32/F32,"") | I32: =IF(AND(ISNUMBER(E32),E32>0),H32/E32,"sem casos antes") | J32: 0.000589 | K32: =C32/C$5 | L32: =F32/F$5 | M32: =(L32-K32)*100
A33: País | B33: AU | C33: =COUNTIFS(Base_Assinaturas!$H$2:$H$5001,"Sim",Base_Assinaturas!$G$2:$G$5001,"Até 2024-S1",Base_Assinaturas!$V$2:$V$5001,"AU") | D33: =SUMIFS(Base_Assinaturas!$I$2:$I$5001,Base_Assinaturas!$H$2:$H$5001,"Sim",Base_Assinaturas!$G$2:$G$5001,"Até 2024-S1",Base_Assinaturas!$V$2:$V$5001,"AU") | E33: =IF(C33>0,D33/C33,"") | F33: =COUNTIFS(Base_Assinaturas!$H$2:$H$5001,"Sim",Base_Assinaturas!$G$2:$G$5001,"2024-S2",Base_Assinaturas!$V$2:$V$5001,"AU") | G33: =SUMIFS(Base_Assinaturas!$I$2:$I$5001,Base_Assinaturas!$H$2:$H$5001,"Sim",Base_Assinaturas!$G$2:$G$5001,"2024-S2",Base_Assinaturas!$V$2:$V$5001,"AU") | H33: =IF(F33>0,G33/F33,"") | I33: =IF(AND(ISNUMBER(E33),E33>0),H33/E33,"sem casos antes") | J33: 0.340355 | K33: =C33/C$5 | L33: =F33/F$5 | M33: =(L33-K33)*100 | N33: 0.022 | O33: =SUMPRODUCT(L33:L39,E33:E39)
B34: CA | C34: =COUNTIFS(Base_Assinaturas!$H$2:$H$5001,"Sim",Base_Assinaturas!$G$2:$G$5001,"Até 2024-S1",Base_Assinaturas!$V$2:$V$5001,"CA") | D34: =SUMIFS(Base_Assinaturas!$I$2:$I$5001,Base_Assinaturas!$H$2:$H$5001,"Sim",Base_Assinaturas!$G$2:$G$5001,"Até 2024-S1",Base_Assinaturas!$V$2:$V$5001,"CA") | E34: =IF(C34>0,D34/C34,"") | F34: =COUNTIFS(Base_Assinaturas!$H$2:$H$5001,"Sim",Base_Assinaturas!$G$2:$G$5001,"2024-S2",Base_Assinaturas!$V$2:$V$5001,"CA") | G34: =SUMIFS(Base_Assinaturas!$I$2:$I$5001,Base_Assinaturas!$H$2:$H$5001,"Sim",Base_Assinaturas!$G$2:$G$5001,"2024-S2",Base_Assinaturas!$V$2:$V$5001,"CA") | H34: =IF(F34>0,G34/F34,"") | I34: =IF(AND(ISNUMBER(E34),E34>0),H34/E34,"sem casos antes") | J34: 0.042743 | K34: =C34/C$5 | L34: =F34/F$5 | M34: =(L34-K34)*100
B35: DE | C35: =COUNTIFS(Base_Assinaturas!$H$2:$H$5001,"Sim",Base_Assinaturas!$G$2:$G$5001,"Até 2024-S1",Base_Assinaturas!$V$2:$V$5001,"DE") | D35: =SUMIFS(Base_Assinaturas!$I$2:$I$5001,Base_Assinaturas!$H$2:$H$5001,"Sim",Base_Assinaturas!$G$2:$G$5001,"Até 2024-S1",Base_Assinaturas!$V$2:$V$5001,"DE") | E35: =IF(C35>0,D35/C35,"") | F35: =COUNTIFS(Base_Assinaturas!$H$2:$H$5001,"Sim",Base_Assinaturas!$G$2:$G$5001,"2024-S2",Base_Assinaturas!$V$2:$V$5001,"DE") | G35: =SUMIFS(Base_Assinaturas!$I$2:$I$5001,Base_Assinaturas!$H$2:$H$5001,"Sim",Base_Assinaturas!$G$2:$G$5001,"2024-S2",Base_Assinaturas!$V$2:$V$5001,"DE") | H35: =IF(F35>0,G35/F35,"") | I35: =IF(AND(ISNUMBER(E35),E35>0),H35/E35,"sem casos antes") | J35: 0.571033 | K35: =C35/C$5 | L35: =F35/F$5 | M35: =(L35-K35)*100
B36: FR | C36: =COUNTIFS(Base_Assinaturas!$H$2:$H$5001,"Sim",Base_Assinaturas!$G$2:$G$5001,"Até 2024-S1",Base_Assinaturas!$V$2:$V$5001,"FR") | D36: =SUMIFS(Base_Assinaturas!$I$2:$I$5001,Base_Assinaturas!$H$2:$H$5001,"Sim",Base_Assinaturas!$G$2:$G$5001,"Até 2024-S1",Base_Assinaturas!$V$2:$V$5001,"FR") | E36: =IF(C36>0,D36/C36,"") | F36: =COUNTIFS(Base_Assinaturas!$H$2:$H$5001,"Sim",Base_Assinaturas!$G$2:$G$5001,"2024-S2",Base_Assinaturas!$V$2:$V$5001,"FR") | G36: =SUMIFS(Base_Assinaturas!$I$2:$I$5001,Base_Assinaturas!$H$2:$H$5001,"Sim",Base_Assinaturas!$G$2:$G$5001,"2024-S2",Base_Assinaturas!$V$2:$V$5001,"FR") | H36: =IF(F36>0,G36/F36,"") | I36: =IF(AND(ISNUMBER(E36),E36>0),H36/E36,"sem casos antes") | J36: 0.13173 | K36: =C36/C$5 | L36: =F36/F$5 | M36: =(L36-K36)*100
B37: IN | C37: =COUNTIFS(Base_Assinaturas!$H$2:$H$5001,"Sim",Base_Assinaturas!$G$2:$G$5001,"Até 2024-S1",Base_Assinaturas!$V$2:$V$5001,"IN") | D37: =SUMIFS(Base_Assinaturas!$I$2:$I$5001,Base_Assinaturas!$H$2:$H$5001,"Sim",Base_Assinaturas!$G$2:$G$5001,"Até 2024-S1",Base_Assinaturas!$V$2:$V$5001,"IN") | E37: =IF(C37>0,D37/C37,"") | F37: =COUNTIFS(Base_Assinaturas!$H$2:$H$5001,"Sim",Base_Assinaturas!$G$2:$G$5001,"2024-S2",Base_Assinaturas!$V$2:$V$5001,"IN") | G37: =SUMIFS(Base_Assinaturas!$I$2:$I$5001,Base_Assinaturas!$H$2:$H$5001,"Sim",Base_Assinaturas!$G$2:$G$5001,"2024-S2",Base_Assinaturas!$V$2:$V$5001,"IN") | H37: =IF(F37>0,G37/F37,"") | I37: =IF(AND(ISNUMBER(E37),E37>0),H37/E37,"sem casos antes") | J37: 0.000986 | K37: =C37/C$5 | L37: =F37/F$5 | M37: =(L37-K37)*100
B38: UK | C38: =COUNTIFS(Base_Assinaturas!$H$2:$H$5001,"Sim",Base_Assinaturas!$G$2:$G$5001,"Até 2024-S1",Base_Assinaturas!$V$2:$V$5001,"UK") | D38: =SUMIFS(Base_Assinaturas!$I$2:$I$5001,Base_Assinaturas!$H$2:$H$5001,"Sim",Base_Assinaturas!$G$2:$G$5001,"Até 2024-S1",Base_Assinaturas!$V$2:$V$5001,"UK") | E38: =IF(C38>0,D38/C38,"") | F38: =COUNTIFS(Base_Assinaturas!$H$2:$H$5001,"Sim",Base_Assinaturas!$G$2:$G$5001,"2024-S2",Base_Assinaturas!$V$2:$V$5001,"UK") | G38: =SUMIFS(Base_Assinaturas!$I$2:$I$5001,Base_Assinaturas!$H$2:$H$5001,"Sim",Base_Assinaturas!$G$2:$G$5001,"2024-S2",Base_Assinaturas!$V$2:$V$5001,"UK") | H38: =IF(F38>0,G38/F38,"") | I38: =IF(AND(ISNUMBER(E38),E38>0),H38/E38,"sem casos antes") | J38: 0.006237 | K38: =C38/C$5 | L38: =F38/F$5 | M38: =(L38-K38)*100
B39: US | C39: =COUNTIFS(Base_Assinaturas!$H$2:$H$5001,"Sim",Base_Assinaturas!$G$2:$G$5001,"Até 2024-S1",Base_Assinaturas!$V$2:$V$5001,"US") | D39: =SUMIFS(Base_Assinaturas!$I$2:$I$5001,Base_Assinaturas!$H$2:$H$5001,"Sim",Base_Assinaturas!$G$2:$G$5001,"Até 2024-S1",Base_Assinaturas!$V$2:$V$5001,"US") | E39: =IF(C39>0,D39/C39,"") | F39: =COUNTIFS(Base_Assinaturas!$H$2:$H$5001,"Sim",Base_Assinaturas!$G$2:$G$5001,"2024-S2",Base_Assinaturas!$V$2:$V$5001,"US") | G39: =SUMIFS(Base_Assinaturas!$I$2:$I$5001,Base_Assinaturas!$H$2:$H$5001,"Sim",Base_Assinaturas!$G$2:$G$5001,"2024-S2",Base_Assinaturas!$V$2:$V$5001,"US") | H39: =IF(F39>0,G39/F39,"") | I39: =IF(AND(ISNUMBER(E39),E39>0),H39/E39,"sem casos antes") | J39: 1e-06 | K39: =C39/C$5 | L39: =F39/F$5 | M39: =(L39-K39)*100
A40: Canal de aquisição | B40: ads | C40: =COUNTIFS(Base_Assinaturas!$H$2:$H$5001,"Sim",Base_Assinaturas!$G$2:$G$5001,"Até 2024-S1",Base_Assinaturas!$W$2:$W$5001,"ads") | D40: =SUMIFS(Base_Assinaturas!$I$2:$I$5001,Base_Assinaturas!$H$2:$H$5001,"Sim",Base_Assinaturas!$G$2:$G$5001,"Até 2024-S1",Base_Assinaturas!$W$2:$W$5001,"ads") | E40: =IF(C40>0,D40/C40,"") | F40: =COUNTIFS(Base_Assinaturas!$H$2:$H$5001,"Sim",Base_Assinaturas!$G$2:$G$5001,"2024-S2",Base_Assinaturas!$W$2:$W$5001,"ads") | G40: =SUMIFS(Base_Assinaturas!$I$2:$I$5001,Base_Assinaturas!$H$2:$H$5001,"Sim",Base_Assinaturas!$G$2:$G$5001,"2024-S2",Base_Assinaturas!$W$2:$W$5001,"ads") | H40: =IF(F40>0,G40/F40,"") | I40: =IF(AND(ISNUMBER(E40),E40>0),H40/E40,"sem casos antes") | J40: 0.013866 | K40: =C40/C$5 | L40: =F40/F$5 | M40: =(L40-K40)*100 | N40: 0.046 | O40: =SUMPRODUCT(L40:L44,E40:E44)
B41: event | C41: =COUNTIFS(Base_Assinaturas!$H$2:$H$5001,"Sim",Base_Assinaturas!$G$2:$G$5001,"Até 2024-S1",Base_Assinaturas!$W$2:$W$5001,"event") | D41: =SUMIFS(Base_Assinaturas!$I$2:$I$5001,Base_Assinaturas!$H$2:$H$5001,"Sim",Base_Assinaturas!$G$2:$G$5001,"Até 2024-S1",Base_Assinaturas!$W$2:$W$5001,"event") | E41: =IF(C41>0,D41/C41,"") | F41: =COUNTIFS(Base_Assinaturas!$H$2:$H$5001,"Sim",Base_Assinaturas!$G$2:$G$5001,"2024-S2",Base_Assinaturas!$W$2:$W$5001,"event") | G41: =SUMIFS(Base_Assinaturas!$I$2:$I$5001,Base_Assinaturas!$H$2:$H$5001,"Sim",Base_Assinaturas!$G$2:$G$5001,"2024-S2",Base_Assinaturas!$W$2:$W$5001,"event") | H41: =IF(F41>0,G41/F41,"") | I41: =IF(AND(ISNUMBER(E41),E41>0),H41/E41,"sem casos antes") | J41: 0.158511 | K41: =C41/C$5 | L41: =F41/F$5 | M41: =(L41-K41)*100
...

Sheet Dezembro
A1: Dezembro de 2024: o que há de diferente nos encerramentos?
A2: Contagens por fórmula sobre Base_Assinaturas. "Esperado" = média diária dos 11 primeiros meses de 2024 escalada pelo número de assinaturas ativas (aproximação).
A4: 1. Encerramentos por dia em dezembro/2024
A5: Dia | B5: Assinaturas encerradas | C5: MRR encerrado (US$)
A6: 45627 | B6: =COUNTIFS(Base_Assinaturas!$D$2:$D$5001,A6) | C6: =SUMIFS(Base_Assinaturas!$F$2:$F$5001,Base_Assinaturas!$D$2:$D$5001,A6)
A7: 45628 | B7: =COUNTIFS(Base_Assinaturas!$D$2:$D$5001,A7) | C7: =SUMIFS(Base_Assinaturas!$F$2:$F$5001,Base_Assinaturas!$D$2:$D$5001,A7)
A8: 45629 | B8: =COUNTIFS(Base_Assinaturas!$D$2:$D$5001,A8) | C8: =SUMIFS(Base_Assinaturas!$F$2:$F$5001,Base_Assinaturas!$D$2:$D$5001,A8)
A9: 45630 | B9: =COUNTIFS(Base_Assinaturas!$D$2:$D$5001,A9) | C9: =SUMIFS(Base_Assinaturas!$F$2:$F$5001,Base_Assinaturas!$D$2:$D$5001,A9)
A10: 45631 | B10: =COUNTIFS(Base_Assinaturas!$D$2:$D$5001,A10) | C10: =SUMIFS(Base_Assinaturas!$F$2:$F$5001,Base_Assinaturas!$D$2:$D$5001,A10)
A11: 45632 | B11: =COUNTIFS(Base_Assinaturas!$D$2:$D$5001,A11) | C11: =SUMIFS(Base_Assinaturas!$F$2:$F$5001,Base_Assinaturas!$D$2:$D$5001,A11)
A12: 45633 | B12: =COUNTIFS(Base_Assinaturas!$D$2:$D$5001,A12) | C12: =SUMIFS(Base_Assinaturas!$F$2:$F$5001,Base_Assinaturas!$D$2:$D$5001,A12)
A13: 45634 | B13: =COUNTIFS(Base_Assinaturas!$D$2:$D$5001,A13) | C13: =SUMIFS(Base_Assinaturas!$F$2:$F$5001,Base_Assinaturas!$D$2:$D$5001,A13)
A14: 45635 | B14: =COUNTIFS(Base_Assinaturas!$D$2:$D$5001,A14) | C14: =SUMIFS(Base_Assinaturas!$F$2:$F$5001,Base_Assinaturas!$D$2:$D$5001,A14)
A15: 45636 | B15: =COUNTIFS(Base_Assinaturas!$D$2:$D$5001,A15) | C15: =SUMIFS(Base_Assinaturas!$F$2:$F$5001,Base_Assinaturas!$D$2:$D$5001,A15)
A16: 45637 | B16: =COUNTIFS(Base_Assinaturas!$D$2:$D$5001,A16) | C16: =SUMIFS(Base_Assinaturas!$F$2:$F$5001,Base_Assinaturas!$D$2:$D$5001,A16)
A17: 45638 | B17: =COUNTIFS(Base_Assinaturas!$D$2:$D$5001,A17) | C17: =SUMIFS(Base_Assinaturas!$F$2:$F$5001,Base_Assinaturas!$D$2:$D$5001,A17)
... A36: 45657 | B36: =COUNTIFS(Base_Assinaturas!$D$2:$D$5001,A36) | C36: =SUMIFS(Base_Assinaturas!$F$2:$F$5001,Base_Assinaturas!$D$2:$D$5001,A36)
A37: Total | B37: =SUM(B6:B36) | C37: =SUM(C6:C36)
A38: Dias 29–31 | B38: =SUM(B34:B36) | C38: =SUM(C34:C36)
A39: Média/dia dias 1–28 | B39: =AVERAGE(B6:B33)
A40: Média/dia dias 29–31 | B40: =AVERAGE(B34:B36)
A43: 2. Fim de mês é comum? % dos encerramentos nos 3 últimos dias do mês
A44: Mês | B44: Encerradas | C44: Nos 3 últimos dias | D44: %
A45: 45292 | B45: =COUNTIFS(Base_Assinaturas!$J$2:$J$5001,A45) | C45: =COUNTIFS(Base_Assinaturas!$J$2:$J$5001,A45,Base_Assinaturas!$L$2:$L$5001,"Sim") | D45: =IF(B45>0,C45/B45,"")
A46: 45323 | B46: =COUNTIFS(Base_Assinaturas!$J$2:$J$5001,A46) | C46: =COUNTIFS(Base_Assinaturas!$J$2:$J$5001,A46,Base_Assinaturas!$L$2:$L$5001,"Sim") | D46: =IF(B46>0,C46/B46,"")
A47: 45352 | B47: =COUNTIFS(Base_Assinaturas!$J$2:$J$5001,A47) | C47: =COUNTIFS(Base_Assinaturas!$J$2:$J$5001,A47,Base_Assinaturas!$L$2:$L$5001,"Sim") | D47: =IF(B47>0,C47/B47,"")
A48: 45383 | B48: =COUNTIFS(Base_Assinaturas!$J$2:$J$5001,A48) | C48: =COUNTIFS(Base_Assinaturas!$J$2:$J$5001,A48,Base_Assinaturas!$L$2:$L$5001,"Sim") | D48: =IF(B48>0,C48/B48,"")
A49: 45413 | B49: =COUNTIFS(Base_Assinaturas!$J$2:$J$5001,A49) | C49: =COUNTIFS(Base_Assinaturas!$J$2:$J$5001,A49,Base_Assinaturas!$L$2:$L$5001,"Sim") | D49: =IF(B49>0,C49/B49,"")
A50: 45444 | B50: =COUNTIFS(Base_Assinaturas!$J$2:$J$5001,A50) | C50: =COUNTIFS(Base_Assinaturas!$J$2:$J$5001,A50,Base_Assinaturas!$L$2:$L$5001,"Sim") | D50: =IF(B50>0,C50/B50,"")
A51: 45474 | B51: =COUNTIFS(Base_Assinaturas!$J$2:$J$5001,A51) | C51: =COUNTIFS(Base_Assinaturas!$J$2:$J$5001,A51,Base_Assinaturas!$L$2:$L$5001,"Sim") | D51: =IF(B51>0,C51/B51,"")
A52: 45505 | B52: =COUNTIFS(Base_Assinaturas!$J$2:$J$5001,A52) | C52: =COUNTIFS(Base_Assinaturas!$J$2:$J$5001,A52,Base_Assinaturas!$L$2:$L$5001,"Sim") | D52: =IF(B52>0,C52/B52,"")
A53: 45536 | B53: =COUNTIFS(Base_Assinaturas!$J$2:$J$5001,A53) | C53: =COUNTIFS(Base_Assinaturas!$J$2:$J$5001,A53,Base_Assinaturas!$L$2:$L$5001,"Sim") | D53: =IF(B53>0,C53/B53,"")
A54: 45566 | B54: =COUNTIFS(Base_Assinaturas!$J$2:$J$5001,A54) | C54: =COUNTIFS(Base_Assinaturas!$J$2:$J$5001,A54,Base_Assinaturas!$L$2:$L$5001,"Sim") | D54: =IF(B54>0,C54/B54,"")
A55: 45597 | B55: =COUNTIFS(Base_Assinaturas!$J$2:$J$5001,A55) | C55: =COUNTIFS(Base_Assinaturas!$J$2:$J$5001,A55,Base_Assinaturas!$L$2:$L$5001,"Sim") | D55: =IF(B55>0,C55/B55,"")
A56: 45627 | B56: =COUNTIFS(Base_Assinaturas!$J$2:$J$5001,A56) | C56: =COUNTIFS(Base_Assinaturas!$J$2:$J$5001,A56,Base_Assinaturas!$L$2:$L$5001,"Sim") | D56: =IF(B56>0,C56/B56,"")
A57: jan–nov/24 | B57: =SUM(B45:B55) | C57: =SUM(C45:C55) | D57: =C57/B57
A58: Referência: 3 dias de ~30 ≈ 10% se os encerramentos fossem espalhados ao longo do mês.
A60: 3. Quem encerrou em dezembro: tempo de vida e perfil
A61: Indicador | B61: Encerradas em dez/24 | C61: Encerradas jan–nov/24
A62: Assinaturas | B62: =COUNTIFS(Base_Assinaturas!$J$2:$J$5001,DATE(2024,12,1)) | C62: =COUNTIFS(Base_Assinaturas!$J$2:$J$5001,">="&DATE(2024,1,1),Base_Assinaturas!$J$2:$J$5001,"<"&DATE(2024,12,1))
...

Sheet Sinais_no_tempo
A1: Sinais no tempo: churn subiu; suporte e uso não acompanharam
A2: Tudo por fórmula sobre as bases. Datas de ticket e de uso têm problemas de coerência com a conta (ver 01_Evidencias); aqui olhamos só a tendência do mês, sem ligar a conta.
A4: Mês | B4: Assinaturas iniciadas | C4: Iniciadas que encerraram em 30 dias | D4: % encerra em 30 dias (coorte do mês) | E4: Tickets | F4: Satisfação média | G4: Resolução média (h) | H4: 1ª resposta média (min) | I4: % escalados | J4: Uso total (usage_count) | K4: Erros por 100 usos
A5: 44927 | B5: =COUNTIFS(Base_Assinaturas!$C$2:$C$5001,">="&A5,Base_Assinaturas!$C$2:$C$5001,"<"&EDATE(A5,1)) | C5: =SUMIFS(Base_Assinaturas!$I$2:$I$5001,Base_Assinaturas!$C$2:$C$5001,">="&A5,Base_Assinaturas!$C$2:$C$5001,"<"&EDATE(A5,1)) | D5: =IF(B5>0,C5/B5,"") | E5: =COUNTIFS(Base_Tickets!$C$2:$C$2001,A5) | F5: =IFERROR(AVERAGEIFS(Base_Tickets!$F$2:$F$2001,Base_Tickets!$C$2:$C$2001,A5),"") | G5: =IFERROR(AVERAGEIFS(Base_Tickets!$D$2:$D$2001,Base_Tickets!$C$2:$C$2001,A5),"") | H5: =IFERROR(AVERAGEIFS(Base_Tickets!$E$2:$E$2001,Base_Tickets!$C$2:$C$2001,A5),"") | I5: =IFERROR(AVERAGEIFS(Base_Tickets!$G$2:$G$2001,Base_Tickets!$C$2:$C$2001,A5),"") | J5: =SUMIFS(Base_Uso!$C$2:$C$25001,Base_Uso!$B$2:$B$25001,A5) | K5: =IFERROR(SUMIFS(Base_Uso!$D$2:$D$25001,Base_Uso!$B$2:$B$25001,A5)/J5*100,"")
A6: 44958 | B6: =COUNTIFS(Base_Assinaturas!$C$2:$C$5001,">="&A6,Base_Assinaturas!$C$2:$C$5001,"<"&EDATE(A6,1)) | C6: =SUMIFS(Base_Assinaturas!$I$2:$I$5001,Base_Assinaturas!$C$2:$C$5001,">="&A6,Base_Assinaturas!$C$2:$C$5001,"<"&EDATE(A6,1)) | D6: =IF(B6>0,C6/B6,"") | E6: =COUNTIFS(Base_Tickets!$C$2:$C$2001,A6) | F6: =IFERROR(AVERAGEIFS(Base_Tickets!$F$2:$F$2001,Base_Tickets!$C$2:$C$2001,A6),"") | G6: =IFERROR(AVERAGEIFS(Base_Tickets!$D$2:$D$2001,Base_Tickets!$C$2:$C$2001,A6),"") | H6: =IFERROR(AVERAGEIFS(Base_Tickets!$E$2:$E$2001,Base_Tickets!$C$2:$C$2001,A6),"") | I6: =IFERROR(AVERAGEIFS(Base_Tickets!$G$2:$G$2001,Base_Tickets!$C$2:$C$2001,A6),"") | J6: =SUMIFS(Base_Uso!$C$2:$C$25001,Base_Uso!$B$2:$B$25001,A6) | K6: =IFERROR(SUMIFS(Base_Uso!$D$2:$D$25001,Base_Uso!$B$2:$B$25001,A6)/J6*100,"")
A7: 44986 | B7: =COUNTIFS(Base_Assinaturas!$C$2:$C$5001,">="&A7,Base_Assinaturas!$C$2:$C$5001,"<"&EDATE(A7,1)) | C7: =SUMIFS(Base_Assinaturas!$I$2:$I$5001,Base_Assinaturas!$C$2:$C$5001,">="&A7,Base_Assinaturas!$C$2:$C$5001,"<"&EDATE(A7,1)) | D7: =IF(B7>0,C7/B7,"") | E7: =COUNTIFS(Base_Tickets!$C$2:$C$2001,A7) | F7: =IFERROR(AVERAGEIFS(Base_Tickets!$F$2:$F$2001,Base_Tickets!$C$2:$C$2001,A7),"") | G7: =IFERROR(AVERAGEIFS(Base_Tickets!$D$2:$D$2001,Base_Tickets!$C$2:$C$2001,A7),"") | H7: =IFERROR(AVERAGEIFS(Base_Tickets!$E$2:$E$2001,Base_Tickets!$C$2:$C$2001,A7),"") | I7: =IFERROR(AVERAGEIFS(Base_Tickets!$G$2:$G$2001,Base_Tickets!$C$2:$C$2001,A7),"") | J7: =SUMIFS(Base_Uso!$C$2:$C$25001,Base_Uso!$B$2:$B$25001,A7) | K7: =IFERROR(SUMIFS(Base_Uso!$D$2:$D$25001,Base_Uso!$B$2:$B$25001,A7)/J7*100,"")
A8: 45017 | B8: =COUNTIFS(Base_Assinaturas!$C$2:$C$5001,">="&A8,Base_Assinaturas!$C$2:$C$5001,"<"&EDATE(A8,1)) | C8: =SUMIFS(Base_Assinaturas!$I$2:$I$5001,Base_Assinaturas!$C$2:$C$5001,">="&A8,Base_Assinaturas!$C$2:$C$5001,"<"&EDATE(A8,1)) | D8: =IF(B8>0,C8/B8,"") | E8: =COUNTIFS(Base_Tickets!$C$2:$C$2001,A8) | F8: =IFERROR(AVERAGEIFS(Base_Tickets!$F$2:$F$2001,Base_Tickets!$C$2:$C$2001,A8),"") | G8: =IFERROR(AVERAGEIFS(Base_Tickets!$D$2:$D$2001,Base_Tickets!$C$2:$C$2001,A8),"") | H8: =IFERROR(AVERAGEIFS(Base_Tickets!$E$2:$E$2001,Base_Tickets!$C$2:$C$2001,A8),"") | I8: =IFERROR(AVERAGEIFS(Base_Tickets!$G$2:$G$2001,Base_Tickets!$C$2:$C$2001,A8),"") | J8: =SUMIFS(Base_Uso!$C$2:$C$25001,Base_Uso!$B$2:$B$25001,A8) | K8: =IFERROR(SUMIFS(Base_Uso!$D$2:$D$25001,Base_Uso!$B$2:$B$25001,A8)/J8*100,"")
A9: 45047 | B9: =COUNTIFS(Base_Assinaturas!$C$2:$C$5001,">="&A9,Base_Assinaturas!$C$2:$C$5001,"<"&EDATE(A9,1)) | C9: =SUMIFS(Base_Assinaturas!$I$2:$I$5001,Base_Assinaturas!$C$2:$C$5001,">="&A9,Base_Assinaturas!$C$2:$C$5001,"<"&EDATE(A9,1)) | D9: =IF(B9>0,C9/B9,"") | E9: =COUNTIFS(Base_Tickets!$C$2:$C$2001,A9) | F9: =IFERROR(AVERAGEIFS(Base_Tickets!$F$2:$F$2001,Base_Tickets!$C$2:$C$2001,A9),"") | G9: =IFERROR(AVERAGEIFS(Base_Tickets!$D$2:$D$2001,Base_Tickets!$C$2:$C$2001,A9),"") | H9: =IFERROR(AVERAGEIFS(Base_Tickets!$E$2:$E$2001,Base_Tickets!$C$2:$C$2001,A9),"") | I9: =IFERROR(AVERAGEIFS(Base_Tickets!$G$2:$G$2001,Base_Tickets!$C$2:$C$2001,A9),"") | J9: =SUMIFS(Base_Uso!$C$2:$C$25001,Base_Uso!$B$2:$B$25001,A9) | K9: =IFERROR(SUMIFS(Base_Uso!$D$2:$D$25001,Base_Uso!$B$2:$B$25001,A9)/J9*100,"")
A10: 45078 | B10: =COUNTIFS(Base_Assinaturas!$C$2:$C$5001,">="&A10,Base_Assinaturas!$C$2:$C$5001,"<"&EDATE(A10,1)) | C10: =SUMIFS(Base_Assinaturas!$I$2:$I$5001,Base_Assinaturas!$C$2:$C$5001,">="&A10,Base_Assinaturas!$C$2:$C$5001,"<"&EDATE(A10,1)) | D10: =IF(B10>0,C10/B10,"") | E10: =COUNTIFS(Base_Tickets!$C$2:$C$2001,A10) | F10: =IFERROR(AVERAGEIFS(Base_Tickets!$F$2:$F$2001,Base_Tickets!$C$2:$C$2001,A10),"") | G10: =IFERROR(AVERAGEIFS(Base_Tickets!$D$2:$D$2001,Base_Tickets!$C$2:$C$2001,A10),"") | H10: =IFERROR(AVERAGEIFS(Base_Tickets!$E$2:$E$2001,Base_Tickets!$C$2:$C$2001,A10),"") | I10: =IFERROR(AVERAGEIFS(Base_Tickets!$G$2:$G$2001,Base_Tickets!$C$2:$C$2001,A10),"") | J10: =SUMIFS(Base_Uso!$C$2:$C$25001,Base_Uso!$B$2:$B$25001,A10) | K10: =IFERROR(SUMIFS(Base_Uso!$D$2:$D$25001,Base_Uso!$B$2:$B$25001,A10)/J10*100,"")
A11: 45108 | B11: =COUNTIFS(Base_Assinaturas!$C$2:$C$5001,">="&A11,Base_Assinaturas!$C$2:$C$5001,"<"&EDATE(A11,1)) | C11: =SUMIFS(Base_Assinaturas!$I$2:$I$5001,Base_Assinaturas!$C$2:$C$5001,">="&A11,Base_Assinaturas!$C$2:$C$5001,"<"&EDATE(A11,1)) | D11: =IF(B11>0,C11/B11,"") | E11: =COUNTIFS(Base_Tickets!$C$2:$C$2001,A11) | F11: =IFERROR(AVERAGEIFS(Base_Tickets!$F$2:$F$2001,Base_Tickets!$C$2:$C$2001,A11),"") | G11: =IFERROR(AVERAGEIFS(Base_Tickets!$D$2:$D$2001,Base_Tickets!$C$2:$C$2001,A11),"") | H11: =IFERROR(AVERAGEIFS(Base_Tickets!$E$2:$E$2001,Base_Tickets!$C$2:$C$2001,A11),"") | I11: =IFERROR(AVERAGEIFS(Base_Tickets!$G$2:$G$2001,Base_Tickets!$C$2:$C$2001,A11),"") | J11: =SUMIFS(Base_Uso!$C$2:$C$25001,Base_Uso!$B$2:$B$25001,A11) | K11: =IFERROR(SUMIFS(Base_Uso!$D$2:$D$25001,Base_Uso!$B$2:$B$25001,A11)/J11*100,"")
A12: 45139 | B12: =COUNTIFS(Base_Assinaturas!$C$2:$C$5001,">="&A12,Base_Assinaturas!$C$2:$C$5001,"<"&EDATE(A12,1)) | C12: =SUMIFS(Base_Assinaturas!$I$2:$I$5001,Base_Assinaturas!$C$2:$C$5001,">="&A12,Base_Assinaturas!$C$2:$C$5001,"<"&EDATE(A12,1)) | D12: =IF(B12>0,C12/B12,"") | E12: =COUNTIFS(Base_Tickets!$C$2:$C$2001,A12) | F12: =IFERROR(AVERAGEIFS(Base_Tickets!$F$2:$F$2001,Base_Tickets!$C$2:$C$2001,A12),"") | G12: =IFERROR(AVERAGEIFS(Base_Tickets!$D$2:$D$2001,Base_Tickets!$C$2:$C$2001,A12),"") | H12: =IFERROR(AVERAGEIFS(Base_Tickets!$E$2:$E$2001,Base_Tickets!$C$2:$C$2001,A12),"") | I12: =IFERROR(AVERAGEIFS(Base_Tickets!$G$2:$G$2001,Base_Tickets!$C$2:$C$2001,A12),"") | J12: =SUMIFS(Base_Uso!$C$2:$C$25001,Base_Uso!$B$2:$B$25001,A12) | K12: =IFERROR(SUMIFS(Base_Uso!$D$2:$D$25001,Base_Uso!$B$2:$B$25001,A12)/J12*100,"")
A13: 45170 | B13: =COUNTIFS(Base_Assinaturas!$C$2:$C$5001,">="&A13,Base_Assinaturas!$C$2:$C$5001,"<"&EDATE(A13,1)) | C13: =SUMIFS(Base_Assinaturas!$I$2:$I$5001,Base_Assinaturas!$C$2:$C$5001,">="&A13,Base_Assinaturas!$C$2:$C$5001,"<"&EDATE(A13,1)) | D13: =IF(B13>0,C13/B13,"") | E13: =COUNTIFS(Base_Tickets!$C$2:$C$2001,A13) | F13: =IFERROR(AVERAGEIFS(Base_Tickets!$F$2:$F$2001,Base_Tickets!$C$2:$C$2001,A13),"") | G13: =IFERROR(AVERAGEIFS(Base_Tickets!$D$2:$D$2001,Base_Tickets!$C$2:$C$2001,A13),"") | H13: =IFERROR(AVERAGEIFS(Base_Tickets!$E$2:$E$2001,Base_Tickets!$C$2:$C$2001,A13),"") | I13: =IFERROR(AVERAGEIFS(Base_Tickets!$G$2:$G$2001,Base_Tickets!$C$2:$C$2001,A13),"") | J13: =SUMIFS(Base_Uso!$C$2:$C$25001,Base_Uso!$B$2:$B$25001,A13) | K13: =IFERROR(SUMIFS(Base_Uso!$D$2:$D$25001,Base_Uso!$B$2:$B$25001,A13)/J13*100,"")
A14: 45200 | B14: =COUNTIFS(Base_Assinaturas!$C$2:$C$5001,">="&A14,Base_Assinaturas!$C$2:$C$5001,"<"&EDATE(A14,1)) | C14: =SUMIFS(Base_Assinaturas!$I$2:$I$5001,Base_Assinaturas!$C$2:$C$5001,">="&A14,Base_Assinaturas!$C$2:$C$5001,"<"&EDATE(A14,1)) | D14: =IF(B14>0,C14/B14,"") | E14: =COUNTIFS(Base_Tickets!$C$2:$C$2001,A14) | F14: =IFERROR(AVERAGEIFS(Base_Tickets!$F$2:$F$2001,Base_Tickets!$C$2:$C$2001,A14),"") | G14: =IFERROR(AVERAGEIFS(Base_Tickets!$D$2:$D$2001,Base_Tickets!$C$2:$C$2001,A14),"") | H14: =IFERROR(AVERAGEIFS(Base_Tickets!$E$2:$E$2001,Base_Tickets!$C$2:$C$2001,A14),"") | I14: =IFERROR(AVERAGEIFS(Base_Tickets!$G$2:$G$2001,Base_Tickets!$C$2:$C$2001,A14),"") | J14: =SUMIFS(Base_Uso!$C$2:$C$25001,Base_Uso!$B$2:$B$25001,A14) | K14: =IFERROR(SUMIFS(Base_Uso!$D$2:$D$25001,Base_Uso!$B$2:$B$25001,A14)/J14*100,"")
A15: 45231 | B15: =COUNTIFS(Base_Assinaturas!$C$2:$C$5001,">="&A15,Base_Assinaturas!$C$2:$C$5001,"<"&EDATE(A15,1)) | C15: =SUMIFS(Base_Assinaturas!$I$2:$I$5001,Base_Assinaturas!$C$2:$C$5001,">="&A15,Base_Assinaturas!$C$2:$C$5001,"<"&EDATE(A15,1)) | D15: =IF(B15>0,C15/B15,"") | E15: =COUNTIFS(Base_Tickets!$C$2:$C$2001,A15) | F15: =IFERROR(AVERAGEIFS(Base_Tickets!$F$2:$F$2001,Base_Tickets!$C$2:$C$2001,A15),"") | G15: =IFERROR(AVERAGEIFS(Base_Tickets!$D$2:$D$2001,Base_Tickets!$C$2:$C$2001,A15),"") | H15: =IFERROR(AVERAGEIFS(Base_Tickets!$E$2:$E$2001,Base_Tickets!$C$2:$C$2001,A15),"") | I15: =IFERROR(AVERAGEIFS(Base_Tickets!$G$2:$G$2001,Base_Tickets!$C$2:$C$2001,A15),"") | J15: =SUMIFS(Base_Uso!$C$2:$C$25001,Base_Uso!$B$2:$B$25001,A15) | K15: =IFERROR(SUMIFS(Base_Uso!$D$2:$D$25001,Base_Uso!$B$2:$B$25001,A15)/J15*100,"")
A16: 45261 | B16: =COUNTIFS(Base_Assinaturas!$C$2:$C$5001,">="&A16,Base_Assinaturas!$C$2:$C$5001,"<"&EDATE(A16,1)) | C16: =SUMIFS(Base_Assinaturas!$I$2:$I$5001,Base_Assinaturas!$C$2:$C$5001,">="&A16,Base_Assinaturas!$C$2:$C$5001,"<"&EDATE(A16,1)) | D16: =IF(B16>0,C16/B16,"") | E16: =COUNTIFS(Base_Tickets!$C$2:$C$2001,A16) | F16: =IFERROR(AVERAGEIFS(Base_Tickets!$F$2:$F$2001,Base_Tickets!$C$2:$C$2001,A16),"") | G16: =IFERROR(AVERAGEIFS(Base_Tickets!$D$2:$D$2001,Base_Tickets!$C$2:$C$2001,A16),"") | H16: =IFERROR(AVERAGEIFS(Base_Tickets!$E$2:$E$2001,Base_Tickets!$C$2:$C$2001,A16),"") | I16: =IFERROR(AVERAGEIFS(Base_Tickets!$G$2:$G$2001,Base_Tickets!$C$2:$C$2001,A16),"") | J16: =SUMIFS(Base_Uso!$C$2:$C$25001,Base_Uso!$B$2:$B$25001,A16) | K16: =IFERROR(SUMIFS(Base_Uso!$D$2:$D$25001,Base_Uso!$B$2:$B$25001,A16)/J16*100,"")
... A27: 45597 | B27: =COUNTIFS(Base_Assinaturas!$C$2:$C$5001,">="&A27,Base_Assinaturas!$C$2:$C$5001,"<"&EDATE(A27,1)) | C27: =SUMIFS(Base_Assinaturas!$I$2:$I$5001,Base_Assinaturas!$C$2:$C$5001,">="&A27,Base_Assinaturas!$C$2:$C$5001,"<"&EDATE(A27,1)) | D27: =IF(B27>0,C27/B27,"") | E27: =COUNTIFS(Base_Tickets!$C$2:$C$2001,A27) | F27: =IFERROR(AVERAGEIFS(Base_Tickets!$F$2:$F$2001,Base_Tickets!$C$2:$C$2001,A27),"") | G27: =IFERROR(AVERAGEIFS(Base_Tickets!$D$2:$D$2001,Base_Tickets!$C$2:$C$2001,A27),"") | H27: =IFERROR(AVERAGEIFS(Base_Tickets!$E$2:$E$2001,Base_Tickets!$C$2:$C$2001,A27),"") | I27: =IFERROR(AVERAGEIFS(Base_Tickets!$G$2:$G$2001,Base_Tickets!$C$2:$C$2001,A27),"") | J27: =SUMIFS(Base_Uso!$C$2:$C$25001,Base_Uso!$B$2:$B$25001,A27) | K27: =IFERROR(SUMIFS(Base_Uso!$D$2:$D$25001,Base_Uso!$B$2:$B$25001,A27)/J27*100,"")
A28: Coortes até nov/24 (dez/24 ainda não teve 30 dias). Leitura: % que encerra em 30 dias sobe a partir de jul/24; satisfação, tempos de atendimento, escalação, uso e erros ficam estáveis. O CS está certo (satisfação ok) e o produto também (uso não caiu), mas nenhum desses indicadores acompanha o churn.

Sheet Subconjunto_limpo
A1: Subconjunto limpo: 100 contas em que as 3 marcações concordam
A2: 50 contas com churn nas 3 definições (churn_flag, evento e assinatura encerrada) vs 50 sem churn em nenhuma. Médias por fórmula; p = permutação (5.000 sorteios) entre os dois grupos limpos.
A4: Indicador | B4: Churn (3 concordam) | C4: Ativa (3 concordam) | D4: Divergente (400) | E4: Diferença (churn − ativa) | F4: p (churn vs ativa) | G4: Leitura
A5: Contas | B5: =COUNTIFS(Base_Contas!$B$2:$B$501,"Churn (3 concordam)") | C5: =COUNTIFS(Base_Contas!$B$2:$B$501,"Ativa (3 concordam)") | D5: =COUNTIFS(Base_Contas!$B$2:$B$501,"Divergente")
A6: MRR ativo (US$) | B6: =IFERROR(AVERAGEIFS(Base_Contas!$H$2:$H$501,Base_Contas!$B$2:$B$501,"Churn (3 concordam)"),"") | C6: =IFERROR(AVERAGEIFS(Base_Contas!$H$2:$H$501,Base_Contas!$B$2:$B$501,"Ativa (3 concordam)"),"") | D6: =IFERROR(AVERAGEIFS(Base_Contas!$H$2:$H$501,Base_Contas!$B$2:$B$501,"Divergente"),"") | E6: =B6-C6 | F6: 0.2531 | G6: =IF(F6<0.05,"Diferença além do acaso","Sem diferença detectável")
A7: Assinaturas por conta | B7: =IFERROR(AVERAGEIFS(Base_Contas!$I$2:$I$501,Base_Contas!$B$2:$B$501,"Churn (3 concordam)"),"") | C7: =IFERROR(AVERAGEIFS(Base_Contas!$I$2:$I$501,Base_Contas!$B$2:$B$501,"Ativa (3 concordam)"),"") | D7: =IFERROR(AVERAGEIFS(Base_Contas!$I$2:$I$501,Base_Contas!$B$2:$B$501,"Divergente"),"") | E7: =B7-C7 | F7: 0.008 | G7: =IF(F7<0.05,"Diferença além do acaso","Sem diferença detectável")
A8: % das assinaturas iniciadas em 2024-S2 | B8: =IFERROR(AVERAGEIFS(Base_Contas!$J$2:$J$501,Base_Contas!$B$2:$B$501,"Churn (3 concordam)"),"") | C8: =IFERROR(AVERAGEIFS(Base_Contas!$J$2:$J$501,Base_Contas!$B$2:$B$501,"Ativa (3 concordam)"),"") | D8: =IFERROR(AVERAGEIFS(Base_Contas!$J$2:$J$501,Base_Contas!$B$2:$B$501,"Divergente"),"") | E8: =B8-C8 | F8: 0.2354 | G8: =IF(F8<0.05,"Diferença além do acaso","Sem diferença detectável")
A9: Meses desde o cadastro | B9: =IFERROR(AVERAGEIFS(Base_Contas!$K$2:$K$501,Base_Contas!$B$2:$B$501,"Churn (3 concordam)"),"") | C9: =IFERROR(AVERAGEIFS(Base_Contas!$K$2:$K$501,Base_Contas!$B$2:$B$501,"Ativa (3 concordam)"),"") | D9: =IFERROR(AVERAGEIFS(Base_Contas!$K$2:$K$501,Base_Contas!$B$2:$B$501,"Divergente"),"") | E9: =B9-C9 | F9: 0.4213 | G9: =IF(F9<0.05,"Diferença além do acaso","Sem diferença detectável")
A10: Seats (cadastro) | B10: =IFERROR(AVERAGEIFS(Base_Contas!$L$2:$L$501,Base_Contas!$B$2:$B$501,"Churn (3 concordam)"),"") | C10: =IFERROR(AVERAGEIFS(Base_Contas!$L$2:$L$501,Base_Contas!$B$2:$B$501,"Ativa (3 concordam)"),"") | D10: =IFERROR(AVERAGEIFS(Base_Contas!$L$2:$L$501,Base_Contas!$B$2:$B$501,"Divergente"),"") | E10: =B10-C10 | F10: 0.2947 | G10: =IF(F10<0.05,"Diferença além do acaso","Sem diferença detectável")
A11: Uso total (usage_count) | B11: =IFERROR(AVERAGEIFS(Base_Contas!$M$2:$M$501,Base_Contas!$B$2:$B$501,"Churn (3 concordam)"),"") | C11: =IFERROR(AVERAGEIFS(Base_Contas!$M$2:$M$501,Base_Contas!$B$2:$B$501,"Ativa (3 concordam)"),"") | D11: =IFERROR(AVERAGEIFS(Base_Contas!$M$2:$M$501,Base_Contas!$B$2:$B$501,"Divergente"),"") | E11: =B11-C11 | F11: 0.0306 | G11: =IF(F11<0.05,"Diferença além do acaso","Sem diferença detectável")
A12: Erros por 100 usos | B12: =IFERROR(AVERAGEIFS(Base_Contas!$N$2:$N$501,Base_Contas!$B$2:$B$501,"Churn (3 concordam)"),"") | C12: =IFERROR(AVERAGEIFS(Base_Contas!$N$2:$N$501,Base_Contas!$B$2:$B$501,"Ativa (3 concordam)"),"") | D12: =IFERROR(AVERAGEIFS(Base_Contas!$N$2:$N$501,Base_Contas!$B$2:$B$501,"Divergente"),"") | E12: =B12-C12 | F12: 0.3667 | G12: =IF(F12<0.05,"Diferença além do acaso","Sem diferença detectável")
A13: Tickets por conta | B13: =IFERROR(AVERAGEIFS(Base_Contas!$O$2:$O$501,Base_Contas!$B$2:$B$501,"Churn (3 concordam)"),"") | C13: =IFERROR(AVERAGEIFS(Base_Contas!$O$2:$O$501,Base_Contas!$B$2:$B$501,"Ativa (3 concordam)"),"") | D13: =IFERROR(AVERAGEIFS(Base_Contas!$O$2:$O$501,Base_Contas!$B$2:$B$501,"Divergente"),"") | E13: =B13-C13 | F13: 0.6215 | G13: =IF(F13<0.05,"Diferença além do acaso","Sem diferença detectável")
A14: Satisfação média | B14: =IFERROR(AVERAGEIFS(Base_Contas!$P$2:$P$501,Base_Contas!$B$2:$B$501,"Churn (3 concordam)"),"") | C14: =IFERROR(AVERAGEIFS(Base_Contas!$P$2:$P$501,Base_Contas!$B$2:$B$501,"Ativa (3 concordam)"),"") | D14: =IFERROR(AVERAGEIFS(Base_Contas!$P$2:$P$501,Base_Contas!$B$2:$B$501,"Divergente"),"") | E14: =B14-C14 | F14: 0.8612 | G14: =IF(F14<0.05,"Diferença além do acaso","Sem diferença detectável")
A15: % com upgrade | B15: =IFERROR(AVERAGEIFS(Base_Contas!$Q$2:$Q$501,Base_Contas!$B$2:$B$501,"Churn (3 concordam)"),"") | C15: =IFERROR(AVERAGEIFS(Base_Contas!$Q$2:$Q$501,Base_Contas!$B$2:$B$501,"Ativa (3 concordam)"),"") | D15: =IFERROR(AVERAGEIFS(Base_Contas!$Q$2:$Q$501,Base_Contas!$B$2:$B$501,"Divergente"),"") | E15: =B15-C15 | F15: 0.8352 | G15: =IF(F15<0.05,"Diferença além do acaso","Sem diferença detectável")
A16: % com downgrade | B16: =IFERROR(AVERAGEIFS(Base_Contas!$R$2:$R$501,Base_Contas!$B$2:$B$501,"Churn (3 concordam)"),"") | C16: =IFERROR(AVERAGEIFS(Base_Contas!$R$2:$R$501,Base_Contas!$B$2:$B$501,"Ativa (3 concordam)"),"") | D16: =IFERROR(AVERAGEIFS(Base_Contas!$R$2:$R$501,Base_Contas!$B$2:$B$501,"Divergente"),"") | E16: =B16-C16 | F16: 0.5323 | G16: =IF(F16<0.05,"Diferença além do acaso","Sem diferença detectável")
A17: % DevTools | B17: =IFERROR(AVERAGEIFS(Base_Contas!$S$2:$S$501,Base_Contas!$B$2:$B$501,"Churn (3 concordam)"),"") | C17: =IFERROR(AVERAGEIFS(Base_Contas!$S$2:$S$501,Base_Contas!$B$2:$B$501,"Ativa (3 concordam)"),"") | D17: =IFERROR(AVERAGEIFS(Base_Contas!$S$2:$S$501,Base_Contas!$B$2:$B$501,"Divergente"),"") | E17: =B17-C17 | F17: 0.0038 | G17: =IF(F17<0.05,"Diferença além do acaso","Sem diferença detectável")
A18: % canal partner | B18: =IFERROR(AVERAGEIFS(Base_Contas!$T$2:$T$501,Base_Contas!$B$2:$B$501,"Churn (3 concordam)"),"") | C18: =IFERROR(AVERAGEIFS(Base_Contas!$T$2:$T$501,Base_Contas!$B$2:$B$501,"Ativa (3 concordam)"),"") | D18: =IFERROR(AVERAGEIFS(Base_Contas!$T$2:$T$501,Base_Contas!$B$2:$B$501,"Divergente"),"") | E18: =B18-C18 | F18: 0.0264 | G18: =IF(F18<0.05,"Diferença além do acaso","Sem diferença detectável")
A20: churn_flag por indústria na base toda (500 contas)
A21: Indústria | B21: Contas | C21: Com churn_flag | D21: % churn_flag
A22: Cybersecurity | B22: =COUNTIFS(Base_Contas!$C$2:$C$501,A22) | C22: =COUNTIFS(Base_Contas!$C$2:$C$501,A22,Base_Contas!$E$2:$E$501,TRUE) | D22: =C22/B22
A23: DevTools | B23: =COUNTIFS(Base_Contas!$C$2:$C$501,A23) | C23: =COUNTIFS(Base_Contas!$C$2:$C$501,A23,Base_Contas!$E$2:$E$501,TRUE) | D23: =C23/B23
A24: EdTech | B24: =COUNTIFS(Base_Contas!$C$2:$C$501,A24) | C24: =COUNTIFS(Base_Contas!$C$2:$C$501,A24,Base_Contas!$E$2:$E$501,TRUE) | D24: =C24/B24
A25: FinTech | B25: =COUNTIFS(Base_Contas!$C$2:$C$501,A25) | C25: =COUNTIFS(Base_Contas!$C$2:$C$501,A25,Base_Contas!$E$2:$E$501,TRUE) | D25: =C25/B25
A26: HealthTech | B26: =COUNTIFS(Base_Contas!$C$2:$C$501,A26) | C26: =COUNTIFS(Base_Contas!$C$2:$C$501,A26,Base_Contas!$E$2:$E$501,TRUE) | D26: =C26/B26
A28: Leitura: as contas "limpas" são parecidas em receita, erros, tickets e satisfação. Diferenças que aparecem: mais assinaturas e mais uso no grupo churn (mecânico: quem tem mais assinaturas tem mais chance de ter uma encerrada e soma mais registros de uso), concentração em DevTools e pouca presença do canal partner.
A29: Cuidado: o grupo "churn" exige churn_flag = TRUE, e o churn_flag já é concentrado em DevTools na base toda (tabela acima). Como receita (P1/P2) e eventos (S1) NÃO mostram DevTools diferente (02_Triangulacao), isso é efeito do churn_flag, não confirmação independente.
A30: Amostra pequena (50 vs 50): serve para checar o que foi achado na base toda, não para descobrir causas novas.

Sheet Base_Assinaturas
A1: subscription_id | B1: account_id | C1: start_date | D1: end_date | E1: duracao_dias | F1: mrr_amount | G1: coorte | H1: observavel_30d | I1: encerrou_30d | J1: mes_fim | K1: dia_fim | L1: ultimos_3_dias_mes | M1: f_plano | N1: f_cobranca | O1: f_trial | P1: f_auto_renew | Q1: f_upgrade | R1: f_downgrade | S1: f_seats | T1: f_idade_conta | U1: f_industria | V1: f_pais | W1: f_canal
A2: S-8cec59 | B2: A-3c1a3f | C2: 45283 | D2: 45394 | E2: 111 | F2: 2786 | G2: Até 2024-S1 | H2: Sim | I2: 0 | J2: 45383 | K2: 12 | L2: Não | M2: Enterprise | N2: monthly | O2: Pago | P2: Sim | Q2: Não | R2: Não | S2: 6–15 | T2: 91–180 dias | U2: DevTools | V2: UK | W2: event
A3: S-0f6f44 | B3: A-9b9fe9 | C3: 45454 | E3: 203 | F3: 833 | G3: Até 2024-S1 | H3: Sim | I3: 0 | M3: Pro | N3: monthly | O3: Pago | P3: Sim | Q3: Não | R3: Não | S3: 16–40 | T3: 181–365 dias | U3: EdTech | V3: AU | W3: other
A4: S-51c0d1 | B4: A-659280 | C4: 45621 | E4: 36 | F4: 0 | G4: 2024-S2 | H4: Sim | I4: 0 | M4: Enterprise | N4: annual | O4: Trial | P4: Não | Q4: Sim | R4: Não | S4: 41+ | T4: Mais de 365 dias | U4: FinTech | V4: IN | W4: event
A5: S-f81687 | B5: A-e7a1e2 | C5: 45619 | D5: 45639 | E5: 20 | F5: 995 | G5: 2024-S2 | H5: Sim | I5: 1 | J5: 45627 | K5: 13 | L5: Não | M5: Enterprise | N5: monthly | O5: Pago | P5: Sim | Q5: Não | R5: Não | S5: 1–5 | T5: 91–180 dias | U5: Cybersecurity | V5: US | W5: event
A6: S-cff5a2 | B6: A-ba6516 | C6: 45301 | E6: 356 | F6: 5373 | G6: Até 2024-S1 | H6: Sim | I6: 0 | M6: Enterprise | N6: monthly | O6: Pago | P6: Sim | Q6: Não | R6: Não | S6: 16–40 | T6: 31–90 dias | U6: FinTech | V6: US | W6: ads
A7: S-4b9b13 | B7: A-fa2041 | C7: 45517 | E7: 140 | F7: 735 | G7: 2024-S2 | H7: Sim | I7: 0 | M7: Pro | N7: monthly | O7: Pago | P7: Sim | Q7: Não | R7: Não | S7: 6–15 | T7: 31–90 dias | U7: HealthTech | V7: US | W7: organic
A8: S-dceac6 | B8: A-417d2f | C8: 45290 | E8: 367 | F8: 796 | G8: Até 2024-S1 | H8: Sim | I8: 0 | M8: Enterprise | N8: annual | O8: Pago | P8: Sim | Q8: Não | R8: Não | S8: 1–5 | T8: 91–180 dias | U8: Cybersecurity | V8: IN | W8: partner
A9: S-8cad7b | B9: A-5f2961 | C9: 45649 | E9: 8 | F9: 304 | G9: 2024-S2 | H9: Não | I9: 0 | M9: Basic | N9: annual | O9: Pago | P9: Sim | Q9: Não | R9: Não | S9: 16–40 | T9: 31–90 dias | U9: HealthTech | V9: US | W9: partner
A10: S-24796e | B10: A-cc8c8f | C10: 45623 | E10: 34 | F10: 4577 | G10: 2024-S2 | H10: Sim | I10: 0 | M10: Enterprise | N10: annual | O10: Pago | P10: Não | Q10: Não | R10: Não | S10: 16–40 | T10: 91–180 dias | U10: DevTools | V10: US | W10: ads
A11: S-d0c344 | B11: A-80eeb6 | C11: 45592 | E11: 65 | F11: 1078 | G11: 2024-S2 | H11: Sim | I11: 0 | M11: Pro | N11: annual | O11: Pago | P11: Não | Q11: Não | R11: Não | S11: 16–40 | T11: Mais de 365 dias | U11: Cybersecurity | V11: UK | W11: organic
