Workbook

Sheet LEIA-ME
B1: Nov/dez 2024 · Caso a caso: as 21 contas em que as duas fontes concordam que o churn foi rápido
B2: Planilha apartada. Lê os CSVs originais sem alterá-los. Só quantidades.
B4: QUEM SÃO
B5: 21 contas que, ao mesmo tempo, tiveram uma assinatura encerrada com menos de 30 dias em nov/dez (fonte assinaturas) e um evento de churn com menos de 30 dias de cadastro (fonte eventos). São os casos mais "limpos" de churn rápido.
B7: ABAS
B8: • Tracos_comuns: o que as 21 têm em comum, comparado com todas as 159 assinaturas rápidas e com as lentas.
B9: • Resumo_21: uma linha por conta.
B10: • Linha_do_tempo: tudo o que aconteceu com cada conta em ordem de data (cadastro, assinaturas, cancelamentos, eventos, tickets). Filtre pela coluna Conta para ler um caso.
B11: • Base_Encerradas_NovDez: as 266 assinaturas encerradas em nov/dez, com o que havia na conta no dia.
B13: O QUE OS CASOS MOSTRAM
B14: 1. Nenhuma das 21 contas foi embora. Todas seguem com várias assinaturas ativas em 31/12 (cerca de 8 por conta). Nas 159 assinaturas rápidas de nov/dez, em só 1 caso a conta ficou sem nenhuma assinatura.
B15: 2. São contas novas que compram em rajada: abrem várias assinaturas em poucos dias (às vezes no mesmo dia, com o mesmo número de seats) e cancelam uma delas logo em seguida.
... B24: • Base fictícia; 21 contas é pouco para generalizar, por isso comparamos com as 159 rápidas. "Até 7 dias" é uma janela escolhida para a análise.

Sheet Tracos_comuns
A1: O que as 21 contas têm em comum (e o que isso diz sobre os cancelamentos rápidos)
A2: Contas em que as duas fontes concordam: assinatura encerrada com menos de 30 dias em nov/dez E evento de churn de conta com menos de 30 dias de cadastro. Contagens por fórmula sobre Resumo_21 e Base_Encerradas_NovDez.
A4: 1. A conta foi embora?
A5: Pergunta | B5: Resultado | C5: De | D5: % | E5: Leitura
A6: Das 21 contas, quantas continuam com assinatura ativa em 31/12? | B6: =COUNTIF(Resumo_21!$M$2:$M$22,">0") | C6: =COUNTA(Resumo_21!$A$2:$A$22) | D6: =B6/C6 | E6: Todas seguem clientes. O "churn" foi de uma assinatura, não da conta.
A7: Ativas em 31/12 por conta (média) | B7: =AVERAGE(Resumo_21!$M$2:$M$22)
A8: Assinaturas abertas em nov/dez por conta (média) | B8: =AVERAGE(Resumo_21!$K$2:$K$22) | E8: São contas novas que abriram várias assinaturas em poucos dias.
A9: Dias entre o cadastro e a 1ª assinatura (média) | B9: =AVERAGE(Resumo_21!$I$2:$I$22)
A10: Das 159 assinaturas rápidas de nov/dez, em quantas a conta ficou SEM nenhuma assinatura? | B10: =COUNTIFS(Base_Encerradas_NovDez!$C$2:$C$267,"Rápida",Base_Encerradas_NovDez!$L$2:$L$267,"Sim") | C10: =COUNTIFS(Base_Encerradas_NovDez!$C$2:$C$267,"Rápida") | D10: =B10/C10 | E10: Praticamente nenhuma: o cancelamento rápido quase nunca é a saída do cliente.
A11: Outras assinaturas ativas no dia do cancelamento rápido (média, 159 rápidas) | B11: =AVERAGEIFS(Base_Encerradas_NovDez!$K$2:$K$267,Base_Encerradas_NovDez!$C$2:$C$267,"Rápida")
A13: 2. O cancelamento rápido parece troca/ajuste de assinatura?
A14: Grupo | B14: Assinaturas | C14: Com nova assinatura da mesma conta até 7 dias antes/depois | D14: % | E14: Leitura
A15: As 21 contas (assinaturas rápidas) | B15: =COUNTIFS(Base_Encerradas_NovDez!$C$2:$C$267,"Rápida",Base_Encerradas_NovDez!$D$2:$D$267,"Sim") | C15: =COUNTIFS(Base_Encerradas_NovDez!$C$2:$C$267,"Rápida",Base_Encerradas_NovDez!$D$2:$D$267,"Sim",Base_Encerradas_NovDez!$M$2:$M$267,"Sim") | D15: =C15/B15
A16: Todas as rápidas de nov/dez (159) | B16: =COUNTIFS(Base_Encerradas_NovDez!$C$2:$C$267,"Rápida") | C16: =COUNTIFS(Base_Encerradas_NovDez!$C$2:$C$267,"Rápida",Base_Encerradas_NovDez!$M$2:$M$267,"Sim") | D16: =C16/B16
A17: Lentas de nov/dez (107) | B17: =COUNTIFS(Base_Encerradas_NovDez!$C$2:$C$267,"Lenta") | C17: =COUNTIFS(Base_Encerradas_NovDez!$C$2:$C$267,"Lenta",Base_Encerradas_NovDez!$M$2:$M$267,"Sim") | D17: =C17/B17
A18: Referência: uma conta qualquer, numa data qualquer de nov/dez | D18: 0.412 | E18: Sorteio de 3.000 pares conta × data (calculado no script). Mostra o quanto é comum abrir assinatura nova em qualquer janela de 15 dias.
A19: Leitura: quem cancela rápido abre outra assinatura perto da data com mais frequência do que o normal (≈ 2 em 3, contra ≈ 2 em 5). Combina com troca de plano/configuração logo após a compra, e não com abandono.
A21: 3. Houve reclamação antes?
A22: Pergunta | B22: Resultado | C22: De | D22: % | E22: Leitura
A23: Tickets das 21 contas (total) | B23: =SUM(Resumo_21!$T$2:$T$22)
A24: … com data ANTES de a conta existir | B24: =SUM(Resumo_21!$U$2:$U$22) | C24: =SUM(Resumo_21!$T$2:$T$22) | D24: =B24/C24 | E24: Impossível na vida real: a ligação ticket → conta não é confiável para essas contas.
A25: … entre o cadastro e o evento de churn | B25: =SUM(Resumo_21!$V$2:$V$22) | C25: =SUM(Resumo_21!$T$2:$T$22) | D25: =B25/C25 | E25: Quase nenhuma reclamação no período em que a conta existia.
A26: Contas com ao menos 1 ticket entre cadastro e evento | B26: =COUNTIF(Resumo_21!$V$2:$V$22,">0") | C26: =COUNTA(Resumo_21!$A$2:$A$22) | D26: =B26/C26
A28: 4. O que o cliente declarou no evento
A29: Motivo / comentário | B29: Contas
A30: Motivo: budget | B30: =COUNTIF(Resumo_21!$P$2:$P$22,"budget")
A31: Motivo: competitor | B31: =COUNTIF(Resumo_21!$P$2:$P$22,"competitor")
A32: Motivo: features | B32: =COUNTIF(Resumo_21!$P$2:$P$22,"features")
A33: Motivo: pricing | B33: =COUNTIF(Resumo_21!$P$2:$P$22,"pricing")
A34: Motivo: support | B34: =COUNTIF(Resumo_21!$P$2:$P$22,"support")
A35: Motivo: unknown | B35: =COUNTIF(Resumo_21!$P$2:$P$22,"unknown")
A36: Comentário: (sem comentário) | B36: =COUNTIF(Resumo_21!$Q$2:$Q$22,"(sem comentário)")
A37: Comentário: missing features | B37: =COUNTIF(Resumo_21!$Q$2:$Q$22,"missing features")
A38: Comentário: switched to competitor | B38: =COUNTIF(Resumo_21!$Q$2:$Q$22,"switched to competitor")
A39: Comentário: too expensive | B39: =COUNTIF(Resumo_21!$Q$2:$Q$22,"too expensive")
A40: Com reembolso | B40: =COUNTIF(Resumo_21!$R$2:$R$22,"Sim")
A41: Motivos espalhados, sem um dominante; e o motivo segue sem conversar com o comentário (ver Linha_do_tempo).
A43: 5. Perfil das 21 contas
A44: Característica | B44: Valor mais comum | C44: Contas
A45: Indústria | B45: EdTech | C45: =COUNTIF(Resumo_21!$B$2:$B$22,B45)
...

Sheet Resumo_21
A1: Conta | B1: Indústria | C1: País | D1: Canal | E1: Plano inicial | F1: Seats (cadastro) | G1: churn_flag | H1: Cadastro | I1: Dias até 1ª assinatura | J1: Assinaturas (total) | K1: Abertas em nov/dez | L1: Encerradas rápido | M1: Ativas em 31/12 | N1: Data do evento | O1: Dias de conta no evento | P1: Motivo | Q1: Comentário | R1: Reembolso? | S1: Nova assinatura até 7 dias do cancelamento? | T1: Tickets (total) | U1: Tickets com data ANTES do cadastro | V1: Tickets entre cadastro e evento | W1: Registros de uso | X1: % registros com erro
A2: A-0354fe | B2: Cybersecurity | C2: US | D2: other | E2: Basic | F2: 34 | G2: Não | H2: 45587 | I2: 12 | J2: 7 | K2: 7 | L2: 1 | M2: 6 | N2: 45611 | O2: 24 | P2: unknown | Q2: switched to competitor | R2: Não | S2: Sim | T2: 4 | U2: 2 | V2: 1 | W2: 45 | X2: 0.311
A3: A-0b0d6d | B3: DevTools | C3: US | D3: organic | E3: Pro | F3: 3 | G3: Não | H3: 45656 | I3: 0 | J3: 13 | K3: 13 | L3: 2 | M3: 11 | N3: 45657 | O3: 1 | P3: competitor | Q3: (sem comentário) | R3: Não | S3: Sim | T3: 5 | U3: 5 | V3: 0 | W3: 62 | X3: 0.419
A4: A-18793f | B4: EdTech | C4: US | D4: organic | E4: Basic | F4: 148 | G4: Não | H4: 45644 | I4: 1 | J4: 11 | K4: 11 | L4: 1 | M4: 10 | N4: 45656 | O4: 12 | P4: support | Q4: (sem comentário) | R4: Sim | S4: Sim | T4: 5 | U4: 5 | V4: 0 | W4: 48 | X4: 0.229
A5: A-309e54 | B5: DevTools | C5: US | D5: other | E5: Pro | F5: 15 | G5: Não | H5: 45635 | I5: 4 | J5: 11 | K5: 11 | L5: 1 | M5: 10 | N5: 45640 | O5: 5 | P5: support | Q5: missing features | R5: Sim | S5: Sim | T5: 5 | U5: 5 | V5: 0 | W5: 52 | X5: 0.308
A6: A-39ddf4 | B6: EdTech | C6: US | D6: partner | E6: Enterprise | F6: 40 | G6: Não | H6: 45631 | I6: 2 | J6: 9 | K6: 9 | L6: 1 | M6: 8 | N6: 45639 | O6: 8 | P6: support | Q6: (sem comentário) | R6: Não | S6: Sim | T6: 5 | U6: 5 | V6: 0 | W6: 46 | X6: 0.326
A7: A-4bfa33 | B7: Cybersecurity | C7: US | D7: event | E7: Basic | F7: 8 | G7: Não | H7: 45633 | I7: 3 | J7: 7 | K7: 7 | L7: 1 | M7: 6 | N7: 45634 | O7: 1 | P7: unknown | Q7: missing features | R7: Não | S7: Sim | T7: 4 | U7: 4 | V7: 0 | W7: 36 | X7: 0.278
A8: A-533452 | B8: DevTools | C8: AU | D8: organic | E8: Pro | F8: 9 | G8: Não | H8: 45608 | I8: 9 | J8: 11 | K8: 11 | L8: 1 | M8: 10 | N8: 45613 | O8: 5 | P8: features | Q8: missing features | R8: Não | S8: Sim | T8: 4 | U8: 4 | V8: 0 | W8: 63 | X8: 0.317
A9: A-5790f4 | B9: FinTech | C9: UK | D9: event | E9: Pro | F9: 1 | G9: Não | H9: 45648 | I9: 0 | J9: 6 | K9: 6 | L9: 1 | M9: 5 | N9: 45651 | O9: 3 | P9: features | Q9: switched to competitor | R9: Sim | S9: Sim | T9: 4 | U9: 4 | V9: 0 | W9: 35 | X9: 0.457
A10: A-5c9849 | B10: EdTech | C10: IN | D10: partner | E10: Basic | F10: 19 | G10: Não | H10: 45599 | I10: 7 | J10: 9 | K10: 9 | L10: 1 | M10: 8 | N10: 45609 | O10: 10 | P10: unknown | Q10: too expensive | R10: Não | S10: Sim | T10: 4 | U10: 4 | V10: 0 | W10: 46 | X10: 0.326
A11: A-6a7c9d | B11: Cybersecurity | C11: US | D11: organic | E11: Enterprise | F11: 26 | G11: Sim | H11: 45589 | I11: 19 | J11: 5 | K11: 5 | L11: 1 | M11: 4 | N11: 45611 | O11: 22 | P11: features | Q11: missing features | R11: Sim | S11: Sim | T11: 3 | U11: 3 | V11: 0 | W11: 19 | X11: 0.211
A12: A-712426 | B12: HealthTech | C12: US | D12: other | E12: Enterprise | F12: 9 | G12: Não | H12: 45606 | I12: 0 | J12: 15 | K12: 15 | L12: 2 | M12: 13 | N12: 45617 | O12: 11 | P12: pricing | Q12: missing features | R12: Não | S12: Sim | T12: 6 | U12: 5 | V12: 0 | W12: 70 | X12: 0.243
A13: A-76fa4d | B13: HealthTech | C13: US | D13: event | E13: Pro | F13: 69 | G13: Não | H13: 45620 | I13: 2 | J13: 7 | K13: 7 | L13: 2 | M13: 5 | N13: 45622 | O13: 2 | P13: unknown | Q13: too expensive | R13: Sim | S13: Sim | T13: 5 | U13: 4 | V13: 0 | W13: 36 | X13: 0.333
... A22: A-fd7ad3 | B22: Cybersecurity | C22: US | D22: event | E22: Enterprise | F22: 1 | G22: Não | H22: 45597 | I22: 1 | J22: 10 | K22: 10 | L22: 2 | M22: 8 | N22: 45608 | O22: 11 | P22: pricing | Q22: switched to competitor | R22: Sim | S22: Sim | T22: 8 | U22: 8 | V22: 0 | W22: 56 | X22: 0.339

Sheet Linha_do_tempo
A1: Conta | B1: Data | C1: Tipo | D1: Detalhe | E1: Alerta
A2: A-0354fe | B2: 44946 | C2: 5 Ticket | D2: T-02ebc4 · prioridade low · satisfação 5 | E2: Data ANTES do cadastro
A3: A-0354fe | B3: 45393 | C3: 5 Ticket | D3: T-0854a1 · prioridade high | E3: Data ANTES do cadastro
A4: A-0354fe | B4: 45587 | C4: 1 Cadastro da conta | D4: Cybersecurity · US · canal other · plano inicial Basic · 34 seats
A5: A-0354fe | B5: 45599 | C5: 2 Assinatura iniciada | D5: S-519f1c · Basic · mensal · 34 seats
A6: A-0354fe | B6: 45599 | C6: 2 Assinatura iniciada | D6: S-487d18 · Enterprise · anual · 34 seats · trial
A7: A-0354fe | B7: 45603 | C7: 5 Ticket | D7: T-12b388 · prioridade medium
A8: A-0354fe | B8: 45611 | C8: 2 Assinatura iniciada | D8: S-bc5908 · Enterprise · mensal · 34 seats
A9: A-0354fe | B9: 45611 | C9: 4 Evento de churn | D9: motivo unknown · comentário: switched to competitor
A10: A-0354fe | B10: 45612 | C10: 2 Assinatura iniciada | D10: S-c8fd93 · Basic · mensal · 34 seats
A11: A-0354fe | B11: 45616 | C11: 3 Assinatura encerrada | D11: S-c8fd93 · Basic · mensal · 34 seats · 4 dias de vida | E11: Cancelamento rápido
A12: A-0354fe | B12: 45619 | C12: 2 Assinatura iniciada | D12: S-ab63e3 · Basic · anual · 34 seats
A13: A-0354fe | B13: 45622 | C13: 4 Evento de churn | D13: motivo support · comentário: switched to competitor
A14: A-0354fe | B14: 45626 | C14: 5 Ticket | D14: T-abd0a8 · prioridade high · satisfação 3
A15: A-0354fe | B15: 45636 | C15: 2 Assinatura iniciada | D15: S-70af60 · Basic · anual · 34 seats · trial
A16: A-0354fe | B16: 45636 | C16: 2 Assinatura iniciada | D16: S-9ea111 · Enterprise · mensal · 34 seats
A17: A-0b0d6d | B17: 45051 | C17: 5 Ticket | D17: T-bccf47 · prioridade high | E17: Data ANTES do cadastro
A18: A-0b0d6d | B18: 45052 | C18: 5 Ticket | D18: T-14733a · prioridade high · satisfação 5 · escalado | E18: Data ANTES do cadastro
A19: A-0b0d6d | B19: 45141 | C19: 5 Ticket | D19: T-1760ba · prioridade medium · satisfação 3 | E19: Data ANTES do cadastro
A20: A-0b0d6d | B20: 45305 | C20: 5 Ticket | D20: T-88d5fe · prioridade urgent | E20: Data ANTES do cadastro
A21: A-0b0d6d | B21: 45574 | C21: 5 Ticket | D21: T-1df716 · prioridade medium | E21: Data ANTES do cadastro
A22: A-0b0d6d | B22: 45656 | C22: 1 Cadastro da conta | D22: DevTools · US · canal organic · plano inicial Pro · 3 seats
A23: A-0b0d6d | B23: 45656 | C23: 2 Assinatura iniciada | D23: S-a69aed · Basic · mensal · 3 seats
A24: A-0b0d6d | B24: 45656 | C24: 2 Assinatura iniciada | D24: S-a405f7 · Pro · anual · 22 seats
A25: A-0b0d6d | B25: 45656 | C25: 2 Assinatura iniciada | D25: S-6ef81d · Basic · anual · 25 seats
A26: A-0b0d6d | B26: 45656 | C26: 2 Assinatura iniciada | D26: S-196e49 · Basic · mensal · 12 seats
A27: A-0b0d6d | B27: 45656 | C27: 2 Assinatura iniciada | D27: S-ef2703 · Enterprise · anual · 36 seats
A28: A-0b0d6d | B28: 45657 | C28: 2 Assinatura iniciada | D28: S-b35b20 · Pro · mensal · 3 seats
A29: A-0b0d6d | B29: 45657 | C29: 2 Assinatura iniciada | D29: S-b81c97 · Pro · mensal · 18 seats
A30: A-0b0d6d | B30: 45657 | C30: 2 Assinatura iniciada | D30: S-246942 · Enterprise · mensal · 45 seats
A31: A-0b0d6d | B31: 45657 | C31: 2 Assinatura iniciada | D31: S-3236ee · Basic · mensal · 13 seats
A32: A-0b0d6d | B32: 45657 | C32: 2 Assinatura iniciada | D32: S-7e145e · Enterprise · anual · 52 seats
A33: A-0b0d6d | B33: 45657 | C33: 2 Assinatura iniciada | D33: S-5e0619 · Pro · anual · 6 seats
... A35: A-0b0d6d | B35: 45657 | C35: 2 Assinatura iniciada | D35: S-5c4dd7 · Pro · anual · 21 seats
A36: A-0b0d6d | B36: 45657 | C36: 3 Assinatura encerrada | D36: S-6ef81d · Basic · anual · 25 seats · 1 dias de vida | E36: Cancelamento rápido
A37: A-0b0d6d | B37: 45657 | C37: 3 Assinatura encerrada | D37: S-6f47c5 · Enterprise · anual · 13 seats · 0 dias de vida | E37: Cancelamento rápido
A38: A-0b0d6d | B38: 45657 | C38: 4 Evento de churn | D38: motivo competitor · comentário: (sem comentário)
A39: A-18793f | B39: 44989 | C39: 5 Ticket | D39: T-aac2ca · prioridade low · satisfação 4 | E39: Data ANTES do cadastro
A40: A-18793f | B40: 45147 | C40: 5 Ticket | D40: T-32884f · prioridade high · satisfação 5 | E40: Data ANTES do cadastro
A41: A-18793f | B41: 45200 | C41: 5 Ticket | D41: T-a2dd12 · prioridade high · satisfação 4 | E41: Data ANTES do cadastro
...

Sheet Base_Encerradas_NovDez
A1: Assinatura | B1: Conta | C1: Grupo | D1: Uma das 21 contas? | E1: Início | F1: Fim | G1: Dias de vida | H1: Plano | I1: Cobrança | J1: Seats | K1: Outras assinaturas ativas no dia do fim | L1: Conta ficou sem nenhuma assinatura? | M1: Nova assinatura até 7 dias (antes/depois)? | N1: Nova com mesmos seats?
A2: S-f81687 | B2: A-e7a1e2 | C2: Rápida | D2: Não | E2: 45619 | F2: 45639 | G2: 20 | H2: Enterprise | I2: monthly | J2: 5 | K2: 9 | L2: Não | M2: Não | N2: Não
A3: S-3bd427 | B3: A-2e3bad | C3: Rápida | D3: Não | E3: 45630 | F3: 45653 | G3: 23 | H3: Basic | I3: monthly | J3: 61 | K3: 8 | L3: Não | M3: Não | N3: Não
A4: S-aff55c | B4: A-bb2f49 | C4: Lenta | D4: Não | E4: 45305 | F4: 45655 | G4: 350 | H4: Pro | I4: monthly | J4: 8 | K4: 10 | L4: Não | M4: Sim | N4: Não
A5: S-7f8cd8 | B5: A-53f4e3 | C5: Lenta | D5: Não | E5: 45553 | F5: 45613 | G5: 60 | H5: Enterprise | I5: monthly | J5: 20 | K5: 5 | L5: Não | M5: Não | N5: Não
A6: S-b2d472 | B6: A-bcf87c | C6: Lenta | D6: Não | E6: 45531 | F6: 45637 | G6: 106 | H6: Enterprise | I6: annual | J6: 10 | K6: 8 | L6: Não | M6: Sim | N6: Não
A7: S-0267b7 | B7: A-65a46c | C7: Lenta | D7: Não | E7: 45582 | F7: 45630 | G7: 48 | H7: Enterprise | I7: monthly | J7: 13 | K7: 6 | L7: Não | M7: Não | N7: Não
A8: S-ce5450 | B8: A-0a282f | C8: Rápida | D8: Não | E8: 45651 | F8: 45654 | G8: 3 | H8: Pro | I8: annual | J8: 8 | K8: 12 | L8: Não | M8: Sim | N8: Não
A9: S-0cb6ed | B9: A-ac85cd | C9: Lenta | D9: Não | E9: 45605 | F9: 45644 | G9: 39 | H9: Pro | I9: annual | J9: 53 | K9: 6 | L9: Não | M9: Sim | N9: Sim
A10: S-1bd2ec | B10: A-e60f9d | C10: Rápida | D10: Não | E10: 45651 | F10: 45654 | G10: 3 | H10: Basic | I10: annual | J10: 38 | K10: 13 | L10: Não | M10: Sim | N10: Não
A11: S-017e33 | B11: A-f9cc74 | C11: Rápida | D11: Não | E11: 45604 | F11: 45621 | G11: 17 | H11: Basic | I11: monthly | J11: 53 | K11: 4 | L11: Não | M11: Sim | N11: Não
A12: S-9b2c95 | B12: A-e60f9d | C12: Rápida | D12: Não | E12: 45620 | F12: 45631 | G12: 11 | H12: Pro | I12: annual | J12: 29 | K12: 9 | L12: Não | M12: Sim | N12: Sim
A13: S-431c03 | B13: A-e4bf56 | C13: Rápida | D13: Não | E13: 45628 | F13: 45645 | G13: 17 | H13: Enterprise | I13: monthly | J13: 37 | K13: 5 | L13: Não | M13: Sim | N13: Não
... A267: S-4fe9b6 | B267: A-8bde0c | C267: Rápida | D267: Sim | E267: 45645 | F267: 45656 | G267: 11 | H267: Pro | I267: annual | J267: 25 | K267: 16 | L267: Não | M267: Sim | N267: Não
