Workbook

Sheet LEIA-ME
B1: Nov/dez 2024 · As assinaturas encerradas foram troca, redução ou saída do cliente?
B2: Planilha apartada. Lê os CSVs originais sem alterá-los. Só quantidades.
B4: A REGRA (simples e explicável)
B5: Para cada uma das 266 assinaturas encerradas em nov/dez, olhamos a conta no dia do encerramento:
B6: • SAÍDA DO CLIENTE: a conta ficou sem nenhuma assinatura ativa e não abriu outra em até 7 dias.
B7: • TROCA/AJUSTE: a conta abriu outra assinatura até 7 dias antes ou depois do encerramento.
B8: • REDUÇÃO: a conta continuou com outras assinaturas ativas, sem compra nova perto da data.
B9: A janela de 7 dias é uma escolha; a aba Resumo mostra o resultado também com 3 e 14 dias.
B11: RESULTADO
B12: • Saída do cliente: 0 de 266. Nenhuma conta ficou sem assinatura por causa desses encerramentos (com janela de 3 dias aparece 1 caso, que reabre em seguida).
B13: • Troca/ajuste: 156 (59%). Entre as rápidas: 107 de 159 (67%).
B14: • Redução: 110 (41%).
... B26: • Base fictícia. A regra olha só a tabela de assinaturas (a confiável). "Redução" pode incluir casos em que a conta já tinha a assinatura substituta antes da janela.

Sheet Resumo
A1: As 266 assinaturas encerradas em nov/dez: quantas foram perda de cliente?
A2: Regra (janela de 7 dias): SAÍDA = a conta ficou sem nenhuma assinatura ativa e não comprou outra em até 7 dias · TROCA/AJUSTE = a conta abriu outra assinatura até 7 dias antes ou depois · REDUÇÃO = a conta seguiu ativa, sem compra nova perto.
A4: 1. Todas as encerradas
B5: Encerradas | C5: Troca/ajuste | D5: % | E5: Redução | F5: % | G5: Saída do cliente | H5: %
A6: Todas | B6: =COUNTA(Lista_266!$A$2:$A$267) | C6: =COUNTIFS(Lista_266!$N$2:$N$267,"Troca/ajuste") | D6: =IF($B6>0,C6/$B6,"") | E6: =COUNTIFS(Lista_266!$N$2:$N$267,"Redução") | F6: =IF($B6>0,E6/$B6,"") | G6: =COUNTIFS(Lista_266!$N$2:$N$267,"Saída do cliente") | H6: =IF($B6>0,G6/$B6,"")
A8: 2. Por velocidade
A9: Velocidade | B9: Encerradas | C9: Troca/ajuste | D9: % | E9: Redução | F9: % | G9: Saída do cliente | H9: %
A10: Rápida (< 30 dias) | B10: =COUNTIFS(Lista_266!$C$2:$C$267,"Rápida (< 30 dias)") | C10: =COUNTIFS(Lista_266!$N$2:$N$267,"Troca/ajuste",Lista_266!$C$2:$C$267,"Rápida (< 30 dias)") | D10: =IF($B10>0,C10/$B10,"") | E10: =COUNTIFS(Lista_266!$N$2:$N$267,"Redução",Lista_266!$C$2:$C$267,"Rápida (< 30 dias)") | F10: =IF($B10>0,E10/$B10,"") | G10: =COUNTIFS(Lista_266!$N$2:$N$267,"Saída do cliente",Lista_266!$C$2:$C$267,"Rápida (< 30 dias)") | H10: =IF($B10>0,G10/$B10,"")
A11: Lenta (30+ dias) | B11: =COUNTIFS(Lista_266!$C$2:$C$267,"Lenta (30+ dias)") | C11: =COUNTIFS(Lista_266!$N$2:$N$267,"Troca/ajuste",Lista_266!$C$2:$C$267,"Lenta (30+ dias)") | D11: =IF($B11>0,C11/$B11,"") | E11: =COUNTIFS(Lista_266!$N$2:$N$267,"Redução",Lista_266!$C$2:$C$267,"Lenta (30+ dias)") | F11: =IF($B11>0,E11/$B11,"") | G11: =COUNTIFS(Lista_266!$N$2:$N$267,"Saída do cliente",Lista_266!$C$2:$C$267,"Lenta (30+ dias)") | H11: =IF($B11>0,G11/$B11,"")
A13: 3. Por mês
A14: Mês do fim | B14: Encerradas | C14: Troca/ajuste | D14: % | E14: Redução | F14: % | G14: Saída do cliente | H14: %
A15: Nov/24 | B15: =COUNTIFS(Lista_266!$D$2:$D$267,"Nov/24") | C15: =COUNTIFS(Lista_266!$N$2:$N$267,"Troca/ajuste",Lista_266!$D$2:$D$267,"Nov/24") | D15: =IF($B15>0,C15/$B15,"") | E15: =COUNTIFS(Lista_266!$N$2:$N$267,"Redução",Lista_266!$D$2:$D$267,"Nov/24") | F15: =IF($B15>0,E15/$B15,"") | G15: =COUNTIFS(Lista_266!$N$2:$N$267,"Saída do cliente",Lista_266!$D$2:$D$267,"Nov/24") | H15: =IF($B15>0,G15/$B15,"")
A16: Dez/24 | B16: =COUNTIFS(Lista_266!$D$2:$D$267,"Dez/24") | C16: =COUNTIFS(Lista_266!$N$2:$N$267,"Troca/ajuste",Lista_266!$D$2:$D$267,"Dez/24") | D16: =IF($B16>0,C16/$B16,"") | E16: =COUNTIFS(Lista_266!$N$2:$N$267,"Redução",Lista_266!$D$2:$D$267,"Dez/24") | F16: =IF($B16>0,E16/$B16,"") | G16: =COUNTIFS(Lista_266!$N$2:$N$267,"Saída do cliente",Lista_266!$D$2:$D$267,"Dez/24") | H16: =IF($B16>0,G16/$B16,"")
A18: 4. O pico de 29 a 31/12
A19: Fim entre 29 e 31/12? | B19: Encerradas | C19: Troca/ajuste | D19: % | E19: Redução | F19: % | G19: Saída do cliente | H19: %
A20: Sim | B20: =COUNTIFS(Lista_266!$E$2:$E$267,"Sim") | C20: =COUNTIFS(Lista_266!$N$2:$N$267,"Troca/ajuste",Lista_266!$E$2:$E$267,"Sim") | D20: =IF($B20>0,C20/$B20,"") | E20: =COUNTIFS(Lista_266!$N$2:$N$267,"Redução",Lista_266!$E$2:$E$267,"Sim") | F20: =IF($B20>0,E20/$B20,"") | G20: =COUNTIFS(Lista_266!$N$2:$N$267,"Saída do cliente",Lista_266!$E$2:$E$267,"Sim") | H20: =IF($B20>0,G20/$B20,"")
A21: Não | B21: =COUNTIFS(Lista_266!$E$2:$E$267,"Não") | C21: =COUNTIFS(Lista_266!$N$2:$N$267,"Troca/ajuste",Lista_266!$E$2:$E$267,"Não") | D21: =IF($B21>0,C21/$B21,"") | E21: =COUNTIFS(Lista_266!$N$2:$N$267,"Redução",Lista_266!$E$2:$E$267,"Não") | F21: =IF($B21>0,E21/$B21,"") | G21: =COUNTIFS(Lista_266!$N$2:$N$267,"Saída do cliente",Lista_266!$E$2:$E$267,"Não") | H21: =IF($B21>0,G21/$B21,"")
A23: 5. A conta registrou evento de churn em nov/dez?
A24: Evento de churn? | B24: Encerradas | C24: Troca/ajuste | D24: % | E24: Redução | F24: % | G24: Saída do cliente | H24: %
A25: Sim | B25: =COUNTIFS(Lista_266!$W$2:$W$267,"Sim") | C25: =COUNTIFS(Lista_266!$N$2:$N$267,"Troca/ajuste",Lista_266!$W$2:$W$267,"Sim") | D25: =IF($B25>0,C25/$B25,"") | E25: =COUNTIFS(Lista_266!$N$2:$N$267,"Redução",Lista_266!$W$2:$W$267,"Sim") | F25: =IF($B25>0,E25/$B25,"") | G25: =COUNTIFS(Lista_266!$N$2:$N$267,"Saída do cliente",Lista_266!$W$2:$W$267,"Sim") | H25: =IF($B25>0,G25/$B25,"")
A26: Não | B26: =COUNTIFS(Lista_266!$W$2:$W$267,"Não") | C26: =COUNTIFS(Lista_266!$N$2:$N$267,"Troca/ajuste",Lista_266!$W$2:$W$267,"Não") | D26: =IF($B26>0,C26/$B26,"") | E26: =COUNTIFS(Lista_266!$N$2:$N$267,"Redução",Lista_266!$W$2:$W$267,"Não") | F26: =IF($B26>0,E26/$B26,"") | G26: =COUNTIFS(Lista_266!$N$2:$N$267,"Saída do cliente",Lista_266!$W$2:$W$267,"Não") | H26: =IF($B26>0,G26/$B26,"")
A28: 6. E se a janela fosse outra? (sensibilidade da regra)
A29: Janela | B29: Encerradas | C29: Troca/ajuste | D29: % | E29: Redução | F29: % | G29: Saída do cliente | H29: %
A30: 3 dias | B30: =COUNTA(Lista_266!$A$2:$A$267) | C30: =COUNTIF(Lista_266!$O$2:$O$267,"Troca/ajuste") | D30: =C30/$B30 | E30: =COUNTIF(Lista_266!$O$2:$O$267,"Redução") | F30: =E30/$B30 | G30: =COUNTIF(Lista_266!$O$2:$O$267,"Saída do cliente") | H30: =G30/$B30
A31: 7 dias | B31: =COUNTA(Lista_266!$A$2:$A$267) | C31: =COUNTIF(Lista_266!$N$2:$N$267,"Troca/ajuste") | D31: =C31/$B31 | E31: =COUNTIF(Lista_266!$N$2:$N$267,"Redução") | F31: =E31/$B31 | G31: =COUNTIF(Lista_266!$N$2:$N$267,"Saída do cliente") | H31: =G31/$B31
A32: 14 dias | B32: =COUNTA(Lista_266!$A$2:$A$267) | C32: =COUNTIF(Lista_266!$P$2:$P$267,"Troca/ajuste") | D32: =C32/$B32 | E32: =COUNTIF(Lista_266!$P$2:$P$267,"Redução") | F32: =E32/$B32 | G32: =COUNTIF(Lista_266!$P$2:$P$267,"Saída do cliente") | H32: =G32/$B32
A34: Referência: chance de uma conta qualquer abrir assinatura em ±7 dias de uma data qualquer de nov/dez | D34: 0.412
A35: Contas sem nenhuma assinatura ativa em 31/12/2024 (base inteira, 500 contas) | D35: 0
A37: Leitura: nenhuma das 266 assinaturas encerradas em nov/dez levou a conta a ficar sem assinatura. Não houve saída de cliente no período. O que houve foi troca/ajuste (a conta abriu outra assinatura perto da data) e redução (a conta seguiu com as demais assinaturas).
A38: Cuidado com a "troca": essas contas abrem assinaturas com frequência. Numa data qualquer, já existe 41% de chance de haver assinatura nova em ±7 dias. Por isso parte das "trocas" pode ser coincidência; o excesso acima dessa referência é o que indica troca de fato.
A39: A regra é simples e explicável de propósito. A aba Lista_266 mostra, para cada assinatura, quantas outras estavam ativas no dia e quais assinaturas novas apareceram perto.

Sheet Trocas
A1: Trocas/ajustes: o que a conta abriu no lugar?
A2: Compara a assinatura cancelada com a assinatura nova mais próxima (até 7 dias antes ou depois). Contagens por fórmula sobre Lista_266.
A4: Plano da nova vs a cancelada
B5: Rápidas | C5: % | D5: Lentas | E5: % | F5: Todas | G5: %
A6: Mesmo plano | B6: =COUNTIFS(Lista_266!$N$2:$N$267,"Troca/ajuste",Lista_266!$T$2:$T$267,A6,Lista_266!$C$2:$C$267,"Rápida (< 30 dias)") | C6: =B6/SUM(B$6:B$8) | D6: =COUNTIFS(Lista_266!$N$2:$N$267,"Troca/ajuste",Lista_266!$T$2:$T$267,A6,Lista_266!$C$2:$C$267,"Lenta (30+ dias)") | E6: =D6/SUM(D$6:D$8) | F6: =B6+D6 | G6: =F6/SUM(F$6:F$8)
A7: Plano acima | B7: =COUNTIFS(Lista_266!$N$2:$N$267,"Troca/ajuste",Lista_266!$T$2:$T$267,A7,Lista_266!$C$2:$C$267,"Rápida (< 30 dias)") | C7: =B7/SUM(B$6:B$8) | D7: =COUNTIFS(Lista_266!$N$2:$N$267,"Troca/ajuste",Lista_266!$T$2:$T$267,A7,Lista_266!$C$2:$C$267,"Lenta (30+ dias)") | E7: =D7/SUM(D$6:D$8) | F7: =B7+D7 | G7: =F7/SUM(F$6:F$8)
A8: Plano abaixo | B8: =COUNTIFS(Lista_266!$N$2:$N$267,"Troca/ajuste",Lista_266!$T$2:$T$267,A8,Lista_266!$C$2:$C$267,"Rápida (< 30 dias)") | C8: =B8/SUM(B$6:B$8) | D8: =COUNTIFS(Lista_266!$N$2:$N$267,"Troca/ajuste",Lista_266!$T$2:$T$267,A8,Lista_266!$C$2:$C$267,"Lenta (30+ dias)") | E8: =D8/SUM(D$6:D$8) | F8: =B8+D8 | G8: =F8/SUM(F$6:F$8)
A10: Cobrança da nova vs a cancelada
B11: Rápidas | C11: % | D11: Lentas | E11: % | F11: Todas | G11: %
A12: Mesma cobrança | B12: =COUNTIFS(Lista_266!$N$2:$N$267,"Troca/ajuste",Lista_266!$U$2:$U$267,A12,Lista_266!$C$2:$C$267,"Rápida (< 30 dias)") | C12: =B12/SUM(B$12:B$14) | D12: =COUNTIFS(Lista_266!$N$2:$N$267,"Troca/ajuste",Lista_266!$U$2:$U$267,A12,Lista_266!$C$2:$C$267,"Lenta (30+ dias)") | E12: =D12/SUM(D$12:D$14) | F12: =B12+D12 | G12: =F12/SUM(F$12:F$14)
A13: Mudou para anual | B13: =COUNTIFS(Lista_266!$N$2:$N$267,"Troca/ajuste",Lista_266!$U$2:$U$267,A13,Lista_266!$C$2:$C$267,"Rápida (< 30 dias)") | C13: =B13/SUM(B$12:B$14) | D13: =COUNTIFS(Lista_266!$N$2:$N$267,"Troca/ajuste",Lista_266!$U$2:$U$267,A13,Lista_266!$C$2:$C$267,"Lenta (30+ dias)") | E13: =D13/SUM(D$12:D$14) | F13: =B13+D13 | G13: =F13/SUM(F$12:F$14)
A14: Mudou para mensal | B14: =COUNTIFS(Lista_266!$N$2:$N$267,"Troca/ajuste",Lista_266!$U$2:$U$267,A14,Lista_266!$C$2:$C$267,"Rápida (< 30 dias)") | C14: =B14/SUM(B$12:B$14) | D14: =COUNTIFS(Lista_266!$N$2:$N$267,"Troca/ajuste",Lista_266!$U$2:$U$267,A14,Lista_266!$C$2:$C$267,"Lenta (30+ dias)") | E14: =D14/SUM(D$12:D$14) | F14: =B14+D14 | G14: =F14/SUM(F$12:F$14)
A16: Seats da nova vs a cancelada
B17: Rápidas | C17: % | D17: Lentas | E17: % | F17: Todas | G17: %
A18: Mesmos seats | B18: =COUNTIFS(Lista_266!$N$2:$N$267,"Troca/ajuste",Lista_266!$V$2:$V$267,A18,Lista_266!$C$2:$C$267,"Rápida (< 30 dias)") | C18: =B18/SUM(B$18:B$20) | D18: =COUNTIFS(Lista_266!$N$2:$N$267,"Troca/ajuste",Lista_266!$V$2:$V$267,A18,Lista_266!$C$2:$C$267,"Lenta (30+ dias)") | E18: =D18/SUM(D$18:D$20) | F18: =B18+D18 | G18: =F18/SUM(F$18:F$20)
A19: Mais seats | B19: =COUNTIFS(Lista_266!$N$2:$N$267,"Troca/ajuste",Lista_266!$V$2:$V$267,A19,Lista_266!$C$2:$C$267,"Rápida (< 30 dias)") | C19: =B19/SUM(B$18:B$20) | D19: =COUNTIFS(Lista_266!$N$2:$N$267,"Troca/ajuste",Lista_266!$V$2:$V$267,A19,Lista_266!$C$2:$C$267,"Lenta (30+ dias)") | E19: =D19/SUM(D$18:D$20) | F19: =B19+D19 | G19: =F19/SUM(F$18:F$20)
A20: Menos seats | B20: =COUNTIFS(Lista_266!$N$2:$N$267,"Troca/ajuste",Lista_266!$V$2:$V$267,A20,Lista_266!$C$2:$C$267,"Rápida (< 30 dias)") | C20: =B20/SUM(B$18:B$20) | D20: =COUNTIFS(Lista_266!$N$2:$N$267,"Troca/ajuste",Lista_266!$V$2:$V$267,A20,Lista_266!$C$2:$C$267,"Lenta (30+ dias)") | E20: =D20/SUM(D$18:D$20) | F20: =B20+D20 | G20: =F20/SUM(F$18:F$20)
A22: Leitura: a troca não tem uma direção só. Há trocas para plano acima, abaixo e igual, e mudanças de cobrança e de seats para os dois lados: parece reconfiguração do contrato logo após a compra, não um movimento único (ex.: "todo mundo descendo de plano").

Sheet Por_perfil
A1: Tipo de cancelamento por plano, cobrança, seats e país
A2: Janela de 7 dias. Contagens por fórmula sobre Lista_266.
A4: Plano da assinatura cancelada
A5: Plano | B5: Encerradas | C5: Troca/ajuste | D5: % | E5: Redução | F5: % | G5: Saída do cliente | H5: %
A6: Basic | B6: =COUNTIFS(Lista_266!$I$2:$I$267,"Basic") | C6: =COUNTIFS(Lista_266!$N$2:$N$267,"Troca/ajuste",Lista_266!$I$2:$I$267,"Basic") | D6: =IF($B6>0,C6/$B6,"") | E6: =COUNTIFS(Lista_266!$N$2:$N$267,"Redução",Lista_266!$I$2:$I$267,"Basic") | F6: =IF($B6>0,E6/$B6,"") | G6: =COUNTIFS(Lista_266!$N$2:$N$267,"Saída do cliente",Lista_266!$I$2:$I$267,"Basic") | H6: =IF($B6>0,G6/$B6,"")
A7: Pro | B7: =COUNTIFS(Lista_266!$I$2:$I$267,"Pro") | C7: =COUNTIFS(Lista_266!$N$2:$N$267,"Troca/ajuste",Lista_266!$I$2:$I$267,"Pro") | D7: =IF($B7>0,C7/$B7,"") | E7: =COUNTIFS(Lista_266!$N$2:$N$267,"Redução",Lista_266!$I$2:$I$267,"Pro") | F7: =IF($B7>0,E7/$B7,"") | G7: =COUNTIFS(Lista_266!$N$2:$N$267,"Saída do cliente",Lista_266!$I$2:$I$267,"Pro") | H7: =IF($B7>0,G7/$B7,"")
A8: Enterprise | B8: =COUNTIFS(Lista_266!$I$2:$I$267,"Enterprise") | C8: =COUNTIFS(Lista_266!$N$2:$N$267,"Troca/ajuste",Lista_266!$I$2:$I$267,"Enterprise") | D8: =IF($B8>0,C8/$B8,"") | E8: =COUNTIFS(Lista_266!$N$2:$N$267,"Redução",Lista_266!$I$2:$I$267,"Enterprise") | F8: =IF($B8>0,E8/$B8,"") | G8: =COUNTIFS(Lista_266!$N$2:$N$267,"Saída do cliente",Lista_266!$I$2:$I$267,"Enterprise") | H8: =IF($B8>0,G8/$B8,"")
A10: Cobrança
A11: Cobrança | B11: Encerradas | C11: Troca/ajuste | D11: % | E11: Redução | F11: % | G11: Saída do cliente | H11: %
A12: Anual | B12: =COUNTIFS(Lista_266!$J$2:$J$267,"Anual") | C12: =COUNTIFS(Lista_266!$N$2:$N$267,"Troca/ajuste",Lista_266!$J$2:$J$267,"Anual") | D12: =IF($B12>0,C12/$B12,"") | E12: =COUNTIFS(Lista_266!$N$2:$N$267,"Redução",Lista_266!$J$2:$J$267,"Anual") | F12: =IF($B12>0,E12/$B12,"") | G12: =COUNTIFS(Lista_266!$N$2:$N$267,"Saída do cliente",Lista_266!$J$2:$J$267,"Anual") | H12: =IF($B12>0,G12/$B12,"")
A13: Mensal | B13: =COUNTIFS(Lista_266!$J$2:$J$267,"Mensal") | C13: =COUNTIFS(Lista_266!$N$2:$N$267,"Troca/ajuste",Lista_266!$J$2:$J$267,"Mensal") | D13: =IF($B13>0,C13/$B13,"") | E13: =COUNTIFS(Lista_266!$N$2:$N$267,"Redução",Lista_266!$J$2:$J$267,"Mensal") | F13: =IF($B13>0,E13/$B13,"") | G13: =COUNTIFS(Lista_266!$N$2:$N$267,"Saída do cliente",Lista_266!$J$2:$J$267,"Mensal") | H13: =IF($B13>0,G13/$B13,"")
A15: Faixa de seats
A16: Seats | B16: Encerradas | C16: Troca/ajuste | D16: % | E16: Redução | F16: % | G16: Saída do cliente | H16: %
A17: 01–05 | B17: =COUNTIFS(Lista_266!$L$2:$L$267,"01–05") | C17: =COUNTIFS(Lista_266!$N$2:$N$267,"Troca/ajuste",Lista_266!$L$2:$L$267,"01–05") | D17: =IF($B17>0,C17/$B17,"") | E17: =COUNTIFS(Lista_266!$N$2:$N$267,"Redução",Lista_266!$L$2:$L$267,"01–05") | F17: =IF($B17>0,E17/$B17,"") | G17: =COUNTIFS(Lista_266!$N$2:$N$267,"Saída do cliente",Lista_266!$L$2:$L$267,"01–05") | H17: =IF($B17>0,G17/$B17,"")
A18: 06–10 | B18: =COUNTIFS(Lista_266!$L$2:$L$267,"06–10") | C18: =COUNTIFS(Lista_266!$N$2:$N$267,"Troca/ajuste",Lista_266!$L$2:$L$267,"06–10") | D18: =IF($B18>0,C18/$B18,"") | E18: =COUNTIFS(Lista_266!$N$2:$N$267,"Redução",Lista_266!$L$2:$L$267,"06–10") | F18: =IF($B18>0,E18/$B18,"") | G18: =COUNTIFS(Lista_266!$N$2:$N$267,"Saída do cliente",Lista_266!$L$2:$L$267,"06–10") | H18: =IF($B18>0,G18/$B18,"")
A19: 11–20 | B19: =COUNTIFS(Lista_266!$L$2:$L$267,"11–20") | C19: =COUNTIFS(Lista_266!$N$2:$N$267,"Troca/ajuste",Lista_266!$L$2:$L$267,"11–20") | D19: =IF($B19>0,C19/$B19,"") | E19: =COUNTIFS(Lista_266!$N$2:$N$267,"Redução",Lista_266!$L$2:$L$267,"11–20") | F19: =IF($B19>0,E19/$B19,"") | G19: =COUNTIFS(Lista_266!$N$2:$N$267,"Saída do cliente",Lista_266!$L$2:$L$267,"11–20") | H19: =IF($B19>0,G19/$B19,"")
A20: 21–40 | B20: =COUNTIFS(Lista_266!$L$2:$L$267,"21–40") | C20: =COUNTIFS(Lista_266!$N$2:$N$267,"Troca/ajuste",Lista_266!$L$2:$L$267,"21–40") | D20: =IF($B20>0,C20/$B20,"") | E20: =COUNTIFS(Lista_266!$N$2:$N$267,"Redução",Lista_266!$L$2:$L$267,"21–40") | F20: =IF($B20>0,E20/$B20,"") | G20: =COUNTIFS(Lista_266!$N$2:$N$267,"Saída do cliente",Lista_266!$L$2:$L$267,"21–40") | H20: =IF($B20>0,G20/$B20,"")
A21: 41–80 | B21: =COUNTIFS(Lista_266!$L$2:$L$267,"41–80") | C21: =COUNTIFS(Lista_266!$N$2:$N$267,"Troca/ajuste",Lista_266!$L$2:$L$267,"41–80") | D21: =IF($B21>0,C21/$B21,"") | E21: =COUNTIFS(Lista_266!$N$2:$N$267,"Redução",Lista_266!$L$2:$L$267,"41–80") | F21: =IF($B21>0,E21/$B21,"") | G21: =COUNTIFS(Lista_266!$N$2:$N$267,"Saída do cliente",Lista_266!$L$2:$L$267,"41–80") | H21: =IF($B21>0,G21/$B21,"")
A22: 81 ou mais | B22: =COUNTIFS(Lista_266!$L$2:$L$267,"81 ou mais") | C22: =COUNTIFS(Lista_266!$N$2:$N$267,"Troca/ajuste",Lista_266!$L$2:$L$267,"81 ou mais") | D22: =IF($B22>0,C22/$B22,"") | E22: =COUNTIFS(Lista_266!$N$2:$N$267,"Redução",Lista_266!$L$2:$L$267,"81 ou mais") | F22: =IF($B22>0,E22/$B22,"") | G22: =COUNTIFS(Lista_266!$N$2:$N$267,"Saída do cliente",Lista_266!$L$2:$L$267,"81 ou mais") | H22: =IF($B22>0,G22/$B22,"")
A24: País
A25: País | B25: Encerradas | C25: Troca/ajuste | D25: % | E25: Redução | F25: % | G25: Saída do cliente | H25: %
A26: AU | B26: =COUNTIFS(Lista_266!$M$2:$M$267,"AU") | C26: =COUNTIFS(Lista_266!$N$2:$N$267,"Troca/ajuste",Lista_266!$M$2:$M$267,"AU") | D26: =IF($B26>0,C26/$B26,"") | E26: =COUNTIFS(Lista_266!$N$2:$N$267,"Redução",Lista_266!$M$2:$M$267,"AU") | F26: =IF($B26>0,E26/$B26,"") | G26: =COUNTIFS(Lista_266!$N$2:$N$267,"Saída do cliente",Lista_266!$M$2:$M$267,"AU") | H26: =IF($B26>0,G26/$B26,"")
A27: CA | B27: =COUNTIFS(Lista_266!$M$2:$M$267,"CA") | C27: =COUNTIFS(Lista_266!$N$2:$N$267,"Troca/ajuste",Lista_266!$M$2:$M$267,"CA") | D27: =IF($B27>0,C27/$B27,"") | E27: =COUNTIFS(Lista_266!$N$2:$N$267,"Redução",Lista_266!$M$2:$M$267,"CA") | F27: =IF($B27>0,E27/$B27,"") | G27: =COUNTIFS(Lista_266!$N$2:$N$267,"Saída do cliente",Lista_266!$M$2:$M$267,"CA") | H27: =IF($B27>0,G27/$B27,"")
A28: DE | B28: =COUNTIFS(Lista_266!$M$2:$M$267,"DE") | C28: =COUNTIFS(Lista_266!$N$2:$N$267,"Troca/ajuste",Lista_266!$M$2:$M$267,"DE") | D28: =IF($B28>0,C28/$B28,"") | E28: =COUNTIFS(Lista_266!$N$2:$N$267,"Redução",Lista_266!$M$2:$M$267,"DE") | F28: =IF($B28>0,E28/$B28,"") | G28: =COUNTIFS(Lista_266!$N$2:$N$267,"Saída do cliente",Lista_266!$M$2:$M$267,"DE") | H28: =IF($B28>0,G28/$B28,"")
A29: FR | B29: =COUNTIFS(Lista_266!$M$2:$M$267,"FR") | C29: =COUNTIFS(Lista_266!$N$2:$N$267,"Troca/ajuste",Lista_266!$M$2:$M$267,"FR") | D29: =IF($B29>0,C29/$B29,"") | E29: =COUNTIFS(Lista_266!$N$2:$N$267,"Redução",Lista_266!$M$2:$M$267,"FR") | F29: =IF($B29>0,E29/$B29,"") | G29: =COUNTIFS(Lista_266!$N$2:$N$267,"Saída do cliente",Lista_266!$M$2:$M$267,"FR") | H29: =IF($B29>0,G29/$B29,"")
A30: IN | B30: =COUNTIFS(Lista_266!$M$2:$M$267,"IN") | C30: =COUNTIFS(Lista_266!$N$2:$N$267,"Troca/ajuste",Lista_266!$M$2:$M$267,"IN") | D30: =IF($B30>0,C30/$B30,"") | E30: =COUNTIFS(Lista_266!$N$2:$N$267,"Redução",Lista_266!$M$2:$M$267,"IN") | F30: =IF($B30>0,E30/$B30,"") | G30: =COUNTIFS(Lista_266!$N$2:$N$267,"Saída do cliente",Lista_266!$M$2:$M$267,"IN") | H30: =IF($B30>0,G30/$B30,"")
A31: UK | B31: =COUNTIFS(Lista_266!$M$2:$M$267,"UK") | C31: =COUNTIFS(Lista_266!$N$2:$N$267,"Troca/ajuste",Lista_266!$M$2:$M$267,"UK") | D31: =IF($B31>0,C31/$B31,"") | E31: =COUNTIFS(Lista_266!$N$2:$N$267,"Redução",Lista_266!$M$2:$M$267,"UK") | F31: =IF($B31>0,E31/$B31,"") | G31: =COUNTIFS(Lista_266!$N$2:$N$267,"Saída do cliente",Lista_266!$M$2:$M$267,"UK") | H31: =IF($B31>0,G31/$B31,"")
A32: US | B32: =COUNTIFS(Lista_266!$M$2:$M$267,"US") | C32: =COUNTIFS(Lista_266!$N$2:$N$267,"Troca/ajuste",Lista_266!$M$2:$M$267,"US") | D32: =IF($B32>0,C32/$B32,"") | E32: =COUNTIFS(Lista_266!$N$2:$N$267,"Redução",Lista_266!$M$2:$M$267,"US") | F32: =IF($B32>0,E32/$B32,"") | G32: =COUNTIFS(Lista_266!$N$2:$N$267,"Saída do cliente",Lista_266!$M$2:$M$267,"US") | H32: =IF($B32>0,G32/$B32,"")

Sheet Lista_266
A1: Assinatura | B1: Conta | C1: Velocidade | D1: Mês do fim | E1: Fim entre 29 e 31/12? | F1: Início | G1: Fim | H1: Dias de vida | I1: Plano | J1: Cobrança | K1: Seats | L1: Faixa de seats | M1: País | N1: TIPO (janela 7 dias) | O1: Tipo (janela 3 dias) | P1: Tipo (janela 14 dias) | Q1: Outras assinaturas ativas no dia do fim | R1: Assinaturas novas até 7 dias antes/depois | S1: Nova mais próxima | T1: Plano da nova vs cancelada | U1: Cobrança da nova vs cancelada | V1: Seats da nova vs cancelada | W1: Conta tem evento de churn em nov/dez?
A2: S-8b9deb | B2: A-6c093d | C2: Lenta (30+ dias) | D2: Nov/24 | E2: Não | F2: 45547 | G2: 45597 | H2: 50 | I2: Pro | J2: Mensal | K2: 7 | L2: 06–10 | M2: US | N2: Redução | O2: Redução | P2: Redução | Q2: 8 | W2: Não
A3: S-2178f0 | B3: A-b30291 | C3: Lenta (30+ dias) | D3: Nov/24 | E3: Não | F3: 45561 | G3: 45598 | H3: 37 | I3: Basic | J3: Mensal | K3: 5 | L3: 01–05 | M3: US | N3: Redução | O3: Redução | P3: Troca/ajuste | Q3: 8 | W3: Não
A4: S-aba835 | B4: A-5b1bcd | C4: Lenta (30+ dias) | D4: Nov/24 | E4: Não | F4: 45192 | G4: 45598 | H4: 406 | I4: Basic | J4: Anual | K4: 73 | L4: 41–80 | M4: US | N4: Redução | O4: Redução | P4: Redução | Q4: 13 | W4: Não
A5: S-4df118 | B5: A-86fc1d | C5: Rápida (< 30 dias) | D5: Nov/24 | E5: Não | F5: 45593 | G5: 45598 | H5: 5 | I5: Basic | J5: Mensal | K5: 26 | L5: 21–40 | M5: UK | N5: Troca/ajuste | O5: Troca/ajuste | P5: Troca/ajuste | Q5: 4 | R5: S-807f28, S-188518 | S5: S-807f28 | T5: Plano acima | U5: Mesma cobrança | V5: Mesmos seats | W5: Não
A6: S-af2d97 | B6: A-781cc0 | C6: Rápida (< 30 dias) | D6: Nov/24 | E6: Não | F6: 45597 | G6: 45598 | H6: 1 | I6: Pro | J6: Mensal | K6: 28 | L6: 21–40 | M6: US | N6: Troca/ajuste | O6: Troca/ajuste | P6: Troca/ajuste | Q6: 12 | R6: S-beaa35, S-95aaf8 | S6: S-beaa35 | T6: Mesmo plano | U6: Mesma cobrança | V6: Menos seats | W6: Sim
A7: S-54283b | B7: A-4c56c9 | C7: Lenta (30+ dias) | D7: Nov/24 | E7: Não | F7: 45531 | G7: 45599 | H7: 68 | I7: Enterprise | J7: Mensal | K7: 49 | L7: 41–80 | M7: US | N7: Redução | O7: Redução | P7: Troca/ajuste | Q7: 6 | W7: Não
A8: S-79bb4c | B8: A-f45426 | C8: Lenta (30+ dias) | D8: Nov/24 | E8: Não | F8: 45556 | G8: 45599 | H8: 43 | I8: Pro | J8: Anual | K8: 11 | L8: 11–20 | M8: US | N8: Redução | O8: Redução | P8: Troca/ajuste | Q8: 5 | W8: Sim
A9: S-983266 | B9: A-dcc2f0 | C9: Lenta (30+ dias) | D9: Nov/24 | E9: Não | F9: 45551 | G9: 45599 | H9: 48 | I9: Pro | J9: Anual | K9: 15 | L9: 11–20 | M9: UK | N9: Redução | O9: Redução | P9: Troca/ajuste | Q9: 12 | W9: Não
A10: S-c844bd | B10: A-6a4e2d | C10: Lenta (30+ dias) | D10: Nov/24 | E10: Não | F10: 45314 | G10: 45599 | H10: 285 | I10: Basic | J10: Anual | K10: 9 | L10: 06–10 | M10: UK | N10: Redução | O10: Redução | P10: Redução | Q10: 9 | W10: Não
A11: S-7dab19 | B11: A-de58ca | C11: Lenta (30+ dias) | D11: Nov/24 | E11: Não | F11: 45284 | G11: 45600 | H11: 316 | I11: Basic | J11: Anual | K11: 47 | L11: 41–80 | M11: DE | N11: Redução | O11: Redução | P11: Redução | Q11: 9 | W11: Não
A12: S-e1e2bf | B12: A-7da956 | C12: Lenta (30+ dias) | D12: Nov/24 | E12: Não | F12: 45559 | G12: 45600 | H12: 41 | I12: Basic | J12: Anual | K12: 13 | L12: 11–20 | M12: US | N12: Troca/ajuste | O12: Troca/ajuste | P12: Troca/ajuste | Q12: 9 | R12: S-d19da0 | S12: S-d19da0 | T12: Mesmo plano | U12: Mesma cobrança | V12: Mesmos seats | W12: Não
A13: S-1be7c5 | B13: A-80eeb6 | C13: Lenta (30+ dias) | D13: Nov/24 | E13: Não | F13: 45122 | G13: 45601 | H13: 479 | I13: Basic | J13: Mensal | K13: 34 | L13: 21–40 | M13: UK | N13: Troca/ajuste | O13: Redução | P13: Troca/ajuste | Q13: 13 | R13: S-8a6579 | S13: S-8a6579 | T13: Mesmo plano | U13: Mudou para anual | V13: Menos seats | W13: Não
A14: S-6f0169 | B14: A-86cdb4 | C14: Rápida (< 30 dias) | D14: Nov/24 | E14: Não | F14: 45588 | G14: 45602 | H14: 14 | I14: Pro | J14: Mensal | K14: 3 | L14: 01–05 | M14: DE | N14: Troca/ajuste | O14: Redução | P14: Troca/ajuste | Q14: 4 | R14: S-834a48 | S14: S-834a48 | T14: Plano abaixo | U14: Mesma cobrança | V14: Mais seats | W14: Não
A15: S-d449e1 | B15: A-ccabf0 | C15: Rápida (< 30 dias) | D15: Nov/24 | E15: Não | F15: 45580 | G15: 45602 | H15: 22 | I15: Basic | J15: Anual | K15: 25 | L15: 21–40 | M15: IN | N15: Redução | O15: Redução | P15: Redução | Q15: 9 | W15: Não
A16: S-c2fd82 | B16: A-84ebe4 | C16: Lenta (30+ dias) | D16: Nov/24 | E16: Não | F16: 45472 | G16: 45602 | H16: 130 | I16: Enterprise | J16: Mensal | K16: 82 | L16: 81 ou mais | M16: US | N16: Redução | O16: Redução | P16: Troca/ajuste | Q16: 8 | W16: Não
A17: S-63e282 | B17: A-6a4e2d | C17: Rápida (< 30 dias) | D17: Nov/24 | E17: Não | F17: 45580 | G17: 45603 | H17: 23 | I17: Pro | J17: Anual | K17: 14 | L17: 11–20 | M17: UK | N17: Redução | O17: Redução | P17: Redução | Q17: 8 | W17: Não
A18: S-f94b9b | B18: A-82861f | C18: Rápida (< 30 dias) | D18: Nov/24 | E18: Não | F18: 45581 | G18: 45604 | H18: 23 | I18: Pro | J18: Anual | K18: 41 | L18: 41–80 | M18: UK | N18: Redução | O18: Redução | P18: Troca/ajuste | Q18: 7 | W18: Não
A19: S-c2a14b | B19: A-526d93 | C19: Rápida (< 30 dias) | D19: Nov/24 | E19: Não | F19: 45604 | G19: 45606 | H19: 2 | I19: Enterprise | J19: Anual | K19: 43 | L19: 41–80 | M19: FR | N19: Redução | O19: Redução | P19: Redução | Q19: 8 | W19: Não
A20: S-a3ab14 | B20: A-fdfc91 | C20: Lenta (30+ dias) | D20: Nov/24 | E20: Não | F20: 45504 | G20: 45606 | H20: 102 | I20: Pro | J20: Anual | K20: 29 | L20: 21–40 | M20: US | N20: Redução | O20: Redução | P20: Redução | Q20: 9 | W20: Não
A21: S-d35d49 | B21: A-bc87bc | C21: Lenta (30+ dias) | D21: Nov/24 | E21: Não | F21: 45546 | G21: 45606 | H21: 60 | I21: Basic | J21: Anual | K21: 18 | L21: 11–20 | M21: US | N21: Troca/ajuste | O21: Troca/ajuste | P21: Troca/ajuste | Q21: 2 | R21: S-ad8055, S-c84ce4 | S21: S-ad8055 | T21: Plano acima | U21: Mudou para mensal | V21: Menos seats | W21: Não
A22: S-3ee7c3 | B22: A-cdf020 | C22: Lenta (30+ dias) | D22: Nov/24 | E22: Não | F22: 45388 | G22: 45606 | H22: 218 | I22: Enterprise | J22: Mensal | K22: 23 | L22: 21–40 | M22: AU | N22: Redução | O22: Redução | P22: Redução | Q22: 5 | W22: Sim
A23: S-0c5771 | B23: A-798a3f | C23: Lenta (30+ dias) | D23: Nov/24 | E23: Não | F23: 45346 | G23: 45606 | H23: 260 | I23: Enterprise | J23: Anual | K23: 12 | L23: 11–20 | M23: FR | N23: Redução | O23: Redução | P23: Redução | Q23: 7 | W23: Não
A24: S-0455a5 | B24: A-993085 | C24: Rápida (< 30 dias) | D24: Nov/24 | E24: Não | F24: 45587 | G24: 45606 | H24: 19 | I24: Enterprise | J24: Mensal | K24: 42 | L24: 41–80 | M24: US | N24: Redução | O24: Redução | P24: Redução | Q24: 14 | W24: Não
A25: S-4695b8 | B25: A-ad64c6 | C25: Lenta (30+ dias) | D25: Nov/24 | E25: Não | F25: 45519 | G25: 45607 | H25: 88 | I25: Pro | J25: Anual | K25: 12 | L25: 11–20 | M25: UK | N25: Redução | O25: Redução | P25: Troca/ajuste | Q25: 4 | W25: Não
A26: S-e6571c | B26: A-0be015 | C26: Rápida (< 30 dias) | D26: Nov/24 | E26: Não | F26: 45599 | G26: 45608 | H26: 9 | I26: Basic | J26: Anual | K26: 19 | L26: 11–20 | M26: US | N26: Troca/ajuste | O26: Redução | P26: Troca/ajuste | Q26: 1 | R26: S-f9a56a | S26: S-f9a56a | T26: Mesmo plano | U26: Mudou para mensal | V26: Mais seats | W26: Sim
A27: S-abddce | B27: A-7d514c | C27: Lenta (30+ dias) | D27: Nov/24 | E27: Não | F27: 45474 | G27: 45608 | H27: 134 | I27: Enterprise | J27: Mensal | K27: 43 | L27: 41–80 | M27: DE | N27: Troca/ajuste | O27: Redução | P27: Troca/ajuste | Q27: 7 | R27: S-9e6a18 | S27: S-9e6a18 | T27: Plano abaixo | U27: Mesma cobrança | V27: Menos seats | W27: Não
A28: S-499ea3 | B28: A-c16cf7 | C28: Rápida (< 30 dias) | D28: Nov/24 | E28: Não | F28: 45586 | G28: 45608 | H28: 22 | I28: Enterprise | J28: Mensal | K28: 24 | L28: 21–40 | M28: US | N28: Troca/ajuste | O28: Troca/ajuste | P28: Troca/ajuste | Q28: 4 | R28: S-30bb47 | S28: S-30bb47 | T28: Mesmo plano | U28: Mudou para anual | V28: Menos seats | W28: Sim
A29: S-59d90a | B29: A-aa9511 | C29: Lenta (30+ dias) | D29: Nov/24 | E29: Não | F29: 45532 | G29: 45609 | H29: 77 | I29: Pro | J29: Anual | K29: 29 | L29: 21–40 | M29: US | N29: Troca/ajuste | O29: Redução | P29: Troca/ajuste | Q29: 12 | R29: S-071ade | S29: S-071ade | T29: Plano abaixo | U29: Mesma cobrança | V29: Menos seats | W29: Não
A30: S-ca1cb9 | B30: A-5a215a | C30: Lenta (30+ dias) | D30: Nov/24 | E30: Não | F30: 45551 | G30: 45609 | H30: 58 | I30: Enterprise | J30: Anual | K30: 87 | L30: 81 ou mais | M30: FR | N30: Redução | O30: Redução | P30: Troca/ajuste | Q30: 13 | W30: Não
A31: S-766d8b | B31: A-82861f | C31: Lenta (30+ dias) | D31: Nov/24 | E31: Não | F31: 45439 | G31: 45611 | H31: 172 | I31: Enterprise | J31: Mensal | K31: 41 | L31: 41–80 | M31: UK | N31: Troca/ajuste | O31: Redução | P31: Troca/ajuste | Q31: 6 | R31: S-c51ab8 | S31: S-c51ab8 | T31: Mesmo plano | U31: Mudou para anual | V31: Mesmos seats | W31: Não
A32: S-d91f4c | B32: A-1b7577 | C32: Rápida (< 30 dias) | D32: Nov/24 | E32: Não | F32: 45611 | G32: 45611 | H32: 0 | I32: Basic | J32: Mensal | K32: 10 | L32: 06–10 | M32: US | N32: Troca/ajuste | O32: Troca/ajuste | P32: Troca/ajuste | Q32: 4 | R32: S-467d4a, S-06770c | S32: S-06770c | T32: Mesmo plano | U32: Mesma cobrança | V32: Mais seats | W32: Não
A33: S-f4019e | B33: A-7988d1 | C33: Lenta (30+ dias) | D33: Nov/24 | E33: Não | F33: 45563 | G33: 45612 | H33: 49 | I33: Basic | J33: Mensal | K33: 33 | L33: 21–40 | M33: US | N33: Redução | O33: Redução | P33: Redução | Q33: 7 | W33: Sim
A34: S-32e881 | B34: A-029f69 | C34: Lenta (30+ dias) | D34: Nov/24 | E34: Não | F34: 45575 | G34: 45612 | H34: 37 | I34: Pro | J34: Mensal | K34: 3 | L34: 01–05 | M34: CA | N34: Troca/ajuste | O34: Troca/ajuste | P34: Troca/ajuste | Q34: 9 | R34: S-e07b30, S-e6dee4 | S34: S-e07b30 | T34: Mesmo plano | U34: Mudou para anual | V34: Mesmos seats | W34: Sim
A35: S-3c52a6 | B35: A-2f6a32 | C35: Lenta (30+ dias) | D35: Nov/24 | E35: Não | F35: 45560 | G35: 45612 | H35: 52 | I35: Basic | J35: Anual | K35: 19 | L35: 11–20 | M35: US | N35: Troca/ajuste | O35: Troca/ajuste | P35: Troca/ajuste | Q35: 6 | R35: S-a1e688, S-f4e6c0 | S35: S-f4e6c0 | T35: Mesmo plano | U35: Mudou para mensal | V35: Mesmos seats | W35: Não
A36: S-7f8cd8 | B36: A-53f4e3 | C36: Lenta (30+ dias) | D36: Nov/24 | E36: Não | F36: 45553 | G36: 45613 | H36: 60 | I36: Enterprise | J36: Mensal | K36: 20 | L36: 11–20 | M36: UK | N36: Redução | O36: Redução | P36: Troca/ajuste | Q36: 5 | W36: Sim
A37: S-369495 | B37: A-b3fe05 | C37: Rápida (< 30 dias) | D37: Nov/24 | E37: Não | F37: 45585 | G37: 45614 | H37: 29 | I37: Pro | J37: Mensal | K37: 8 | L37: 06–10 | M37: CA | N37: Troca/ajuste | O37: Redução | P37: Troca/ajuste | Q37: 7 | R37: S-275d57 | S37: S-275d57 | T37: Plano abaixo | U37: Mesma cobrança | V37: Mais seats | W37: Não
A38: S-8e5ceb | B38: A-7f4db3 | C38: Rápida (< 30 dias) | D38: Nov/24 | E38: Não | F38: 45603 | G38: 45614 | H38: 11 | I38: Enterprise | J38: Mensal | K38: 9 | L38: 06–10 | M38: US | N38: Redução | O38: Redução | P38: Troca/ajuste | Q38: 12 | W38: Não
A39: S-d3f138 | B39: A-560d27 | C39: Rápida (< 30 dias) | D39: Nov/24 | E39: Não | F39: 45586 | G39: 45614 | H39: 28 | I39: Enterprise | J39: Mensal | K39: 23 | L39: 21–40 | M39: US | N39: Troca/ajuste | O39: Troca/ajuste | P39: Troca/ajuste | Q39: 10 | R39: S-cb54dc, S-a603dd | S39: S-cb54dc | T39: Mesmo plano | U39: Mudou para anual | V39: Mais seats | W39: Não
A40: S-befdba | B40: A-ff79f2 | C40: Rápida (< 30 dias) | D40: Nov/24 | E40: Não | F40: 45611 | G40: 45615 | H40: 4 | I40: Basic | J40: Anual | K40: 36 | L40: 21–40 | M40: US | N40: Redução | O40: Redução | P40: Redução | Q40: 6 | W40: Não
...
